Workbook

Sheet README
A1: Independent DCF Validation Workbook
A2: Track A Phase 2A — Independent spreadsheet validator, built in a fresh session with no exposure to this repository's DCF/WACC implementation.
A4: Purpose
A5: This workbook independently reconstructs the Discounted Cash Flow (DCF) and WACC/CAPM calculations described in docs/model-specifications/dcf.md and docs/model-specifications/wacc-capm.md, entered as real, cell-by-cell Excel formulas from the written specification's prose and equations — never by reading, importing, or copying formulas from src/dcf_model/dcf.py or any other implementation file in this repository. Its purpose is to provide a second, mechanically independent calculation path that could catch a systematic formula bug the codebase's own test suite could never catch (a test written to match an incorrect implementation would still pass). See docs/independent-validation-plan.md and L-012 in docs/limitations-register.md.
A7: What this workbook does NOT do
A8: It does not import, execute, or call any code from this repository. It does not compare its own output against a live run of the codebase — the 'codebase output' columns on the Summary & Reconciliation sheet are deliberately left blank, to be filled in by a separate future session per the validation plan's explicit two-session design. It makes no investment recommendation of any kind.
A10: Sheet inventory
A11: Sheet | B11: Contents
A12: README | B12: This sheet.
A13: Sources | B13: Every data source, hostname, and retrieval detail used to build this workbook.
A14: Assumptions | B14: Every shared modeling assumption, with its source and rationale.
A15: Summary & Reconciliation | B15: Cross-company summary of every key output, plus the (currently blank) reconciliation-vs-codebase table.
A16: Inputs_<TICKER> (x4) | B16: Frozen raw facts and assumptions for one company — all hardcoded input cells (blue font).
A17: DCF_<TICKER> (x4) | B17: Every DCF/WACC formula for one company (black font, gray fill = computed, never hardcoded), with spec-section labels and local Validation Checks.
A18: Sensitivity_<TICKER> (x4) | B18: One-variable and two-way sensitivity tables for one company, with direction checks.
A19: Research Outlook | B19: Narrative interpretation of the independent findings, fragility discussion, and the profitability-is-not-established disclaimer.
A20: Validation Checks | B20: Cross-company rollup of every PASS/FAIL/PENDING check, plus the sign-off checklist from independent-validation-plan.md.
A22: Legend
A23: Blue text | B23: Hardcoded input — a frozen fact or a stated assumption. Never a formula.
A24: Black text, gray fill | B24: A live formula, computed from other cells. Never a pasted/hardcoded result.
A25: PASS | B25: Check succeeded.
A26: FAIL | B26: Check failed — investigated and documented (never silently forced to PASS).
A27: PENDING | B27: Cannot be evaluated yet (e.g. awaiting the codebase-output comparison from a separate future session).
A29: Companies validated
A30: Ticker | B30: Entity | C30: Profile (confirmed from frozen data) | D30: Revenue CAGR | E30: Avg Op Margin
A31: MSFT | B31: MICROSOFT CORPORATION | C31: Large-cap, capital-light, high-margin | D31: 13.74% | E31: 44.18%
A32: CAT | B32: CATERPILLAR INC | C32: Capital-intensive, moderate leverage | D32: 7.31% | E32: 16.56%
A33: INTC | B33: INTEL CORP | C33: Mature, negative/near-zero recent revenue growth | D33: -9.55% | E33: 0.46%
A34: VZ | B34: VERIZON COMMUNICATIONS INC | C34: Meaningfully leveraged (recommended 4th profile) | D34: 0.85% | E34: 21.22%
A36: Reproducibility
A37: Generated by build_workbook_v2.py (this directory), which loads snapshots/*.json and writes every formula programmatically via xlsx_lite.py (a small stdlib-only OOXML writer — openpyxl, xlsxwriter, and LibreOffice were not available in this build environment, and installing dependencies is out of scope for this task). Re-run: python3 build_workbook_v2.py

Sheet Sources
A1: Data Sources
A2: Full per-field provenance is in source_manifest.csv alongside this workbook. This sheet summarizes.
A4: Hostnames contacted (read-only, unauthenticated)
A5: Hostname | B5: Purpose | C5: Endpoint pattern used
A6: www.sec.gov | B6: CIK ticker lookup | C6: https://www.sec.gov/files/company_tickers.json
A7: data.sec.gov | B7: Primary financial-statement facts (XBRL) | C7: https://data.sec.gov/api/xbrl/companyfacts/CIK{10-digit}.json
A8: query1/query2.finance.yahoo.com (via yfinance) | B8: Current price, shares outstanding, beta, sector | C8: yfinance Ticker.info / Ticker.fast_info
A10: MSFT — MICROSOFT CORPORATION (CIK 0000789019)
A11: Field | B11: Fiscal Period / Timestamp | C11: XBRL Tag / Source | D11: Filing Accession | E11: Filed / Retrieved Date | F11: Provenance | G11: Source URL
A12: Revenue | B12: 2022-06-30 | C12: RevenueFromContractWithCustomerExcludingAssessedTax | D12: 0001564590-22-026876 | E12: 2022-07-28 | F12: reported | G12: https://www.sec.gov/Archives/edgar/data/789019/000156459022026876/0001564590-22-026876-index.htm
A13: EBIT/Operating Income | B13: 2022-06-30 | C13: OperatingIncomeLoss | D13: 0001564590-22-026876 | E13: 2022-07-28 | F13: reported | G13: https://www.sec.gov/Archives/edgar/data/789019/000156459022026876/0001564590-22-026876-index.htm
A14: Revenue | B14: 2023-06-30 | C14: RevenueFromContractWithCustomerExcludingAssessedTax | D14: 0000950170-23-035122 | E14: 2023-07-27 | F14: reported | G14: https://www.sec.gov/Archives/edgar/data/789019/000095017023035122/0000950170-23-035122-index.htm
A15: EBIT/Operating Income | B15: 2023-06-30 | C15: OperatingIncomeLoss | D15: 0000950170-23-035122 | E15: 2023-07-27 | F15: reported | G15: https://www.sec.gov/Archives/edgar/data/789019/000095017023035122/0000950170-23-035122-index.htm
A16: Revenue | B16: 2024-06-30 | C16: RevenueFromContractWithCustomerExcludingAssessedTax | D16: 0000950170-24-087843 | E16: 2024-07-30 | F16: reported | G16: https://www.sec.gov/Archives/edgar/data/789019/000095017024087843/0000950170-24-087843-index.htm
A17: EBIT/Operating Income | B17: 2024-06-30 | C17: OperatingIncomeLoss | D17: 0000950170-24-087843 | E17: 2024-07-30 | F17: reported | G17: https://www.sec.gov/Archives/edgar/data/789019/000095017024087843/0000950170-24-087843-index.htm
A18: Revenue | B18: 2025-06-30 | C18: RevenueFromContractWithCustomerExcludingAssessedTax | D18: 0000950170-25-100235 | E18: 2025-07-30 | F18: reported | G18: https://www.sec.gov/Archives/edgar/data/789019/000095017025100235/0000950170-25-100235-index.htm
A19: EBIT/Operating Income | B19: 2025-06-30 | C19: OperatingIncomeLoss | D19: 0000950170-25-100235 | E19: 2025-07-30 | F19: reported | G19: https://www.sec.gov/Archives/edgar/data/789019/000095017025100235/0000950170-25-100235-index.htm
A20: Revenue | B20: 2026-06-30 | C20: RevenueFromContractWithCustomerExcludingAssessedTax | D20: 0001193125-26-323660 | E20: 2026-07-29 | F20: reported | G20: https://www.sec.gov/Archives/edgar/data/789019/000119312526323660/0001193125-26-323660-index.htm
A21: EBIT/Operating Income | B21: 2026-06-30 | C21: OperatingIncomeLoss | D21: 0001193125-26-323660 | E21: 2026-07-29 | F21: reported | G21: https://www.sec.gov/Archives/edgar/data/789019/000119312526323660/0001193125-26-323660-index.htm
A22: Pretax Income (latest) | B22: 2026-06-30 | C22: IncomeLossFromContinuingOperationsBeforeIncomeTaxesExtraordinaryItemsNoncontrollingInterest | D22: 0001193125-26-323660 | E22: 2026-07-29 | F22: reported | G22: https://www.sec.gov/Archives/edgar/data/789019/000119312526323660/0001193125-26-323660-index.htm
... A28: Total Debt (latest, derived) | B28: 2026-06-30 | C28: Total Debt = LongTermDebtNoncurrent ($31,067,000,000) + LongTermDebtCurrent ($9,227,000,000) = $40,294,000,000 | D28: 0001193125-26-323660 | E28: 2026-07-29 | F28: derived (sum of components above) | G28: https://www.sec.gov/Archives/edgar/data/789019/000119312526323660/0001193125-26-323660-index.htm
A29: Price / Shares / Beta / Sector | B29: 2026-08-17T17:22:55.505484+00:00 | C29: yfinance Ticker.info | E29: 2026-08-17T17:22:55.505484+00:00 | F29: reported (unchanged from original freeze) | G29: https://finance.yahoo.com/quote/MSFT
A31: CAT — CATERPILLAR INC (CIK 0000018230)
A32: Field | B32: Fiscal Period / Timestamp | C32: XBRL Tag / Source | D32: Filing Accession | E32: Filed / Retrieved Date | F32: Provenance | G32: Source URL
A33: Revenue | B33: 2021-12-31 | C33: Revenues | D33: 0000018230-22-000050 | E33: 2022-02-16 | F33: reported | G33: https://www.sec.gov/Archives/edgar/data/18230/000001823022000050/0000018230-22-000050-index.htm
A34: EBIT/Operating Income | B34: 2021-12-31 | C34: OperatingIncomeLoss | D34: 0000018230-22-000050 | E34: 2022-02-16 | F34: reported | G34: https://www.sec.gov/Archives/edgar/data/18230/000001823022000050/0000018230-22-000050-index.htm
A35: Revenue | B35: 2022-12-31 | C35: Revenues | D35: 0000018230-23-000011 | E35: 2023-02-15 | F35: reported | G35: https://www.sec.gov/Archives/edgar/data/18230/000001823023000011/0000018230-23-000011-index.htm
A36: EBIT/Operating Income | B36: 2022-12-31 | C36: OperatingIncomeLoss | D36: 0000018230-23-000011 | E36: 2023-02-15 | F36: reported | G36: https://www.sec.gov/Archives/edgar/data/18230/000001823023000011/0000018230-23-000011-index.htm
A37: Revenue | B37: 2023-12-31 | C37: Revenues | D37: 0000018230-24-000009 | E37: 2024-02-16 | F37: reported | G37: https://www.sec.gov/Archives/edgar/data/18230/000001823024000009/0000018230-24-000009-index.htm
A38: EBIT/Operating Income | B38: 2023-12-31 | C38: OperatingIncomeLoss | D38: 0000018230-24-000009 | E38: 2024-02-16 | F38: reported | G38: https://www.sec.gov/Archives/edgar/data/18230/000001823024000009/0000018230-24-000009-index.htm
A39: Revenue | B39: 2024-12-31 | C39: Revenues | D39: 0000018230-25-000008 | E39: 2025-02-14 | F39: reported | G39: https://www.sec.gov/Archives/edgar/data/18230/000001823025000008/0000018230-25-000008-index.htm
A40: EBIT/Operating Income | B40: 2024-12-31 | C40: OperatingIncomeLoss | D40: 0000018230-25-000008 | E40: 2025-02-14 | F40: reported | G40: https://www.sec.gov/Archives/edgar/data/18230/000001823025000008/0000018230-25-000008-index.htm
A41: Revenue | B41: 2025-12-31 | C41: Revenues | D41: 0000018230-26-000008 | E41: 2026-02-13 | F41: reported | G41: https://www.sec.gov/Archives/edgar/data/18230/000001823026000008/0000018230-26-000008-index.htm
A42: EBIT/Operating Income | B42: 2025-12-31 | C42: OperatingIncomeLoss | D42: 0000018230-26-000008 | E42: 2026-02-13 | F42: reported | G42: https://www.sec.gov/Archives/edgar/data/18230/000001823026000008/0000018230-26-000008-index.htm
A43: Pretax Income (latest) | B43: 2025-12-31 | C43: IncomeLossFromContinuingOperationsBeforeIncomeTaxesMinorityInterestAndIncomeLossFromEquityMethodInvestments | D43: 0000018230-26-000008 | E43: 2026-02-13 | F43: reported | G43: https://www.sec.gov/Archives/edgar/data/18230/000001823026000008/0000018230-26-000008-index.htm
... A49: Total Debt (latest, derived) | B49: 2025-12-31 | C49: Total Debt = LongTermDebtNoncurrent ($30,696,000,000) + ShortTermBorrowings ($5,514,000,000) = $36,210,000,000 | D49: 0000018230-26-000008 | E49: 2026-02-13 | F49: derived (sum of components above) | G49: https://www.sec.gov/Archives/edgar/data/18230/000001823026000008/0000018230-26-000008-index.htm
A50: Price / Shares / Beta / Sector | B50: 2026-08-17T17:22:56.069590+00:00 | C50: yfinance Ticker.info | E50: 2026-08-17T17:22:56.069590+00:00 | F50: reported (unchanged from original freeze) | G50: https://finance.yahoo.com/quote/CAT
A52: INTC — INTEL CORP (CIK 0000050863)
A53: Field | B53: Fiscal Period / Timestamp | C53: XBRL Tag / Source | D53: Filing Accession | E53: Filed / Retrieved Date | F53: Provenance | G53: Source URL
A54: Revenue | B54: 2021-12-25 | C54: RevenueFromContractWithCustomerExcludingAssessedTax | D54: 0000050863-22-000007 | E54: 2022-01-27 | F54: reported | G54: https://www.sec.gov/Archives/edgar/data/50863/000005086322000007/0000050863-22-000007-index.htm
...

Sheet Assumptions
A1: Assumptions
A2: Per docs/assumptions-register.md and the task's shared-assumption directive.
A4: Shared assumptions (identical for every company unless noted)
A5: Assumption | B5: Value | C5: Register ID | D5: Rationale
A6: Risk-free rate | B6: 4.0% | C6: A-001 | D6: 10Y Treasury proxy; fixed per task directive rather than a live fetch (SEC/yfinance macro endpoints not required here).
A7: Market risk premium | B7: 5.5% | C7: A-009 | D7: Standard long-run U.S. equity risk premium estimate.
A8: Terminal growth rate | B8: 2.5% | C8: A-003 | D8: Roughly tracks long-run nominal GDP growth; bounded well under typical WACC.
A9: Projection period | B9: 5 years | C9: — | D9: Standard explicit DCF forecast window.
A10: D&A % of revenue | B10: 3% | C10: A-004 | D10: Fixed simplifying assumption, not derived per-company.
A11: CapEx % of revenue | B11: 4% | C11: A-004 | D11: Fixed simplifying assumption, not derived per-company.
A12: ΔNWC % of revenue change | B12: 1% | C12: A-004 | D12: Applied to the CHANGE in revenue, not revenue itself (avoids double-counting).
A13: WACC clamp | B13: [5%, 20%] | C13: A-006 | D13: Prevents a degenerate beta/rate combination from producing a nonsensical discount rate.
A14: Terminal growth clamp | B14: [0%, 5%] | C14: spec (dcf.md) | D14: Keeps WACC−g well-behaved.
A15: Historical revenue growth cap | B15: 25% (uncapped below) | C15: A-002 | D15: Caps a hyper-growth anomaly; deliberately NOT floored — a shrinking company's negative CAGR is used as-is.
A17: Company-specific derived values & disclosed fallbacks
A18: Ticker | B18: Tax Rate (derived) | C18: Method | D18: Cost of Debt (derived) | E18: Method | F18: Note
A19: MSFT | B19: 19.40% | C19: derived | D19: 7.57% | E19: derived
A20: CAT | B20: 23.98% | C20: derived | D20: 5.09% | E20: derived
A21: INTC | B21: 98.33% | C21: derived | D21: 2.34% | E21: derived | F21: Tax rate 98.3% is technically in [0,1) but economically extreme — latest-year pretax income ($1.56B) is nearly fully offset by tax provision ($1.53B), likely a valuation-allowance/one-time effect on a slim profit base. Used as-is per spec (in-range values are not overridden); flagged prominently here and in Research Outlook, not silently smoothed.
A22: VZ | B22: 22.34% | C22: derived | D22: 4.23% | E22: derived
A24: Missing-data fallbacks actually triggered in this validation
A25: None. All four companies had complete SEC EDGAR data for every required field (revenue, EBIT/operating income — one derived via Pretax+Interest for periods without a reported OperatingIncomeLoss tag, pretax income, tax provision, interest expense, total debt, cash) and complete yfinance market data (price, shares, beta, sector). No DEFAULT_TAX_RATE=21%, DEFAULT_COST_OF_DEBT=5%, DEFAULT_BETA=1.0, or DEFAULT_REVENUE_GROWTH/MARGIN fallback was triggered for any of the four companies — every derived value below is a genuine derivation from frozen facts, not a fallback default.

Sheet Inputs_MSFT
A1: Inputs — MSFT (MICROSOFT CORPORATION) | Frozen 2026-08-17T17:23:45.327319+00:00
A2: Profile: Large-cap, capital-light, high-margin | CIK 0000789019 | All USD values are actual dollars (not thousands/millions) unless noted.
A4: SECTION 1 — Historical Annual Data (SEC EDGAR, frozen)
A5: Fiscal Year End | B5: Revenue (USD) | C5: EBIT / Operating Income (USD) | D5: Provenance
A6: 44742 | B6: 198270000000 | C6: 83383000000 | D6: XBRL tag: RevenueFromContractWithCustomerExcludingAssessedTax
A7: 45107 | B7: 211915000000 | C7: 88523000000 | D7: XBRL tag: RevenueFromContractWithCustomerExcludingAssessedTax
A8: 45473 | B8: 245122000000 | C8: 109433000000 | D8: XBRL tag: RevenueFromContractWithCustomerExcludingAssessedTax
A9: 45838 | B9: 281724000000 | C9: 128528000000 | D9: XBRL tag: RevenueFromContractWithCustomerExcludingAssessedTax
A10: 46203 | B10: 331839000000 | C10: 155237000000 | D10: XBRL tag: RevenueFromContractWithCustomerExcludingAssessedTax
A12: SECTION 2 — Latest-Year Facts (SEC EDGAR, frozen)
A13: Latest Complete Fiscal Year End | B13: 46203
A14: Pretax Income (USD) | B14: 165934000000
A15: Tax Provision (USD) | B15: 32185000000
A16: Interest Expense (USD) | B16: 3051000000 | D16: Method: reported; tag: InterestExpenseNonoperating
A17: Total Debt (USD) | B17: 40294000000 | D17: Total Debt = LongTermDebtNoncurrent ($31,067,000,000) + LongTermDebtCurrent ($9,227,000,000) = $40,294,000,000 | Full per-component provenance (XBRL tag, accession, filed date, source URL): see Sources sheet.
A18: Cash & Equivalents (USD) | B18: 20935000000
A20: SECTION 3 — Market Data (Yahoo Finance via yfinance, frozen)
A21: Current Price (USD/share) | B21: 479.78
A22: Shares Outstanding | B22: 7425545491
A23: Beta (levered equity) | B23: 1.099
A24: Sector (GICS) | B24: Technology
A26: SECTION 4 — Assumptions (shared across companies unless noted; assumptions-register.md)
A27: Risk-free rate (A-001) | B27: 0.04
A28: Market risk premium (A-009) | B28: 0.055
A29: Terminal growth rate, base case (A-003) | B29: 0.025
A30: Projection years | B30: 5
A31: D&A % of revenue (A-004) | B31: 0.03
A32: CapEx % of revenue (A-004) | B32: 0.04
A33: ΔNWC % of revenue change (A-004) | B33: 0.01
A34: WACC clamp — minimum (A-006) | B34: 0.05
A35: WACC clamp — maximum (A-006) | B35: 0.2
A36: Terminal growth clamp — minimum | B36: 0
A37: Terminal growth clamp — maximum | B37: 0.05
A38: Historical revenue growth cap (A-002) | B38: 0.25

Sheet DCF_MSFT
A1: DCF Valuation — MSFT (MICROSOFT CORPORATION) [V2 — Track A Phase 2C]
A2: Every formula below is entered independently from docs/model-specifications/dcf.md and wacc-capm.md prose/equations — never copied from src/dcf_model/dcf.py. V2: years_elapsed now uses actual fiscal-period-end date subtraction, per the Track A Phase 2C specification clarification (A-028/L-019) — see row below.
A4: SECTION 1 — Historical Revenue CAGR & Operating Margin [dcf.md §Historical revenue-growth and operating-margin derivation]
A5: Years elapsed = (latest fiscal date − earliest fiscal date) / 365.25 [V2; A-028] | B5: =('Inputs_MSFT'!$A$10-'Inputs_MSFT'!$A$6)/365.25 -> 4 | D5: Spec: dcf.md — years_elapsed is ACTUAL elapsed calendar days between the earliest- and latest-dated valid observations / 365.25, never (periods−1) (A-028; Track A Phase 2C, resolving the ambiguity Phase 2B found).
A6: Diagnostic — naive (N periods − 1) years [V1's convention; NOT used below] | B6: 4 | C6: REGULAR | D6: Fiscal calendar is evenly spaced for this company — actual years_elapsed equals the naive (N periods − 1) count to within floating-point noise, so V1 and V2 agree here by coincidence, not because (periods − 1) is a generally correct convention.
A8: Raw Revenue CAGR = (Rev_latest/Rev_earliest)^(1/years) − 1 | B8: =('Inputs_MSFT'!$B$10/'Inputs_MSFT'!$B$6)^(1/B5)-1 -> 0.13741147
A9: Capped Revenue CAGR (cap A-002; NOT floored below) | B9: =MIN(B8,'Inputs_MSFT'!$B$38) -> 0.13741147 | D9: Spec: dcf.md — capped at MAX_REVENUE_GROWTH_RATE=25%, unbounded below (A-002)
A10: Average Historical Operating Margin = simple average of EBIT_t/Revenue_t | B10: =('Inputs_MSFT'!$C$6/'Inputs_MSFT'!$B$6+'Inputs_MSFT'!$C$7/'Inputs_MSFT'!$B$7+'Inputs_MSFT'!$C$8/'Inputs_MSFT'!$B$8+'Inputs_MSFT'!$C$9/'Inputs_MSFT'!$B$9+'Inputs_MSFT'!$C$10/'Inputs_MSFT'!$B$10)/5 -> 0.44175047
A12: SECTION 2 — WACC via CAPM [wacc-capm.md §Formula]
A13: Market Capitalization = Price × Shares Outstanding | B13: ='Inputs_MSFT'!$B$21*'Inputs_MSFT'!$B$22 -> 3.5626282e+12
A14: Effective Tax Rate = Tax Provision / Pretax Income (latest FY) | B14: ='Inputs_MSFT'!$B$15/'Inputs_MSFT'!$B$14 -> 0.19396266 | D14: Method: derived. Spec: wacc-capm.md — derived as tax_provision/pretax_income, valid range [0,1); DEFAULT_TAX_RATE=21% only on missing data.
A15: Cost of Debt = |Interest Expense| / Total Debt (latest FY) | B15: =ABS('Inputs_MSFT'!$B$16)/'Inputs_MSFT'!$B$17 -> 0.075718469
A16: Cost of Equity (CAPM) = Rf + Beta × MRP | B16: ='Inputs_MSFT'!$B$27+'Inputs_MSFT'!$B$23*'Inputs_MSFT'!$B$28 -> 0.100445
A17: After-Tax Cost of Debt = Cost of Debt × (1 − Tax Rate) | B17: =B15*(1-B14) -> 0.061031914
A18: Weight of Equity = MktCap / (MktCap + Total Debt) | B18: =B13/(B13+'Inputs_MSFT'!$B$17) -> 0.9888163
A19: Weight of Debt = Total Debt / (MktCap + Total Debt) | B19: ='Inputs_MSFT'!$B$17/(B13+'Inputs_MSFT'!$B$17) -> 0.0111837
A20: Raw WACC = We×Re + Wd×Rd(after-tax) | B20: =B18*B16+B19*B17 -> 0.10000422
A21: Final WACC — clamped to [5%,20%] (A-006), via MEDIAN(raw,min,max) | B21: =MEDIAN(B20,'Inputs_MSFT'!$B$34,'Inputs_MSFT'!$B$35) -> 0.10000422 | D21: MEDIAN(x,min,max) is a standard single-formula clamp: returns min if x<min, max if x>max, else x.
A23: SECTION 3 — 5-Year Free Cash Flow Projection [dcf.md §Free Cash Flow projection]
B24: Year 0 (base, actual) | C24: Year 1 | D24: Year 2 | E24: Year 3 | F24: Year 4 | G24: Year 5
A25: Revenue = Revenue_(t-1) × (1 + growth) | B25: ='Inputs_MSFT'!$B$10 -> 331839000000 | C25: =B25*(1+$B$9) -> 3.7743749e+11 | D25: =C25*(1+$B$9) -> 4.2930173e+11 | E25: =D25*(1+$B$9) -> 4.8829271e+11 | F25: =E25*(1+$B$9) -> 5.5538973e+11 | G25: =F25*(1+$B$9) -> 6.3170665e+11
A26: EBIT = Revenue × Operating Margin | C26: =C25*$B$10 -> 1.6673319e+11 | D26: =D25*$B$10 -> 1.8964424e+11 | E26: =E25*$B$10 -> 2.1570353e+11 | F26: =F25*$B$10 -> 2.4534367e+11 | G26: =G25*$B$10 -> 2.7905671e+11
A27: NOPAT = EBIT × (1 − Tax Rate) | C27: =C26*(1-$B$14) -> 1.3439317e+11 | D27: =D26*(1-$B$14) -> 1.5286034e+11 | E27: =E26*(1-$B$14) -> 1.738651e+11 | F27: =F26*(1-$B$14) -> 1.9775616e+11 | G27: =G26*(1-$B$14) -> 2.2493013e+11
A28: D&A = Revenue × D&A% (A-004) | C28: =C25*'Inputs_MSFT'!$B$31 -> 1.1323125e+10 | D28: =D25*'Inputs_MSFT'!$B$31 -> 1.2879052e+10 | E28: =E25*'Inputs_MSFT'!$B$31 -> 1.4648781e+10 | F28: =F25*'Inputs_MSFT'!$B$31 -> 1.6661692e+10 | G28: =G25*'Inputs_MSFT'!$B$31 -> 1.89512e+10
A29: CapEx = Revenue × CapEx% (A-004) | C29: =C25*'Inputs_MSFT'!$B$32 -> 1.5097499e+10 | D29: =D25*'Inputs_MSFT'!$B$32 -> 1.7172069e+10 | E29: =E25*'Inputs_MSFT'!$B$32 -> 1.9531708e+10 | F29: =F25*'Inputs_MSFT'!$B$32 -> 2.2215589e+10 | G29: =G25*'Inputs_MSFT'!$B$32 -> 2.5268266e+10
A30: ΔNWC = NWC% × (Revenue_t − Revenue_(t-1)) (A-004) | C30: ='Inputs_MSFT'!$B$33*(C25-B25) -> 4.5598486e+08 | D30: ='Inputs_MSFT'!$B$33*(D25-C25) -> 5.1864241e+08 | E30: ='Inputs_MSFT'!$B$33*(E25-D25) -> 5.8990983e+08 | F30: ='Inputs_MSFT'!$B$33*(F25-E25) -> 6.7097021e+08 | G30: ='Inputs_MSFT'!$B$33*(G25-F25) -> 7.6316921e+08
A31: Unlevered FCF = NOPAT + D&A − CapEx − ΔNWC | C31: =C27+C28-C29-C30 -> 1.3016281e+11 | D31: =D27+D28-D29-D30 -> 1.4804868e+11 | E31: =E27+E28-E29-E30 -> 1.6839226e+11 | F31: =F27+F28-F29-F30 -> 1.9153129e+11 | G31: =G27+G28-G29-G30 -> 2.1784989e+11
A33: SECTION 4 — Terminal Value (Gordon Growth) [dcf.md §Terminal value]
A34: Terminal Value = FCF_Y5 × (1+g) / (WACC − g) | B34: =G31*(1+'Inputs_MSFT'!$B$29)/(B21-'Inputs_MSFT'!$B$29) -> 2.9771145e+12
A35: Check: Final WACC > Terminal Growth Rate? | B35: =IF(B21>'Inputs_MSFT'!$B$29,"PASS","FAIL") -> PASS
A37: SECTION 5 — Discounting & Enterprise-to-Equity Bridge [dcf.md §Discounting and the Enterprise-to-Equity bridge]
A38: PV(FCF_t) = FCF_t / (1+WACC)^t | C38: =C31/(1+$B$21)^1 -> 1.1832938e+11 | D38: =D31/(1+$B$21)^2 -> 1.2235334e+11 | E38: =E31/(1+$B$21)^3 -> 1.2651415e+11 | F38: =F31/(1+$B$21)^4 -> 1.3081645e+11 | G38: =G31/(1+$B$21)^5 -> 1.3526505e+11
A39: Sum of PV(FCF Years 1-5) | B39: =SUM(C38:G38) -> 6.3327836e+11
A40: PV(Terminal Value) = TV / (1+WACC)^5 | B40: =B34/(1+B21)^5 -> 1.8485184e+12
A41: Enterprise Value = Sum PV(FCF) + PV(Terminal Value) | B41: =B39+B40 -> 2.4817968e+12
A42: Equity Value = Enterprise Value − Total Debt + Cash | B42: =B41-'Inputs_MSFT'!$B$17+'Inputs_MSFT'!$B$18 -> 2.4624378e+12
A43: Intrinsic Value per Share = Equity Value / Shares Outstanding | B43: =B42/'Inputs_MSFT'!$B$22 -> 331.61709
A44: Current Price / Intrinsic Value (descriptive ratio, NOT a recommendation) | B44: ='Inputs_MSFT'!$B$21/B43 -> 1.4467891
A46: SECTION 6 — Validation Checks (local to this company)
A47: WACC within documented clamp [5%,20%]? | B47: =IF(AND(B21>='Inputs_MSFT'!$B$34,B21<='Inputs_MSFT'!$B$35),"PASS","FAIL") -> PASS
...

Sheet Sensitivity_MSFT
A1: Sensitivity Analysis — MSFT
A2: One variable at a time, other inputs held at base case. Per docs/independent-validation-plan.md §Sensitivity tables.
A4: TABLE 1 — WACC Sensitivity (range [5%,20%], base FCF path held fixed) [dcf.md Terminal Value + discounting]
A5: WACC | B5: Terminal Value | C5: Enterprise Value | D5: Equity Value | E5: Intrinsic Value/Share
A6: 0.05 | B6: =IF($A$6<='Inputs_MSFT'!$B$29,"n/a (WACC<=g)",'DCF_MSFT'!$G$31*(1+'Inputs_MSFT'!$B$29)/($A$6-'Inputs_MSFT'!$B$29)) -> 8.9318455e+12 | C6: =IF(B6="n/a (WACC<=g)","n/a",SUMPRODUCT('DCF_MSFT'!$C$31:$G$31,1/(1+$A$6)^{1,2,3,4,5})+B6/(1+$A$6)^5) -> 7.7303117e+12 | D6: =IF(C6="n/a","n/a",C6-'Inputs_MSFT'!$B$17+'Inputs_MSFT'!$B$18) -> 7.7109527e+12 | E6: =IF(D6="n/a","n/a",D6/'Inputs_MSFT'!$B$22) -> 1038.4359
A7: 0.075 | B7: =IF($A$7<='Inputs_MSFT'!$B$29,"n/a (WACC<=g)",'DCF_MSFT'!$G$31*(1+'Inputs_MSFT'!$B$29)/($A$7-'Inputs_MSFT'!$B$29)) -> 4.4659228e+12 | C7: =IF(B7="n/a (WACC<=g)","n/a",SUMPRODUCT('DCF_MSFT'!$C$31:$G$31,1/(1+$A$7)^{1,2,3,4,5})+B7/(1+$A$7)^5) -> 3.7906832e+12 | D7: =IF(C7="n/a","n/a",C7-'Inputs_MSFT'!$B$17+'Inputs_MSFT'!$B$18) -> 3.7713242e+12 | E7: =IF(D7="n/a","n/a",D7/'Inputs_MSFT'!$B$22) -> 507.88514
A8: 0.1 | B8: =IF($A$8<='Inputs_MSFT'!$B$29,"n/a (WACC<=g)",'DCF_MSFT'!$G$31*(1+'Inputs_MSFT'!$B$29)/($A$8-'Inputs_MSFT'!$B$29)) -> 2.9772818e+12 | C8: =IF(B8="n/a (WACC<=g)","n/a",SUMPRODUCT('DCF_MSFT'!$C$31:$G$31,1/(1+$A$8)^{1,2,3,4,5})+B8/(1+$A$8)^5) -> 2.4819436e+12 | D8: =IF(C8="n/a","n/a",C8-'Inputs_MSFT'!$B$17+'Inputs_MSFT'!$B$18) -> 2.4625846e+12 | E8: =IF(D8="n/a","n/a",D8/'Inputs_MSFT'!$B$22) -> 331.63686
A9: 0.125 | B9: =IF($A$9<='Inputs_MSFT'!$B$29,"n/a (WACC<=g)",'DCF_MSFT'!$G$31*(1+'Inputs_MSFT'!$B$29)/($A$9-'Inputs_MSFT'!$B$29)) -> 2.2329614e+12 | C9: =IF(B9="n/a (WACC<=g)","n/a",SUMPRODUCT('DCF_MSFT'!$C$31:$G$31,1/(1+$A$9)^{1,2,3,4,5})+B9/(1+$A$9)^5) -> 1.8305425e+12 | D9: =IF(C9="n/a","n/a",C9-'Inputs_MSFT'!$B$17+'Inputs_MSFT'!$B$18) -> 1.8111835e+12 | E9: =IF(D9="n/a","n/a",D9/'Inputs_MSFT'!$B$22) -> 243.91251
A10: 0.15 | B10: =IF($A$10<='Inputs_MSFT'!$B$29,"n/a (WACC<=g)",'DCF_MSFT'!$G$31*(1+'Inputs_MSFT'!$B$29)/($A$10-'Inputs_MSFT'!$B$29)) -> 1.7863691e+12 | C10: =IF(B10="n/a (WACC<=g)","n/a",SUMPRODUCT('DCF_MSFT'!$C$31:$G$31,1/(1+$A$10)^{1,2,3,4,5})+B10/(1+$A$10)^5) -> 1.4418115e+12 | D10: =IF(C10="n/a","n/a",C10-'Inputs_MSFT'!$B$17+'Inputs_MSFT'!$B$18) -> 1.4224525e+12 | E10: =IF(D10="n/a","n/a",D10/'Inputs_MSFT'!$B$22) -> 191.56202
A11: 0.175 | B11: =IF($A$11<='Inputs_MSFT'!$B$29,"n/a (WACC<=g)",'DCF_MSFT'!$G$31*(1+'Inputs_MSFT'!$B$29)/($A$11-'Inputs_MSFT'!$B$29)) -> 1.4886409e+12 | C11: =IF(B11="n/a (WACC<=g)","n/a",SUMPRODUCT('DCF_MSFT'!$C$31:$G$31,1/(1+$A$11)^{1,2,3,4,5})+B11/(1+$A$11)^5) -> 1.1842238e+12 | D11: =IF(C11="n/a","n/a",C11-'Inputs_MSFT'!$B$17+'Inputs_MSFT'!$B$18) -> 1.1648648e+12 | E11: =IF(D11="n/a","n/a",D11/'Inputs_MSFT'!$B$22) -> 156.87263
A12: 0.2 | B12: =IF($A$12<='Inputs_MSFT'!$B$29,"n/a (WACC<=g)",'DCF_MSFT'!$G$31*(1+'Inputs_MSFT'!$B$29)/($A$12-'Inputs_MSFT'!$B$29)) -> 1.2759779e+12 | C12: =IF(B12="n/a (WACC<=g)","n/a",SUMPRODUCT('DCF_MSFT'!$C$31:$G$31,1/(1+$A$12)^{1,2,3,4,5})+B12/(1+$A$12)^5) -> 1.0014323e+12 | D12: =IF(C12="n/a","n/a",C12-'Inputs_MSFT'!$B$17+'Inputs_MSFT'!$B$18) -> 9.8207328e+11 | E12: =IF(D12="n/a","n/a",D12/'Inputs_MSFT'!$B$22) -> 132.25604
A13: Direction check: IV decreases as WACC rises? | B13: =IF(E6>E12,"PASS (as expected)","FAIL — investigate (see note)") -> PASS (as expected)
A16: TABLE 2 — Terminal Growth Rate Sensitivity (range [0%,5%]); invalid where g>=WACC
A17: Terminal Growth g | B17: Terminal Value | C17: Enterprise Value | D17: Equity Value | E17: Intrinsic Value/Share
A18: 0 | B18: =IF($A$18>='DCF_MSFT'!$B$21,"n/a (g>=WACC)",'DCF_MSFT'!$G$31*(1+$A$18)/('DCF_MSFT'!$B$21-$A$18)) -> 2.1784071e+12 | C18: =IF(B18="n/a (g>=WACC)","n/a",'DCF_MSFT'!$B$39+B18/(1+'DCF_MSFT'!$B$21)^5) -> 1.9858718e+12 | D18: =IF(C18="n/a","n/a",C18-'Inputs_MSFT'!$B$17+'Inputs_MSFT'!$B$18) -> 1.9665128e+12 | E18: =IF(D18="n/a","n/a",D18/'Inputs_MSFT'!$B$22) -> 264.83076
A19: 0.01 | B19: =IF($A$19>='DCF_MSFT'!$B$21,"n/a (g>=WACC)",'DCF_MSFT'!$G$31*(1+$A$19)/('DCF_MSFT'!$B$21-$A$19)) -> 2.4446454e+12 | C19: =IF(B19="n/a (g>=WACC)","n/a",'DCF_MSFT'!$B$39+B19/(1+'DCF_MSFT'!$B$21)^5) -> 2.1511817e+12 | D19: =IF(C19="n/a","n/a",C19-'Inputs_MSFT'!$B$17+'Inputs_MSFT'!$B$18) -> 2.1318227e+12 | E19: =IF(D19="n/a","n/a",D19/'Inputs_MSFT'!$B$22) -> 287.09308
A20: 0.02 | B20: =IF($A$20>='DCF_MSFT'!$B$21,"n/a (g>=WACC)",'DCF_MSFT'!$G$31*(1+$A$20)/('DCF_MSFT'!$B$21-$A$20)) -> 2.7774397e+12 | C20: =IF(B20="n/a (g>=WACC)","n/a",'DCF_MSFT'!$B$39+B20/(1+'DCF_MSFT'!$B$21)^5) -> 2.3578169e+12 | D20: =IF(C20="n/a","n/a",C20-'Inputs_MSFT'!$B$17+'Inputs_MSFT'!$B$18) -> 2.3384579e+12 | E20: =IF(D20="n/a","n/a",D20/'Inputs_MSFT'!$B$22) -> 314.92068
A21: 0.025 | B21: =IF($A$21>='DCF_MSFT'!$B$21,"n/a (g>=WACC)",'DCF_MSFT'!$G$31*(1+$A$21)/('DCF_MSFT'!$B$21-$A$21)) -> 2.9771145e+12 | C21: =IF(B21="n/a (g>=WACC)","n/a",'DCF_MSFT'!$B$39+B21/(1+'DCF_MSFT'!$B$21)^5) -> 2.4817968e+12 | D21: =IF(C21="n/a","n/a",C21-'Inputs_MSFT'!$B$17+'Inputs_MSFT'!$B$18) -> 2.4624378e+12 | E21: =IF(D21="n/a","n/a",D21/'Inputs_MSFT'!$B$22) -> 331.61709
A22: 0.03 | B22: =IF($A$22>='DCF_MSFT'!$B$21,"n/a (g>=WACC)",'DCF_MSFT'!$G$31*(1+$A$22)/('DCF_MSFT'!$B$21-$A$22)) -> 3.2053125e+12 | C22: =IF(B22="n/a (g>=WACC)","n/a",'DCF_MSFT'!$B$39+B22/(1+'DCF_MSFT'!$B$21)^5) -> 2.6234871e+12 | D22: =IF(C22="n/a","n/a",C22-'Inputs_MSFT'!$B$17+'Inputs_MSFT'!$B$18) -> 2.6041281e+12 | E22: =IF(D22="n/a","n/a",D22/'Inputs_MSFT'!$B$22) -> 350.69856
A23: 0.04 | B23: =IF($A$23>='DCF_MSFT'!$B$21,"n/a (g>=WACC)",'DCF_MSFT'!$G$31*(1+$A$23)/('DCF_MSFT'!$B$21-$A$23)) -> 3.7757995e+12 | C23: =IF(B23="n/a (g>=WACC)","n/a",'DCF_MSFT'!$B$39+B23/(1+'DCF_MSFT'!$B$21)^5) -> 2.9777078e+12 | D23: =IF(C23="n/a","n/a",C23-'Inputs_MSFT'!$B$17+'Inputs_MSFT'!$B$18) -> 2.9583488e+12 | E23: =IF(D23="n/a","n/a",D23/'Inputs_MSFT'!$B$22) -> 398.40155
A24: 0.05 | B24: =IF($A$24>='DCF_MSFT'!$B$21,"n/a (g>=WACC)",'DCF_MSFT'!$G$31*(1+$A$24)/('DCF_MSFT'!$B$21-$A$24)) -> 4.574462e+12 | C24: =IF(B24="n/a (g>=WACC)","n/a",'DCF_MSFT'!$B$39+B24/(1+'DCF_MSFT'!$B$21)^5) -> 3.4736049e+12 | D24: =IF(C24="n/a","n/a",C24-'Inputs_MSFT'!$B$17+'Inputs_MSFT'!$B$18) -> 3.4542459e+12 | E24: =IF(D24="n/a","n/a",D24/'Inputs_MSFT'!$B$22) -> 465.18413
A25: Direction check: IV increases as terminal growth rises (where valid)? | B25: =IF(E18<E24,"PASS (as expected)","FAIL — investigate (see note)") -> PASS (as expected)
A28: TABLE 3 — Revenue Growth Sensitivity (range [-10%,40%]); base WACC & margin held fixed
A29: Growth g | B29: Rev Y1 | C29: Rev Y2 | D29: Rev Y3 | E29: Rev Y4 | F29: Rev Y5 | G29: FCF Y1 | H29: FCF Y2 | I29: FCF Y3 | J29: FCF Y4 | K29: FCF Y5 | L29: Terminal Value | M29: Enterprise Value | N29: Equity Value | O29: Intrinsic Value/Share
A30: -0.1 | B30: ='DCF_MSFT'!$B$25*(1+$A$30) -> 298655100000 | C30: =B30*(1+$A$30) -> 268789590000 | D30: =C30*(1+$A$30) -> 241910631000 | E30: =D30*(1+$A$30) -> 217719567900 | F30: =E30*(1+$A$30) -> 195947611110 | G30: =B30*'DCF_MSFT'!$B$10*(1-'DCF_MSFT'!$B$14)+B30*'Inputs_MSFT'!$B$31-B30*'Inputs_MSFT'!$B$32-'Inputs_MSFT'!$B$33*(B30-'DCF_MSFT'!$B$25) -> 1.0368662e+11 | H30: =C30*'DCF_MSFT'!$B$10*(1-'DCF_MSFT'!$B$14)+C30*'Inputs_MSFT'!$B$31-C30*'Inputs_MSFT'!$B$32-'Inputs_MSFT'!$B$33*(C30-B30) -> 9.3317962e+10 | I30: =D30*'DCF_MSFT'!$B$10*(1-'DCF_MSFT'!$B$14)+D30*'Inputs_MSFT'!$B$31-D30*'Inputs_MSFT'!$B$32-'Inputs_MSFT'!$B$33*(D30-C30) -> 8.3986166e+10 | J30: =E30*'DCF_MSFT'!$B$10*(1-'DCF_MSFT'!$B$14)+E30*'Inputs_MSFT'!$B$31-E30*'Inputs_MSFT'!$B$32-'Inputs_MSFT'!$B$33*(E30-D30) -> 7.5587549e+10 | K30: =F30*'DCF_MSFT'!$B$10*(1-'DCF_MSFT'!$B$14)+F30*'Inputs_MSFT'!$B$31-F30*'Inputs_MSFT'!$B$32-'Inputs_MSFT'!$B$33*(F30-E30) -> 6.8028794e+10 | L30: =K30*(1+'Inputs_MSFT'!$B$29)/('DCF_MSFT'!$B$21-'Inputs_MSFT'!$B$29) -> 9.2967459e+11 | M30: =SUMPRODUCT(G30:K30,1/(1+'DCF_MSFT'!$B$21)^{1,2,3,4,5})+L30/(1+'DCF_MSFT'!$B$21)^5 -> 9.0559118e+11 | N30: =M30-'Inputs_MSFT'!$B$17+'Inputs_MSFT'!$B$18 -> 8.8623218e+11 | O30: =N30/'Inputs_MSFT'!$B$22 -> 119.3491
A31: -0.05 | B31: ='DCF_MSFT'!$B$25*(1+$A$31) -> 315247050000 | C31: =B31*(1+$A$31) -> 299484697500 | D31: =C31*(1+$A$31) -> 284510462625 | E31: =D31*(1+$A$31) -> 2.7028494e+11 | F31: =E31*(1+$A$31) -> 2.5677069e+11 | G31: =B31*'DCF_MSFT'!$B$10*(1-'DCF_MSFT'!$B$14)+B31*'Inputs_MSFT'!$B$31-B31*'Inputs_MSFT'!$B$32-'Inputs_MSFT'!$B$33*(B31-'DCF_MSFT'!$B$25) -> 1.0926264e+11 | H31: =C31*'DCF_MSFT'!$B$10*(1-'DCF_MSFT'!$B$14)+C31*'Inputs_MSFT'!$B$31-C31*'Inputs_MSFT'!$B$32-'Inputs_MSFT'!$B$33*(C31-B31) -> 1.0379951e+11 | I31: =D31*'DCF_MSFT'!$B$10*(1-'DCF_MSFT'!$B$14)+D31*'Inputs_MSFT'!$B$31-D31*'Inputs_MSFT'!$B$32-'Inputs_MSFT'!$B$33*(D31-C31) -> 9.860953e+10 | J31: =E31*'DCF_MSFT'!$B$10*(1-'DCF_MSFT'!$B$14)+E31*'Inputs_MSFT'!$B$31-E31*'Inputs_MSFT'!$B$32-'Inputs_MSFT'!$B$33*(E31-D31) -> 9.3679054e+10 | K31: =F31*'DCF_MSFT'!$B$10*(1-'DCF_MSFT'!$B$14)+F31*'Inputs_MSFT'!$B$31-F31*'Inputs_MSFT'!$B$32-'Inputs_MSFT'!$B$33*(F31-E31) -> 8.8995101e+10 | L31: =K31*(1+'Inputs_MSFT'!$B$29)/('DCF_MSFT'!$B$21-'Inputs_MSFT'!$B$29) -> 1.216198e+12 | M31: =SUMPRODUCT(G31:K31,1/(1+'DCF_MSFT'!$B$21)^{1,2,3,4,5})+L31/(1+'DCF_MSFT'!$B$21)^5 -> 1.1335891e+12 | N31: =M31-'Inputs_MSFT'!$B$17+'Inputs_MSFT'!$B$18 -> 1.1142301e+12 | O31: =N31/'Inputs_MSFT'!$B$22 -> 150.05363
A32: 0 | B32: ='DCF_MSFT'!$B$25*(1+$A$32) -> 331839000000 | C32: =B32*(1+$A$32) -> 331839000000 | D32: =C32*(1+$A$32) -> 331839000000 | E32: =D32*(1+$A$32) -> 331839000000 | F32: =E32*(1+$A$32) -> 331839000000 | G32: =B32*'DCF_MSFT'!$B$10*(1-'DCF_MSFT'!$B$14)+B32*'Inputs_MSFT'!$B$31-B32*'Inputs_MSFT'!$B$32-'Inputs_MSFT'!$B$33*(B32-'DCF_MSFT'!$B$25) -> 1.1483865e+11 | H32: =C32*'DCF_MSFT'!$B$10*(1-'DCF_MSFT'!$B$14)+C32*'Inputs_MSFT'!$B$31-C32*'Inputs_MSFT'!$B$32-'Inputs_MSFT'!$B$33*(C32-B32) -> 1.1483865e+11 | I32: =D32*'DCF_MSFT'!$B$10*(1-'DCF_MSFT'!$B$14)+D32*'Inputs_MSFT'!$B$31-D32*'Inputs_MSFT'!$B$32-'Inputs_MSFT'!$B$33*(D32-C32) -> 1.1483865e+11 | J32: =E32*'DCF_MSFT'!$B$10*(1-'DCF_MSFT'!$B$14)+E32*'Inputs_MSFT'!$B$31-E32*'Inputs_MSFT'!$B$32-'Inputs_MSFT'!$B$33*(E32-D32) -> 1.1483865e+11 | K32: =F32*'DCF_MSFT'!$B$10*(1-'DCF_MSFT'!$B$14)+F32*'Inputs_MSFT'!$B$31-F32*'Inputs_MSFT'!$B$32-'Inputs_MSFT'!$B$33*(F32-E32) -> 1.1483865e+11 | L32: =K32*(1+'Inputs_MSFT'!$B$29)/('DCF_MSFT'!$B$21-'Inputs_MSFT'!$B$29) -> 1.5693733e+12 | M32: =SUMPRODUCT(G32:K32,1/(1+'DCF_MSFT'!$B$21)^{1,2,3,4,5})+L32/(1+'DCF_MSFT'!$B$21)^5 -> 1.4097628e+12 | N32: =M32-'Inputs_MSFT'!$B$17+'Inputs_MSFT'!$B$18 -> 1.3904038e+12 | O32: =N32/'Inputs_MSFT'!$B$22 -> 187.24602
A33: 0.05 | B33: ='DCF_MSFT'!$B$25*(1+$A$33) -> 348430950000 | C33: =B33*(1+$A$33) -> 365852497500 | D33: =C33*(1+$A$33) -> 384145122375 | E33: =D33*(1+$A$33) -> 4.0335238e+11 | F33: =E33*(1+$A$33) -> 4.2352e+11 | G33: =B33*'DCF_MSFT'!$B$10*(1-'DCF_MSFT'!$B$14)+B33*'Inputs_MSFT'!$B$31-B33*'Inputs_MSFT'!$B$32-'Inputs_MSFT'!$B$33*(B33-'DCF_MSFT'!$B$25) -> 1.2041466e+11 | H33: =C33*'DCF_MSFT'!$B$10*(1-'DCF_MSFT'!$B$14)+C33*'Inputs_MSFT'!$B$31-C33*'Inputs_MSFT'!$B$32-'Inputs_MSFT'!$B$33*(C33-B33) -> 1.264354e+11 | I33: =D33*'DCF_MSFT'!$B$10*(1-'DCF_MSFT'!$B$14)+D33*'Inputs_MSFT'!$B$31-D33*'Inputs_MSFT'!$B$32-'Inputs_MSFT'!$B$33*(D33-C33) -> 1.3275717e+11 | J33: =E33*'DCF_MSFT'!$B$10*(1-'DCF_MSFT'!$B$14)+E33*'Inputs_MSFT'!$B$31-E33*'Inputs_MSFT'!$B$32-'Inputs_MSFT'!$B$33*(E33-D33) -> 1.3939502e+11 | K33: =F33*'DCF_MSFT'!$B$10*(1-'DCF_MSFT'!$B$14)+F33*'Inputs_MSFT'!$B$31-F33*'Inputs_MSFT'!$B$32-'Inputs_MSFT'!$B$33*(F33-E33) -> 1.4636478e+11 | L33: =K33*(1+'Inputs_MSFT'!$B$29)/('DCF_MSFT'!$B$21-'Inputs_MSFT'!$B$29) -> 2.0002062e+12 | M33: =SUMPRODUCT(G33:K33,1/(1+'DCF_MSFT'!$B$21)^{1,2,3,4,5})+L33/(1+'DCF_MSFT'!$B$21)^5 -> 1.7417333e+12 | N33: =M33-'Inputs_MSFT'!$B$17+'Inputs_MSFT'!$B$18 -> 1.7223743e+12 | O33: =N33/'Inputs_MSFT'!$B$22 -> 231.95257
A34: 0.1 | B34: ='DCF_MSFT'!$B$25*(1+$A$34) -> 365022900000 | C34: =B34*(1+$A$34) -> 4.0152519e+11 | D34: =C34*(1+$A$34) -> 4.4167771e+11 | E34: =D34*(1+$A$34) -> 4.8584548e+11 | F34: =E34*(1+$A$34) -> 5.3443003e+11 | G34: =B34*'DCF_MSFT'!$B$10*(1-'DCF_MSFT'!$B$14)+B34*'Inputs_MSFT'!$B$31-B34*'Inputs_MSFT'!$B$32-'Inputs_MSFT'!$B$33*(B34-'DCF_MSFT'!$B$25) -> 1.2599068e+11 | H34: =C34*'DCF_MSFT'!$B$10*(1-'DCF_MSFT'!$B$14)+C34*'Inputs_MSFT'!$B$31-C34*'Inputs_MSFT'!$B$32-'Inputs_MSFT'!$B$33*(C34-B34) -> 1.3858974e+11 | I34: =D34*'DCF_MSFT'!$B$10*(1-'DCF_MSFT'!$B$14)+D34*'Inputs_MSFT'!$B$31-D34*'Inputs_MSFT'!$B$32-'Inputs_MSFT'!$B$33*(D34-C34) -> 1.5244872e+11 | J34: =E34*'DCF_MSFT'!$B$10*(1-'DCF_MSFT'!$B$14)+E34*'Inputs_MSFT'!$B$31-E34*'Inputs_MSFT'!$B$32-'Inputs_MSFT'!$B$33*(E34-D34) -> 1.6769359e+11 | K34: =F34*'DCF_MSFT'!$B$10*(1-'DCF_MSFT'!$B$14)+F34*'Inputs_MSFT'!$B$31-F34*'Inputs_MSFT'!$B$32-'Inputs_MSFT'!$B$33*(F34-E34) -> 1.8446295e+11 | L34: =K34*(1+'Inputs_MSFT'!$B$29)/('DCF_MSFT'!$B$21-'Inputs_MSFT'!$B$29) -> 2.5208519e+12 | M34: =SUMPRODUCT(G34:K34,1/(1+'DCF_MSFT'!$B$21)^{1,2,3,4,5})+L34/(1+'DCF_MSFT'!$B$21)^5 -> 2.137899e+12 | N34: =M34-'Inputs_MSFT'!$B$17+'Inputs_MSFT'!$B$18 -> 2.11854e+12 | O34: =N34/'Inputs_MSFT'!$B$22 -> 285.3043
A35: 0.2 | B35: ='DCF_MSFT'!$B$25*(1+$A$35) -> 398206800000 | C35: =B35*(1+$A$35) -> 477848160000 | D35: =C35*(1+$A$35) -> 573417792000 | E35: =D35*(1+$A$35) -> 688101350400 | F35: =E35*(1+$A$35) -> 825721620480 | G35: =B35*'DCF_MSFT'!$B$10*(1-'DCF_MSFT'!$B$14)+B35*'Inputs_MSFT'!$B$31-B35*'Inputs_MSFT'!$B$32-'Inputs_MSFT'!$B$33*(B35-'DCF_MSFT'!$B$25) -> 1.371427e+11 | H35: =C35*'DCF_MSFT'!$B$10*(1-'DCF_MSFT'!$B$14)+C35*'Inputs_MSFT'!$B$31-C35*'Inputs_MSFT'!$B$32-'Inputs_MSFT'!$B$33*(C35-B35) -> 1.6457124e+11 | I35: =D35*'DCF_MSFT'!$B$10*(1-'DCF_MSFT'!$B$14)+D35*'Inputs_MSFT'!$B$31-D35*'Inputs_MSFT'!$B$32-'Inputs_MSFT'!$B$33*(D35-C35) -> 1.9748549e+11 | J35: =E35*'DCF_MSFT'!$B$10*(1-'DCF_MSFT'!$B$14)+E35*'Inputs_MSFT'!$B$31-E35*'Inputs_MSFT'!$B$32-'Inputs_MSFT'!$B$33*(E35-D35) -> 2.3698259e+11 | K35: =F35*'DCF_MSFT'!$B$10*(1-'DCF_MSFT'!$B$14)+F35*'Inputs_MSFT'!$B$31-F35*'Inputs_MSFT'!$B$32-'Inputs_MSFT'!$B$33*(F35-E35) -> 2.8437911e+11 | L35: =K35*(1+'Inputs_MSFT'!$B$29)/('DCF_MSFT'!$B$21-'Inputs_MSFT'!$B$29) -> 3.886296e+12 | M35: =SUMPRODUCT(G35:K35,1/(1+'DCF_MSFT'!$B$21)^{1,2,3,4,5})+L35/(1+'DCF_MSFT'!$B$21)^5 -> 3.1605263e+12 | N35: =M35-'Inputs_MSFT'!$B$17+'Inputs_MSFT'!$B$18 -> 3.1411673e+12 | O35: =N35/'Inputs_MSFT'!$B$22 -> 423.02176
A36: 0.3 | B36: ='DCF_MSFT'!$B$25*(1+$A$36) -> 431390700000 | C36: =B36*(1+$A$36) -> 560807910000 | D36: =C36*(1+$A$36) -> 729050283000 | E36: =D36*(1+$A$36) -> 947765367900 | F36: =E36*(1+$A$36) -> 1232094978270 | G36: =B36*'DCF_MSFT'!$B$10*(1-'DCF_MSFT'!$B$14)+B36*'Inputs_MSFT'!$B$31-B36*'Inputs_MSFT'!$B$32-'Inputs_MSFT'!$B$33*(B36-'DCF_MSFT'!$B$25) -> 1.4829473e+11 | H36: =C36*'DCF_MSFT'!$B$10*(1-'DCF_MSFT'!$B$14)+C36*'Inputs_MSFT'!$B$31-C36*'Inputs_MSFT'!$B$32-'Inputs_MSFT'!$B$33*(C36-B36) -> 1.9278315e+11 | I36: =D36*'DCF_MSFT'!$B$10*(1-'DCF_MSFT'!$B$14)+D36*'Inputs_MSFT'!$B$31-D36*'Inputs_MSFT'!$B$32-'Inputs_MSFT'!$B$33*(D36-C36) -> 2.5061809e+11 | J36: =E36*'DCF_MSFT'!$B$10*(1-'DCF_MSFT'!$B$14)+E36*'Inputs_MSFT'!$B$31-E36*'Inputs_MSFT'!$B$32-'Inputs_MSFT'!$B$33*(E36-D36) -> 3.2580352e+11 | K36: =F36*'DCF_MSFT'!$B$10*(1-'DCF_MSFT'!$B$14)+F36*'Inputs_MSFT'!$B$31-F36*'Inputs_MSFT'!$B$32-'Inputs_MSFT'!$B$33*(F36-E36) -> 4.2354457e+11 | L36: =K36*(1+'Inputs_MSFT'!$B$29)/('DCF_MSFT'!$B$21-'Inputs_MSFT'!$B$29) -> 5.7881171e+12 | M36: =SUMPRODUCT(G36:K36,1/(1+'DCF_MSFT'!$B$21)^{1,2,3,4,5})+L36/(1+'DCF_MSFT'!$B$21)^5 -> 4.5618316e+12 | N36: =M36-'Inputs_MSFT'!$B$17+'Inputs_MSFT'!$B$18 -> 4.5424726e+12 | O36: =N36/'Inputs_MSFT'!$B$22 -> 611.73587
A37: 0.4 | B37: ='DCF_MSFT'!$B$25*(1+$A$37) -> 464574600000 | C37: =B37*(1+$A$37) -> 650404440000 | D37: =C37*(1+$A$37) -> 910566216000 | E37: =D37*(1+$A$37) -> 1274792702400 | F37: =E37*(1+$A$37) -> 1784709783360 | G37: =B37*'DCF_MSFT'!$B$10*(1-'DCF_MSFT'!$B$14)+B37*'Inputs_MSFT'!$B$31-B37*'Inputs_MSFT'!$B$32-'Inputs_MSFT'!$B$33*(B37-'DCF_MSFT'!$B$25) -> 1.5944675e+11 | H37: =C37*'DCF_MSFT'!$B$10*(1-'DCF_MSFT'!$B$14)+C37*'Inputs_MSFT'!$B$31-C37*'Inputs_MSFT'!$B$32-'Inputs_MSFT'!$B$33*(C37-B37) -> 2.2322546e+11 | I37: =D37*'DCF_MSFT'!$B$10*(1-'DCF_MSFT'!$B$14)+D37*'Inputs_MSFT'!$B$31-D37*'Inputs_MSFT'!$B$32-'Inputs_MSFT'!$B$33*(D37-C37) -> 3.1251564e+11 | J37: =E37*'DCF_MSFT'!$B$10*(1-'DCF_MSFT'!$B$14)+E37*'Inputs_MSFT'!$B$31-E37*'Inputs_MSFT'!$B$32-'Inputs_MSFT'!$B$33*(E37-D37) -> 4.3752189e+11 | K37: =F37*'DCF_MSFT'!$B$10*(1-'DCF_MSFT'!$B$14)+F37*'Inputs_MSFT'!$B$31-F37*'Inputs_MSFT'!$B$32-'Inputs_MSFT'!$B$33*(F37-E37) -> 6.1253065e+11 | L37: =K37*(1+'Inputs_MSFT'!$B$29)/('DCF_MSFT'!$B$21-'Inputs_MSFT'!$B$29) -> 8.3707817e+12 | M37: =SUMPRODUCT(G37:K37,1/(1+'DCF_MSFT'!$B$21)^{1,2,3,4,5})+L37/(1+'DCF_MSFT'!$B$21)^5 -> 6.4408805e+12 | N37: =M37-'Inputs_MSFT'!$B$17+'Inputs_MSFT'!$B$18 -> 6.4215215e+12 | O37: =N37/'Inputs_MSFT'!$B$22 -> 864.78784
A38: Direction check: IV increases as revenue growth rises? | B38: =IF(O30<O37,"PASS (as expected)","FAIL — investigate (see note)") -> PASS (as expected)
A41: TABLE 4 — Operating Margin Sensitivity (range [0%,60%]); base revenue path & WACC held fixed
A42: Margin | B42: FCF Y1 | C42: FCF Y2 | D42: FCF Y3 | E42: FCF Y4 | F42: FCF Y5 | G42: Terminal Value | H42: Enterprise Value | I42: Equity Value | J42: Intrinsic Value/Share
A43: 0 | B43: ='DCF_MSFT'!$C$25*$A$43*(1-'DCF_MSFT'!$B$14)+'DCF_MSFT'!$C$28-'DCF_MSFT'!$C$29-'DCF_MSFT'!$C$30 -> -4.2303597e+09 | C43: ='DCF_MSFT'!$D$25*$A$43*(1-'DCF_MSFT'!$B$14)+'DCF_MSFT'!$D$28-'DCF_MSFT'!$D$29-'DCF_MSFT'!$D$30 -> -4.8116597e+09 | D43: ='DCF_MSFT'!$E$25*$A$43*(1-'DCF_MSFT'!$B$14)+'DCF_MSFT'!$E$28-'DCF_MSFT'!$E$29-'DCF_MSFT'!$E$30 -> -5.4728369e+09 | E43: ='DCF_MSFT'!$F$25*$A$43*(1-'DCF_MSFT'!$B$14)+'DCF_MSFT'!$F$28-'DCF_MSFT'!$F$29-'DCF_MSFT'!$F$30 -> -6.2248675e+09 | F43: ='DCF_MSFT'!$G$25*$A$43*(1-'DCF_MSFT'!$B$14)+'DCF_MSFT'!$G$28-'DCF_MSFT'!$G$29-'DCF_MSFT'!$G$30 -> -7.0802357e+09 | G43: =F43*(1+'Inputs_MSFT'!$B$29)/('DCF_MSFT'!$B$21-'Inputs_MSFT'!$B$29) -> -9.6757783e+10 | H43: =SUMPRODUCT(B43:F43,1/(1+'DCF_MSFT'!$B$21)^{1,2,3,4,5})+G43/(1+'DCF_MSFT'!$B$21)^5 -> -8.0659698e+10 | I43: =H43-'Inputs_MSFT'!$B$17+'Inputs_MSFT'!$B$18 -> -1.000187e+11 | J43: =I43/'Inputs_MSFT'!$B$22 -> -13.469542
A44: 0.1 | B44: ='DCF_MSFT'!$C$25*$A$44*(1-'DCF_MSFT'!$B$14)+'DCF_MSFT'!$C$28-'DCF_MSFT'!$C$29-'DCF_MSFT'!$C$30 -> 2.6192511e+10 | C44: ='DCF_MSFT'!$D$25*$A$44*(1-'DCF_MSFT'!$B$14)+'DCF_MSFT'!$D$28-'DCF_MSFT'!$D$29-'DCF_MSFT'!$D$30 -> 2.9791663e+10 | D44: ='DCF_MSFT'!$E$25*$A$44*(1-'DCF_MSFT'!$B$14)+'DCF_MSFT'!$E$28-'DCF_MSFT'!$E$29-'DCF_MSFT'!$E$30 -> 3.3885379e+10 | E44: ='DCF_MSFT'!$F$25*$A$44*(1-'DCF_MSFT'!$B$14)+'DCF_MSFT'!$F$28-'DCF_MSFT'!$F$29-'DCF_MSFT'!$F$30 -> 3.8541619e+10 | F44: ='DCF_MSFT'!$G$25*$A$44*(1-'DCF_MSFT'!$B$14)+'DCF_MSFT'!$G$28-'DCF_MSFT'!$G$29-'DCF_MSFT'!$G$30 -> 4.3837679e+10 | G44: =F44*(1+'Inputs_MSFT'!$B$29)/('DCF_MSFT'!$B$21-'Inputs_MSFT'!$B$29) -> 5.9908127e+11 | H44: =SUMPRODUCT(B44:F44,1/(1+'DCF_MSFT'!$B$21)^{1,2,3,4,5})+G44/(1+'DCF_MSFT'!$B$21)^5 -> 4.9940907e+11 | I44: =H44-'Inputs_MSFT'!$B$17+'Inputs_MSFT'!$B$18 -> 4.8005007e+11 | J44: =I44/'Inputs_MSFT'!$B$22 -> 64.648459
A45: 0.2 | B45: ='DCF_MSFT'!$C$25*$A$45*(1-'DCF_MSFT'!$B$14)+'DCF_MSFT'!$C$28-'DCF_MSFT'!$C$29-'DCF_MSFT'!$C$30 -> 5.6615382e+10 | C45: ='DCF_MSFT'!$D$25*$A$45*(1-'DCF_MSFT'!$B$14)+'DCF_MSFT'!$D$28-'DCF_MSFT'!$D$29-'DCF_MSFT'!$D$30 -> 6.4394985e+10 | D45: ='DCF_MSFT'!$E$25*$A$45*(1-'DCF_MSFT'!$B$14)+'DCF_MSFT'!$E$28-'DCF_MSFT'!$E$29-'DCF_MSFT'!$E$30 -> 7.3243595e+10 | E45: ='DCF_MSFT'!$F$25*$A$45*(1-'DCF_MSFT'!$B$14)+'DCF_MSFT'!$F$28-'DCF_MSFT'!$F$29-'DCF_MSFT'!$F$30 -> 8.3308105e+10 | F45: ='DCF_MSFT'!$G$25*$A$45*(1-'DCF_MSFT'!$B$14)+'DCF_MSFT'!$G$28-'DCF_MSFT'!$G$29-'DCF_MSFT'!$G$30 -> 9.4755594e+10 | G45: =F45*(1+'Inputs_MSFT'!$B$29)/('DCF_MSFT'!$B$21-'Inputs_MSFT'!$B$29) -> 1.2949203e+12 | H45: =SUMPRODUCT(B45:F45,1/(1+'DCF_MSFT'!$B$21)^{1,2,3,4,5})+G45/(1+'DCF_MSFT'!$B$21)^5 -> 1.0794778e+12 | I45: =H45-'Inputs_MSFT'!$B$17+'Inputs_MSFT'!$B$18 -> 1.0601188e+12 | J45: =I45/'Inputs_MSFT'!$B$22 -> 142.76646
A46: 0.3 | B46: ='DCF_MSFT'!$C$25*$A$46*(1-'DCF_MSFT'!$B$14)+'DCF_MSFT'!$C$28-'DCF_MSFT'!$C$29-'DCF_MSFT'!$C$30 -> 8.7038252e+10 | C46: ='DCF_MSFT'!$D$25*$A$46*(1-'DCF_MSFT'!$B$14)+'DCF_MSFT'!$D$28-'DCF_MSFT'!$D$29-'DCF_MSFT'!$D$30 -> 9.8998307e+10 | D46: ='DCF_MSFT'!$E$25*$A$46*(1-'DCF_MSFT'!$B$14)+'DCF_MSFT'!$E$28-'DCF_MSFT'!$E$29-'DCF_MSFT'!$E$30 -> 1.1260181e+11 | E46: ='DCF_MSFT'!$F$25*$A$46*(1-'DCF_MSFT'!$B$14)+'DCF_MSFT'!$F$28-'DCF_MSFT'!$F$29-'DCF_MSFT'!$F$30 -> 1.2807459e+11 | F46: ='DCF_MSFT'!$G$25*$A$46*(1-'DCF_MSFT'!$B$14)+'DCF_MSFT'!$G$28-'DCF_MSFT'!$G$29-'DCF_MSFT'!$G$30 -> 1.4567351e+11 | G46: =F46*(1+'Inputs_MSFT'!$B$29)/('DCF_MSFT'!$B$21-'Inputs_MSFT'!$B$29) -> 1.9907594e+12 | H46: =SUMPRODUCT(B46:F46,1/(1+'DCF_MSFT'!$B$21)^{1,2,3,4,5})+G46/(1+'DCF_MSFT'!$B$21)^5 -> 1.6595466e+12 | I46: =H46-'Inputs_MSFT'!$B$17+'Inputs_MSFT'!$B$18 -> 1.6401876e+12 | J46: =I46/'Inputs_MSFT'!$B$22 -> 220.88446
A47: 0.4 | B47: ='DCF_MSFT'!$C$25*$A$47*(1-'DCF_MSFT'!$B$14)+'DCF_MSFT'!$C$28-'DCF_MSFT'!$C$29-'DCF_MSFT'!$C$30 -> 1.1746112e+11 | C47: ='DCF_MSFT'!$D$25*$A$47*(1-'DCF_MSFT'!$B$14)+'DCF_MSFT'!$D$28-'DCF_MSFT'!$D$29-'DCF_MSFT'!$D$30 -> 1.3360163e+11 | D47: ='DCF_MSFT'!$E$25*$A$47*(1-'DCF_MSFT'!$B$14)+'DCF_MSFT'!$E$28-'DCF_MSFT'!$E$29-'DCF_MSFT'!$E$30 -> 1.5196003e+11 | E47: ='DCF_MSFT'!$F$25*$A$47*(1-'DCF_MSFT'!$B$14)+'DCF_MSFT'!$F$28-'DCF_MSFT'!$F$29-'DCF_MSFT'!$F$30 -> 1.7284108e+11 | F47: ='DCF_MSFT'!$G$25*$A$47*(1-'DCF_MSFT'!$B$14)+'DCF_MSFT'!$G$28-'DCF_MSFT'!$G$29-'DCF_MSFT'!$G$30 -> 1.9659142e+11 | G47: =F47*(1+'Inputs_MSFT'!$B$29)/('DCF_MSFT'!$B$21-'Inputs_MSFT'!$B$29) -> 2.6865984e+12 | H47: =SUMPRODUCT(B47:F47,1/(1+'DCF_MSFT'!$B$21)^{1,2,3,4,5})+G47/(1+'DCF_MSFT'!$B$21)^5 -> 2.2396154e+12 | I47: =H47-'Inputs_MSFT'!$B$17+'Inputs_MSFT'!$B$18 -> 2.2202564e+12 | J47: =I47/'Inputs_MSFT'!$B$22 -> 299.00246
...

Sheet Inputs_CAT
A1: Inputs — CAT (CATERPILLAR INC) | Frozen 2026-08-17T17:23:45.327869+00:00
A2: Profile: Capital-intensive, moderate leverage | CIK 0000018230 | All USD values are actual dollars (not thousands/millions) unless noted.
A4: SECTION 1 — Historical Annual Data (SEC EDGAR, frozen)
A5: Fiscal Year End | B5: Revenue (USD) | C5: EBIT / Operating Income (USD) | D5: Provenance
A6: 44561 | B6: 50971000000 | C6: 6878000000 | D6: XBRL tag: Revenues
A7: 44926 | B7: 59427000000 | C7: 7904000000 | D7: XBRL tag: Revenues
A8: 45291 | B8: 67060000000 | C8: 12966000000 | D8: XBRL tag: Revenues
A9: 45657 | B9: 64809000000 | C9: 13072000000 | D9: XBRL tag: Revenues
A10: 46022 | B10: 67589000000 | C10: 11151000000 | D10: XBRL tag: Revenues
A12: SECTION 2 — Latest-Year Facts (SEC EDGAR, frozen)
A13: Latest Complete Fiscal Year End | B13: 46022
A14: Pretax Income (USD) | B14: 11541000000
A15: Tax Provision (USD) | B15: 2768000000
A16: Interest Expense (USD) | B16: 1842000000 | D16: Method: proxy_cash_paid_interest; tag: InterestPaidNet
A17: Total Debt (USD) | B17: 36210000000 | D17: Total Debt = LongTermDebtNoncurrent ($30,696,000,000) + ShortTermBorrowings ($5,514,000,000) = $36,210,000,000 | Full per-component provenance (XBRL tag, accession, filed date, source URL): see Sources sheet.
A18: Cash & Equivalents (USD) | B18: 9980000000
A20: SECTION 3 — Market Data (Yahoo Finance via yfinance, frozen)
A21: Current Price (USD/share) | B21: 886
A22: Shares Outstanding | B22: 459674889
A23: Beta (levered equity) | B23: 1.605
A24: Sector (GICS) | B24: Industrials
A26: SECTION 4 — Assumptions (shared across companies unless noted; assumptions-register.md)
A27: Risk-free rate (A-001) | B27: 0.04
A28: Market risk premium (A-009) | B28: 0.055
A29: Terminal growth rate, base case (A-003) | B29: 0.025
A30: Projection years | B30: 5
A31: D&A % of revenue (A-004) | B31: 0.03
A32: CapEx % of revenue (A-004) | B32: 0.04
A33: ΔNWC % of revenue change (A-004) | B33: 0.01
A34: WACC clamp — minimum (A-006) | B34: 0.05
A35: WACC clamp — maximum (A-006) | B35: 0.2
A36: Terminal growth clamp — minimum | B36: 0
A37: Terminal growth clamp — maximum | B37: 0.05
A38: Historical revenue growth cap (A-002) | B38: 0.25

Sheet DCF_CAT
A1: DCF Valuation — CAT (CATERPILLAR INC) [V2 — Track A Phase 2C]
A2: Every formula below is entered independently from docs/model-specifications/dcf.md and wacc-capm.md prose/equations — never copied from src/dcf_model/dcf.py. V2: years_elapsed now uses actual fiscal-period-end date subtraction, per the Track A Phase 2C specification clarification (A-028/L-019) — see row below.
A4: SECTION 1 — Historical Revenue CAGR & Operating Margin [dcf.md §Historical revenue-growth and operating-margin derivation]
A5: Years elapsed = (latest fiscal date − earliest fiscal date) / 365.25 [V2; A-028] | B5: =('Inputs_CAT'!$A$10-'Inputs_CAT'!$A$6)/365.25 -> 4 | D5: Spec: dcf.md — years_elapsed is ACTUAL elapsed calendar days between the earliest- and latest-dated valid observations / 365.25, never (periods−1) (A-028; Track A Phase 2C, resolving the ambiguity Phase 2B found).
A6: Diagnostic — naive (N periods − 1) years [V1's convention; NOT used below] | B6: 4 | C6: REGULAR | D6: Fiscal calendar is evenly spaced for this company — actual years_elapsed equals the naive (N periods − 1) count to within floating-point noise, so V1 and V2 agree here by coincidence, not because (periods − 1) is a generally correct convention.
A8: Raw Revenue CAGR = (Rev_latest/Rev_earliest)^(1/years) − 1 | B8: =('Inputs_CAT'!$B$10/'Inputs_CAT'!$B$6)^(1/B5)-1 -> 0.073095112
A9: Capped Revenue CAGR (cap A-002; NOT floored below) | B9: =MIN(B8,'Inputs_CAT'!$B$38) -> 0.073095112 | D9: Spec: dcf.md — capped at MAX_REVENUE_GROWTH_RATE=25%, unbounded below (A-002)
A10: Average Historical Operating Margin = simple average of EBIT_t/Revenue_t | B10: =('Inputs_CAT'!$C$6/'Inputs_CAT'!$B$6+'Inputs_CAT'!$C$7/'Inputs_CAT'!$B$7+'Inputs_CAT'!$C$8/'Inputs_CAT'!$B$8+'Inputs_CAT'!$C$9/'Inputs_CAT'!$B$9+'Inputs_CAT'!$C$10/'Inputs_CAT'!$B$10)/5 -> 0.16559502
A12: SECTION 2 — WACC via CAPM [wacc-capm.md §Formula]
A13: Market Capitalization = Price × Shares Outstanding | B13: ='Inputs_CAT'!$B$21*'Inputs_CAT'!$B$22 -> 407271951654
A14: Effective Tax Rate = Tax Provision / Pretax Income (latest FY) | B14: ='Inputs_CAT'!$B$15/'Inputs_CAT'!$B$14 -> 0.23984057 | D14: Method: derived. Spec: wacc-capm.md — derived as tax_provision/pretax_income, valid range [0,1); DEFAULT_TAX_RATE=21% only on missing data.
A15: Cost of Debt = |Interest Expense| / Total Debt (latest FY) | B15: =ABS('Inputs_CAT'!$B$16)/'Inputs_CAT'!$B$17 -> 0.050869925
A16: Cost of Equity (CAPM) = Rf + Beta × MRP | B16: ='Inputs_CAT'!$B$27+'Inputs_CAT'!$B$23*'Inputs_CAT'!$B$28 -> 0.128275
A17: After-Tax Cost of Debt = Cost of Debt × (1 − Tax Rate) | B17: =B15*(1-B14) -> 0.038669254
A18: Weight of Equity = MktCap / (MktCap + Total Debt) | B18: =B13/(B13+'Inputs_CAT'!$B$17) -> 0.91835068
A19: Weight of Debt = Total Debt / (MktCap + Total Debt) | B19: ='Inputs_CAT'!$B$17/(B13+'Inputs_CAT'!$B$17) -> 0.08164932
A20: Raw WACC = We×Re + Wd×Rd(after-tax) | B20: =B18*B16+B19*B17 -> 0.12095875
A21: Final WACC — clamped to [5%,20%] (A-006), via MEDIAN(raw,min,max) | B21: =MEDIAN(B20,'Inputs_CAT'!$B$34,'Inputs_CAT'!$B$35) -> 0.12095875 | D21: MEDIAN(x,min,max) is a standard single-formula clamp: returns min if x<min, max if x>max, else x.
A23: SECTION 3 — 5-Year Free Cash Flow Projection [dcf.md §Free Cash Flow projection]
B24: Year 0 (base, actual) | C24: Year 1 | D24: Year 2 | E24: Year 3 | F24: Year 4 | G24: Year 5
A25: Revenue = Revenue_(t-1) × (1 + growth) | B25: ='Inputs_CAT'!$B$10 -> 67589000000 | C25: =B25*(1+$B$9) -> 7.2529426e+10 | D25: =C25*(1+$B$9) -> 7.7830972e+10 | E25: =D25*(1+$B$9) -> 8.3520036e+10 | F25: =E25*(1+$B$9) -> 8.9624942e+10 | G25: =F25*(1+$B$9) -> 9.6176087e+10
A26: EBIT = Revenue × Operating Margin | C26: =C25*$B$10 -> 1.2010511e+10 | D26: =D25*$B$10 -> 1.2888421e+10 | E26: =E25*$B$10 -> 1.3830502e+10 | F26: =F25*$B$10 -> 1.4841444e+10 | G26: =G25*$B$10 -> 1.5926281e+10
A27: NOPAT = EBIT × (1 − Tax Rate) | C27: =C26*(1-$B$14) -> 9.1299035e+09 | D27: =D26*(1-$B$14) -> 9.7972548e+09 | E27: =E26*(1-$B$14) -> 1.0513386e+10 | F27: =F26*(1-$B$14) -> 1.1281863e+10 | G27: =G26*(1-$B$14) -> 1.2106512e+10
A28: D&A = Revenue × D&A% (A-004) | C28: =C25*'Inputs_CAT'!$B$31 -> 2.1758828e+09 | D28: =D25*'Inputs_CAT'!$B$31 -> 2.3349292e+09 | E28: =E25*'Inputs_CAT'!$B$31 -> 2.5056011e+09 | F28: =F25*'Inputs_CAT'!$B$31 -> 2.6887483e+09 | G28: =G25*'Inputs_CAT'!$B$31 -> 2.8852826e+09
A29: CapEx = Revenue × CapEx% (A-004) | C29: =C25*'Inputs_CAT'!$B$32 -> 2.901177e+09 | D29: =D25*'Inputs_CAT'!$B$32 -> 3.1132389e+09 | E29: =E25*'Inputs_CAT'!$B$32 -> 3.3408014e+09 | F29: =F25*'Inputs_CAT'!$B$32 -> 3.5849977e+09 | G29: =G25*'Inputs_CAT'!$B$32 -> 3.8470435e+09
A30: ΔNWC = NWC% × (Revenue_t − Revenue_(t-1)) (A-004) | C30: ='Inputs_CAT'!$B$33*(C25-B25) -> 49404255 | D30: ='Inputs_CAT'!$B$33*(D25-C25) -> 53015465 | E30: ='Inputs_CAT'!$B$33*(E25-D25) -> 56890636 | F30: ='Inputs_CAT'!$B$33*(F25-E25) -> 61049064 | G30: ='Inputs_CAT'!$B$33*(G25-F25) -> 65511452
A31: Unlevered FCF = NOPAT + D&A − CapEx − ΔNWC | C31: =C27+C28-C29-C30 -> 8.355205e+09 | D31: =D27+D28-D29-D30 -> 8.9659296e+09 | E31: =E27+E28-E29-E30 -> 9.6212953e+09 | F31: =F27+F28-F29-F30 -> 1.0324565e+10 | G31: =G27+G28-G29-G30 -> 1.107924e+10
A33: SECTION 4 — Terminal Value (Gordon Growth) [dcf.md §Terminal value]
A34: Terminal Value = FCF_Y5 × (1+g) / (WACC − g) | B34: =G31*(1+'Inputs_CAT'!$B$29)/(B21-'Inputs_CAT'!$B$29) -> 1.1834482e+11
A35: Check: Final WACC > Terminal Growth Rate? | B35: =IF(B21>'Inputs_CAT'!$B$29,"PASS","FAIL") -> PASS
A37: SECTION 5 — Discounting & Enterprise-to-Equity Bridge [dcf.md §Discounting and the Enterprise-to-Equity bridge]
A38: PV(FCF_t) = FCF_t / (1+WACC)^t | C38: =C31/(1+$B$21)^1 -> 7.453624e+09 | D38: =D31/(1+$B$21)^2 -> 7.1353628e+09 | E38: =E31/(1+$B$21)^3 -> 6.8306911e+09 | F38: =F31/(1+$B$21)^4 -> 6.5390285e+09 | G38: =G31/(1+$B$21)^5 -> 6.2598196e+09
A39: Sum of PV(FCF Years 1-5) | B39: =SUM(C38:G38) -> 3.4218526e+10
A40: PV(Terminal Value) = TV / (1+WACC)^5 | B40: =B34/(1+B21)^5 -> 6.6865345e+10
A41: Enterprise Value = Sum PV(FCF) + PV(Terminal Value) | B41: =B39+B40 -> 1.0108387e+11
A42: Equity Value = Enterprise Value − Total Debt + Cash | B42: =B41-'Inputs_CAT'!$B$17+'Inputs_CAT'!$B$18 -> 7.4853871e+10
A43: Intrinsic Value per Share = Equity Value / Shares Outstanding | B43: =B42/'Inputs_CAT'!$B$22 -> 162.8409
A44: Current Price / Intrinsic Value (descriptive ratio, NOT a recommendation) | B44: ='Inputs_CAT'!$B$21/B43 -> 5.4408936
A46: SECTION 6 — Validation Checks (local to this company)
A47: WACC within documented clamp [5%,20%]? | B47: =IF(AND(B21>='Inputs_CAT'!$B$34,B21<='Inputs_CAT'!$B$35),"PASS","FAIL") -> PASS
...

Sheet Sensitivity_CAT
A1: Sensitivity Analysis — CAT
A2: One variable at a time, other inputs held at base case. Per docs/independent-validation-plan.md §Sensitivity tables.
A4: TABLE 1 — WACC Sensitivity (range [5%,20%], base FCF path held fixed) [dcf.md Terminal Value + discounting]
A5: WACC | B5: Terminal Value | C5: Enterprise Value | D5: Equity Value | E5: Intrinsic Value/Share
A6: 0.05 | B6: =IF($A$6<='Inputs_CAT'!$B$29,"n/a (WACC<=g)",'DCF_CAT'!$G$31*(1+'Inputs_CAT'!$B$29)/($A$6-'Inputs_CAT'!$B$29)) -> 4.5424885e+11 | C6: =IF(B6="n/a (WACC<=g)","n/a",SUMPRODUCT('DCF_CAT'!$C$31:$G$31,1/(1+$A$6)^{1,2,3,4,5})+B6/(1+$A$6)^5) -> 3.9749171e+11 | D6: =IF(C6="n/a","n/a",C6-'Inputs_CAT'!$B$17+'Inputs_CAT'!$B$18) -> 3.7126171e+11 | E6: =IF(D6="n/a","n/a",D6/'Inputs_CAT'!$B$22) -> 807.66151
A7: 0.075 | B7: =IF($A$7<='Inputs_CAT'!$B$29,"n/a (WACC<=g)",'DCF_CAT'!$G$31*(1+'Inputs_CAT'!$B$29)/($A$7-'Inputs_CAT'!$B$29)) -> 2.2712442e+11 | C7: =IF(B7="n/a (WACC<=g)","n/a",SUMPRODUCT('DCF_CAT'!$C$31:$G$31,1/(1+$A$7)^{1,2,3,4,5})+B7/(1+$A$7)^5) -> 1.9692942e+11 | D7: =IF(C7="n/a","n/a",C7-'Inputs_CAT'!$B$17+'Inputs_CAT'!$B$18) -> 1.7069942e+11 | E7: =IF(D7="n/a","n/a",D7/'Inputs_CAT'!$B$22) -> 371.34814
A8: 0.1 | B8: =IF($A$8<='Inputs_CAT'!$B$29,"n/a (WACC<=g)",'DCF_CAT'!$G$31*(1+'Inputs_CAT'!$B$29)/($A$8-'Inputs_CAT'!$B$29)) -> 1.5141628e+11 | C8: =IF(B8="n/a (WACC<=g)","n/a",SUMPRODUCT('DCF_CAT'!$C$31:$G$31,1/(1+$A$8)^{1,2,3,4,5})+B8/(1+$A$8)^5) -> 1.3018287e+11 | D8: =IF(C8="n/a","n/a",C8-'Inputs_CAT'!$B$17+'Inputs_CAT'!$B$18) -> 1.0395287e+11 | E8: =IF(D8="n/a","n/a",D8/'Inputs_CAT'!$B$22) -> 226.14434
A9: 0.125 | B9: =IF($A$9<='Inputs_CAT'!$B$29,"n/a (WACC<=g)",'DCF_CAT'!$G$31*(1+'Inputs_CAT'!$B$29)/($A$9-'Inputs_CAT'!$B$29)) -> 1.1356221e+11 | C9: =IF(B9="n/a (WACC<=g)","n/a",SUMPRODUCT('DCF_CAT'!$C$31:$G$31,1/(1+$A$9)^{1,2,3,4,5})+B9/(1+$A$9)^5) -> 9.6881109e+10 | D9: =IF(C9="n/a","n/a",C9-'Inputs_CAT'!$B$17+'Inputs_CAT'!$B$18) -> 7.0651109e+10 | E9: =IF(D9="n/a","n/a",D9/'Inputs_CAT'!$B$22) -> 153.698
A10: 0.15 | B10: =IF($A$10<='Inputs_CAT'!$B$29,"n/a (WACC<=g)",'DCF_CAT'!$G$31*(1+'Inputs_CAT'!$B$29)/($A$10-'Inputs_CAT'!$B$29)) -> 9.0849769e+10 | C10: =IF(B10="n/a (WACC<=g)","n/a",SUMPRODUCT('DCF_CAT'!$C$31:$G$31,1/(1+$A$10)^{1,2,3,4,5})+B10/(1+$A$10)^5) -> 7.695092e+10 | D10: =IF(C10="n/a","n/a",C10-'Inputs_CAT'!$B$17+'Inputs_CAT'!$B$18) -> 5.072092e+10 | E10: =IF(D10="n/a","n/a",D10/'Inputs_CAT'!$B$22) -> 110.34085
A11: 0.175 | B11: =IF($A$11<='Inputs_CAT'!$B$29,"n/a (WACC<=g)",'DCF_CAT'!$G$31*(1+'Inputs_CAT'!$B$29)/($A$11-'Inputs_CAT'!$B$29)) -> 7.5708141e+10 | C11: =IF(B11="n/a (WACC<=g)","n/a",SUMPRODUCT('DCF_CAT'!$C$31:$G$31,1/(1+$A$11)^{1,2,3,4,5})+B11/(1+$A$11)^5) -> 6.3701935e+10 | D11: =IF(C11="n/a","n/a",C11-'Inputs_CAT'!$B$17+'Inputs_CAT'!$B$18) -> 3.7471935e+10 | E11: =IF(D11="n/a","n/a",D11/'Inputs_CAT'!$B$22) -> 81.518342
A12: 0.2 | B12: =IF($A$12<='Inputs_CAT'!$B$29,"n/a (WACC<=g)",'DCF_CAT'!$G$31*(1+'Inputs_CAT'!$B$29)/($A$12-'Inputs_CAT'!$B$29)) -> 6.4892692e+10 | C12: =IF(B12="n/a (WACC<=g)","n/a",SUMPRODUCT('DCF_CAT'!$C$31:$G$31,1/(1+$A$12)^{1,2,3,4,5})+B12/(1+$A$12)^5) -> 5.4267359e+10 | D12: =IF(C12="n/a","n/a",C12-'Inputs_CAT'!$B$17+'Inputs_CAT'!$B$18) -> 2.8037359e+10 | E12: =IF(D12="n/a","n/a",D12/'Inputs_CAT'!$B$22) -> 60.993889
A13: Direction check: IV decreases as WACC rises? | B13: =IF(E6>E12,"PASS (as expected)","FAIL — investigate (see note)") -> PASS (as expected)
A16: TABLE 2 — Terminal Growth Rate Sensitivity (range [0%,5%]); invalid where g>=WACC
A17: Terminal Growth g | B17: Terminal Value | C17: Enterprise Value | D17: Equity Value | E17: Intrinsic Value/Share
A18: 0 | B18: =IF($A$18>='DCF_CAT'!$B$21,"n/a (g>=WACC)",'DCF_CAT'!$G$31*(1+$A$18)/('DCF_CAT'!$B$21-$A$18)) -> 9.1595193e+10 | C18: =IF(B18="n/a (g>=WACC)","n/a",'DCF_CAT'!$B$39+B18/(1+'DCF_CAT'!$B$21)^5) -> 8.5970214e+10 | D18: =IF(C18="n/a","n/a",C18-'Inputs_CAT'!$B$17+'Inputs_CAT'!$B$18) -> 5.9740214e+10 | E18: =IF(D18="n/a","n/a",D18/'Inputs_CAT'!$B$22) -> 129.96188
A19: 0.01 | B19: =IF($A$19>='DCF_CAT'!$B$21,"n/a (g>=WACC)",'DCF_CAT'!$G$31*(1+$A$19)/('DCF_CAT'!$B$21-$A$19)) -> 1.0084858e+11 | C19: =IF(B19="n/a (g>=WACC)","n/a",'DCF_CAT'!$B$39+B19/(1+'DCF_CAT'!$B$21)^5) -> 9.1198419e+10 | D19: =IF(C19="n/a","n/a",C19-'Inputs_CAT'!$B$17+'Inputs_CAT'!$B$18) -> 6.4968419e+10 | E19: =IF(D19="n/a","n/a",D19/'Inputs_CAT'!$B$22) -> 141.33558
A20: 0.02 | B20: =IF($A$20>='DCF_CAT'!$B$21,"n/a (g>=WACC)",'DCF_CAT'!$G$31*(1+$A$20)/('DCF_CAT'!$B$21-$A$20)) -> 1.1193507e+11 | C20: =IF(B20="n/a (g>=WACC)","n/a",'DCF_CAT'!$B$39+B20/(1+'DCF_CAT'!$B$21)^5) -> 9.7462335e+10 | D20: =IF(C20="n/a","n/a",C20-'Inputs_CAT'!$B$17+'Inputs_CAT'!$B$18) -> 7.1232335e+10 | E20: =IF(D20="n/a","n/a",D20/'Inputs_CAT'!$B$22) -> 154.96242
