Workbook

Sheet Tolerances
A1: Tolerance constants -- single source of truth for every comparison table's Tolerance column
A2: Metric | B2: Tolerance | C2: Kind
A3: Revenue CAGR | B3: 0.0001 | C3: percentage points
A4: Operating Margin | B4: 0.0001 | C4: percentage points
A5: WACC | B5: 0.0005 | C5: percentage points
A6: Each FCF year | B6: 0.001 | C6: relative fraction
A7: Terminal Value | B7: 0.002 | C7: relative fraction
A8: PV of Explicit FCF | B8: 0.002 | C8: relative fraction
A9: PV of Terminal Value | B9: 0.002 | C9: relative fraction
A10: Enterprise Value | B10: 0.002 | C10: relative fraction
A11: Equity Value | B11: 0.002 | C11: relative fraction
A12: Intrinsic Value per Share | B12: 0.005 | C12: relative fraction
A13: Sensitivity IVPS (all tables) | B13: 0.005 | C13: relative fraction
A14: Zero-denominator floating-point carve-out (absolute $) | B14: 1e-06 | C14: absolute $

Sheet README
A1: DCF Codebase-to-Independent-Workbook Reconciliation (V2)
A2: Track A Phase 2C. This workbook reconciles src/dcf_model/dcf.py's production output against the independent workbook V2 (validation/independent_dcf/independent_dcf_validation_v2.xlsx), built from the corrected years_elapsed specification. V1 is preserved unchanged and never modified by this workbook or by any script in validation/dcf_reconciliation/.
A4: Sheets:
A5: - Tolerances: the single source of truth for every tolerance constant used elsewhere.
A6: - Base Reconciliation: all 14 required metrics x 4 companies, live-formula comparison.
A7: - Detail_<TICKER>: per-company base reconciliation + accurate sensitivity coverage counts.
A8: - Sensitivity Reconciliation: Table 1/2 full live-formula detail + coverage-count summary.
A9: - All Sensitivity Comparisons: EVERY Table 1-5 scalar comparison (908 rows), formula-driven.
A10: - Findings: narrative summary of what was (and wasn't) found.
A11: - Sign-off: commit/hash provenance (V1 AND V2) and outstanding second-reviewer requirement.
A13: Source commit: 776e76f56e6210f1050caa74c60962ed89162496 (branch remediation/valuation-engine-production-quality)
A14: V1 workbook SHA-256 (preserved, historical): 942b5f096cf546d63487add31eb29b1b690f0819f923f01436093f9bbc75eba1
... A17: PROFITABILITY NOT ESTABLISHED -- this workbook verifies calculation agreement between two independent implementations. It is not investment advice and does not establish that any company is profitable to trade.

Sheet Base Reconciliation
A1: Base-case reconciliation -- all four companies, all 14 required metrics
A2: Codebase/Workbook columns are hardcoded values imported from codebase_outputs.json and the independent workbook V2's cached cells (yellow fill). Absolute Difference / Relative-or-pp Difference / Tolerance / PASS-FAIL are live formulas (white fill). Number formats: percentages for rates, $ for dollar amounts, $0.00 for per-share values -- never conflated.
A4: Metric | B4: Codebase Output | C4: Workbook Output | D4: Absolute Difference | E4: Relative/pp Difference | F4: Tolerance | G4: PASS/FAIL | H4: Workbook Cell
A5: -- MSFT (Microsoft Corporation) --
A6: Historical Revenue CAGR | B6: 0.13741147 | C6: 0.13741147 | D6: =ABS(B6-C6) -> 0 | E6: =D6 -> 0 | F6: ='Tolerances'!$B$3 -> 0.0001 | G6: =IF(D6<=F6,"PASS","FAIL") -> PASS | H6: DCF_MSFT!B9
A7: Historical average Operating Margin | B7: 0.44175047 | C7: 0.44175047 | D7: =ABS(B7-C7) -> 0 | E7: =D7 -> 0 | F7: ='Tolerances'!$B$4 -> 0.0001 | G7: =IF(D7<=F7,"PASS","FAIL") -> PASS | H7: DCF_MSFT!B10
A8: WACC (final, clamped [5%,20%]) | B8: 0.10000422 | C8: 0.10000422 | D8: =ABS(B8-C8) -> 0 | E8: =D8 -> 0 | F8: ='Tolerances'!$B$5 -> 0.0005 | G8: =IF(D8<=F8,"PASS","FAIL") -> PASS | H8: DCF_MSFT!B21
A9: FCF Year 1 | B9: 1.3016281e+11 | C9: 1.3016281e+11 | D9: =ABS(B9-C9) -> 0 | E9: =IF(C9=0,"n/a (zero denom)",D9/ABS(C9)) -> 0 | F9: ='Tolerances'!$B$6 -> 0.001 | G9: =IF(C9=0,IF(D9<=0.000001,"PASS","FAIL"),IF(E9<=F9,"PASS","FAIL")) -> PASS | H9: DCF_MSFT!C31
A10: FCF Year 2 | B10: 1.4804868e+11 | C10: 1.4804868e+11 | D10: =ABS(B10-C10) -> 0 | E10: =IF(C10=0,"n/a (zero denom)",D10/ABS(C10)) -> 0 | F10: ='Tolerances'!$B$6 -> 0.001 | G10: =IF(C10=0,IF(D10<=0.000001,"PASS","FAIL"),IF(E10<=F10,"PASS","FAIL")) -> PASS | H10: DCF_MSFT!D31
A11: FCF Year 3 | B11: 1.6839226e+11 | C11: 1.6839226e+11 | D11: =ABS(B11-C11) -> 0 | E11: =IF(C11=0,"n/a (zero denom)",D11/ABS(C11)) -> 0 | F11: ='Tolerances'!$B$6 -> 0.001 | G11: =IF(C11=0,IF(D11<=0.000001,"PASS","FAIL"),IF(E11<=F11,"PASS","FAIL")) -> PASS | H11: DCF_MSFT!E31
A12: FCF Year 4 | B12: 1.9153129e+11 | C12: 1.9153129e+11 | D12: =ABS(B12-C12) -> 0 | E12: =IF(C12=0,"n/a (zero denom)",D12/ABS(C12)) -> 0 | F12: ='Tolerances'!$B$6 -> 0.001 | G12: =IF(C12=0,IF(D12<=0.000001,"PASS","FAIL"),IF(E12<=F12,"PASS","FAIL")) -> PASS | H12: DCF_MSFT!F31
A13: FCF Year 5 | B13: 2.1784989e+11 | C13: 2.1784989e+11 | D13: =ABS(B13-C13) -> 0 | E13: =IF(C13=0,"n/a (zero denom)",D13/ABS(C13)) -> 0 | F13: ='Tolerances'!$B$6 -> 0.001 | G13: =IF(C13=0,IF(D13<=0.000001,"PASS","FAIL"),IF(E13<=F13,"PASS","FAIL")) -> PASS | H13: DCF_MSFT!G31
A14: Terminal Value | B14: 2.9771145e+12 | C14: 2.9771145e+12 | D14: =ABS(B14-C14) -> 0 | E14: =IF(C14=0,"n/a (zero denom)",D14/ABS(C14)) -> 0 | F14: ='Tolerances'!$B$7 -> 0.002 | G14: =IF(C14=0,IF(D14<=0.000001,"PASS","FAIL"),IF(E14<=F14,"PASS","FAIL")) -> PASS | H14: DCF_MSFT!B34
A15: PV of Explicit FCF (sum of pv_fcf series) | B15: 6.3327836e+11 | C15: 6.3327836e+11 | D15: =ABS(B15-C15) -> 0 | E15: =IF(C15=0,"n/a (zero denom)",D15/ABS(C15)) -> 0 | F15: ='Tolerances'!$B$8 -> 0.002 | G15: =IF(C15=0,IF(D15<=0.000001,"PASS","FAIL"),IF(E15<=F15,"PASS","FAIL")) -> PASS | H15: DCF_MSFT!B39
A16: PV of Terminal Value | B16: 1.8485184e+12 | C16: 1.8485184e+12 | D16: =ABS(B16-C16) -> 0 | E16: =IF(C16=0,"n/a (zero denom)",D16/ABS(C16)) -> 0 | F16: ='Tolerances'!$B$9 -> 0.002 | G16: =IF(C16=0,IF(D16<=0.000001,"PASS","FAIL"),IF(E16<=F16,"PASS","FAIL")) -> PASS | H16: DCF_MSFT!B40
A17: Enterprise Value | B17: 2.4817968e+12 | C17: 2.4817968e+12 | D17: =ABS(B17-C17) -> 0 | E17: =IF(C17=0,"n/a (zero denom)",D17/ABS(C17)) -> 0 | F17: ='Tolerances'!$B$10 -> 0.002 | G17: =IF(C17=0,IF(D17<=0.000001,"PASS","FAIL"),IF(E17<=F17,"PASS","FAIL")) -> PASS | H17: DCF_MSFT!B41
A18: Equity Value | B18: 2.4624378e+12 | C18: 2.4624378e+12 | D18: =ABS(B18-C18) -> 0 | E18: =IF(C18=0,"n/a (zero denom)",D18/ABS(C18)) -> 0 | F18: ='Tolerances'!$B$11 -> 0.002 | G18: =IF(C18=0,IF(D18<=0.000001,"PASS","FAIL"),IF(E18<=F18,"PASS","FAIL")) -> PASS | H18: DCF_MSFT!B42
A19: Intrinsic Value per Share | B19: 331.61709 | C19: 331.61709 | D19: =ABS(B19-C19) -> 0 | E19: =IF(C19=0,"n/a (zero denom)",D19/ABS(C19)) -> 0 | F19: ='Tolerances'!$B$12 -> 0.005 | G19: =IF(C19=0,IF(D19<=0.000001,"PASS","FAIL"),IF(E19<=F19,"PASS","FAIL")) -> PASS | H19: DCF_MSFT!B43
A20: -- CAT (Caterpillar Inc.) --
A21: Historical Revenue CAGR | B21: 0.073095112 | C21: 0.073095112 | D21: =ABS(B21-C21) -> 0 | E21: =D21 -> 0 | F21: ='Tolerances'!$B$3 -> 0.0001 | G21: =IF(D21<=F21,"PASS","FAIL") -> PASS | H21: DCF_CAT!B9
A22: Historical average Operating Margin | B22: 0.16559502 | C22: 0.16559502 | D22: =ABS(B22-C22) -> 0 | E22: =D22 -> 0 | F22: ='Tolerances'!$B$4 -> 0.0001 | G22: =IF(D22<=F22,"PASS","FAIL") -> PASS | H22: DCF_CAT!B10
A23: WACC (final, clamped [5%,20%]) | B23: 0.12095875 | C23: 0.12095875 | D23: =ABS(B23-C23) -> 0 | E23: =D23 -> 0 | F23: ='Tolerances'!$B$5 -> 0.0005 | G23: =IF(D23<=F23,"PASS","FAIL") -> PASS | H23: DCF_CAT!B21
A24: FCF Year 1 | B24: 8.355205e+09 | C24: 8.355205e+09 | D24: =ABS(B24-C24) -> 0 | E24: =IF(C24=0,"n/a (zero denom)",D24/ABS(C24)) -> 0 | F24: ='Tolerances'!$B$6 -> 0.001 | G24: =IF(C24=0,IF(D24<=0.000001,"PASS","FAIL"),IF(E24<=F24,"PASS","FAIL")) -> PASS | H24: DCF_CAT!C31
A25: FCF Year 2 | B25: 8.9659296e+09 | C25: 8.9659296e+09 | D25: =ABS(B25-C25) -> 0 | E25: =IF(C25=0,"n/a (zero denom)",D25/ABS(C25)) -> 0 | F25: ='Tolerances'!$B$6 -> 0.001 | G25: =IF(C25=0,IF(D25<=0.000001,"PASS","FAIL"),IF(E25<=F25,"PASS","FAIL")) -> PASS | H25: DCF_CAT!D31
A26: FCF Year 3 | B26: 9.6212953e+09 | C26: 9.6212953e+09 | D26: =ABS(B26-C26) -> 0 | E26: =IF(C26=0,"n/a (zero denom)",D26/ABS(C26)) -> 0 | F26: ='Tolerances'!$B$6 -> 0.001 | G26: =IF(C26=0,IF(D26<=0.000001,"PASS","FAIL"),IF(E26<=F26,"PASS","FAIL")) -> PASS | H26: DCF_CAT!E31
A27: FCF Year 4 | B27: 1.0324565e+10 | C27: 1.0324565e+10 | D27: =ABS(B27-C27) -> 0 | E27: =IF(C27=0,"n/a (zero denom)",D27/ABS(C27)) -> 0 | F27: ='Tolerances'!$B$6 -> 0.001 | G27: =IF(C27=0,IF(D27<=0.000001,"PASS","FAIL"),IF(E27<=F27,"PASS","FAIL")) -> PASS | H27: DCF_CAT!F31
A28: FCF Year 5 | B28: 1.107924e+10 | C28: 1.107924e+10 | D28: =ABS(B28-C28) -> 0 | E28: =IF(C28=0,"n/a (zero denom)",D28/ABS(C28)) -> 0 | F28: ='Tolerances'!$B$6 -> 0.001 | G28: =IF(C28=0,IF(D28<=0.000001,"PASS","FAIL"),IF(E28<=F28,"PASS","FAIL")) -> PASS | H28: DCF_CAT!G31
A29: Terminal Value | B29: 1.1834482e+11 | C29: 1.1834482e+11 | D29: =ABS(B29-C29) -> 0 | E29: =IF(C29=0,"n/a (zero denom)",D29/ABS(C29)) -> 0 | F29: ='Tolerances'!$B$7 -> 0.002 | G29: =IF(C29=0,IF(D29<=0.000001,"PASS","FAIL"),IF(E29<=F29,"PASS","FAIL")) -> PASS | H29: DCF_CAT!B34
A30: PV of Explicit FCF (sum of pv_fcf series) | B30: 3.4218526e+10 | C30: 3.4218526e+10 | D30: =ABS(B30-C30) -> 0 | E30: =IF(C30=0,"n/a (zero denom)",D30/ABS(C30)) -> 0 | F30: ='Tolerances'!$B$8 -> 0.002 | G30: =IF(C30=0,IF(D30<=0.000001,"PASS","FAIL"),IF(E30<=F30,"PASS","FAIL")) -> PASS | H30: DCF_CAT!B39
A31: PV of Terminal Value | B31: 6.6865345e+10 | C31: 6.6865345e+10 | D31: =ABS(B31-C31) -> 0 | E31: =IF(C31=0,"n/a (zero denom)",D31/ABS(C31)) -> 0 | F31: ='Tolerances'!$B$9 -> 0.002 | G31: =IF(C31=0,IF(D31<=0.000001,"PASS","FAIL"),IF(E31<=F31,"PASS","FAIL")) -> PASS | H31: DCF_CAT!B40
A32: Enterprise Value | B32: 1.0108387e+11 | C32: 1.0108387e+11 | D32: =ABS(B32-C32) -> 0 | E32: =IF(C32=0,"n/a (zero denom)",D32/ABS(C32)) -> 0 | F32: ='Tolerances'!$B$10 -> 0.002 | G32: =IF(C32=0,IF(D32<=0.000001,"PASS","FAIL"),IF(E32<=F32,"PASS","FAIL")) -> PASS | H32: DCF_CAT!B41
A33: Equity Value | B33: 7.4853871e+10 | C33: 7.4853871e+10 | D33: =ABS(B33-C33) -> 0 | E33: =IF(C33=0,"n/a (zero denom)",D33/ABS(C33)) -> 0 | F33: ='Tolerances'!$B$11 -> 0.002 | G33: =IF(C33=0,IF(D33<=0.000001,"PASS","FAIL"),IF(E33<=F33,"PASS","FAIL")) -> PASS | H33: DCF_CAT!B42
A34: Intrinsic Value per Share | B34: 162.8409 | C34: 162.8409 | D34: =ABS(B34-C34) -> 0 | E34: =IF(C34=0,"n/a (zero denom)",D34/ABS(C34)) -> 0 | F34: ='Tolerances'!$B$12 -> 0.005 | G34: =IF(C34=0,IF(D34<=0.000001,"PASS","FAIL"),IF(E34<=F34,"PASS","FAIL")) -> PASS | H34: DCF_CAT!B43
A35: -- INTC (Intel Corporation) --
A36: Historical Revenue CAGR | B36: -0.095544173 | C36: -0.095544173 | D36: =ABS(B36-C36) -> 0 | E36: =D36 -> 0 | F36: ='Tolerances'!$B$3 -> 0.0001 | G36: =IF(D36<=F36,"PASS","FAIL") -> PASS | H36: DCF_INTC!B9
A37: Historical average Operating Margin | B37: 0.0046248517 | C37: 0.0046248517 | D37: =ABS(B37-C37) -> 0 | E37: =D37 -> 0 | F37: ='Tolerances'!$B$4 -> 0.0001 | G37: =IF(D37<=F37,"PASS","FAIL") -> PASS | H37: DCF_INTC!B10
A38: WACC (final, clamped [5%,20%]) | B38: 0.15054645 | C38: 0.15054645 | D38: =ABS(B38-C38) -> 0 | E38: =D38 -> 0 | F38: ='Tolerances'!$B$5 -> 0.0005 | G38: =IF(D38<=F38,"PASS","FAIL") -> PASS | H38: DCF_INTC!B21
A39: FCF Year 1 | B39: -4.2384226e+08 | C39: -4.2384226e+08 | D39: =ABS(B39-C39) -> 0 | E39: =IF(C39=0,"n/a (zero denom)",D39/ABS(C39)) -> 0 | F39: ='Tolerances'!$B$6 -> 0.001 | G39: =IF(C39=0,IF(D39<=0.000001,"PASS","FAIL"),IF(E39<=F39,"PASS","FAIL")) -> PASS | H39: DCF_INTC!C31
A40: FCF Year 2 | B40: -3.8334661e+08 | C40: -3.8334661e+08 | D40: =ABS(B40-C40) -> 0 | E40: =IF(C40=0,"n/a (zero denom)",D40/ABS(C40)) -> 0 | F40: ='Tolerances'!$B$6 -> 0.001 | G40: =IF(C40=0,IF(D40<=0.000001,"PASS","FAIL"),IF(E40<=F40,"PASS","FAIL")) -> PASS | H40: DCF_INTC!D31
A41: FCF Year 3 | B41: -3.4672007e+08 | C41: -3.4672007e+08 | D41: =ABS(B41-C41) -> 0 | E41: =IF(C41=0,"n/a (zero denom)",D41/ABS(C41)) -> 0 | F41: ='Tolerances'!$B$6 -> 0.001 | G41: =IF(C41=0,IF(D41<=0.000001,"PASS","FAIL"),IF(E41<=F41,"PASS","FAIL")) -> PASS | H41: DCF_INTC!E31
...

Sheet Detail_MSFT
A1: Detailed base-case reconciliation -- MSFT (Microsoft Corporation)
A2: All metrics within tolerance.
A4: Metric | B4: Codebase Output | C4: Workbook Output | D4: Absolute Difference | E4: Relative/pp Difference | F4: Tolerance | G4: PASS/FAIL | H4: Workbook Cell
A5: Historical Revenue CAGR | B5: 0.13741147 | C5: 0.13741147 | D5: =ABS(B5-C5) -> 0 | E5: =D5 -> 0 | F5: ='Tolerances'!$B$3 -> 0.0001 | G5: =IF(D5<=F5,"PASS","FAIL") -> PASS | H5: DCF_MSFT!B9
A6: Historical average Operating Margin | B6: 0.44175047 | C6: 0.44175047 | D6: =ABS(B6-C6) -> 0 | E6: =D6 -> 0 | F6: ='Tolerances'!$B$4 -> 0.0001 | G6: =IF(D6<=F6,"PASS","FAIL") -> PASS | H6: DCF_MSFT!B10
A7: WACC (final, clamped [5%,20%]) | B7: 0.10000422 | C7: 0.10000422 | D7: =ABS(B7-C7) -> 0 | E7: =D7 -> 0 | F7: ='Tolerances'!$B$5 -> 0.0005 | G7: =IF(D7<=F7,"PASS","FAIL") -> PASS | H7: DCF_MSFT!B21
A8: FCF Year 1 | B8: 1.3016281e+11 | C8: 1.3016281e+11 | D8: =ABS(B8-C8) -> 0 | E8: =IF(C8=0,"n/a (zero denom)",D8/ABS(C8)) -> 0 | F8: ='Tolerances'!$B$6 -> 0.001 | G8: =IF(C8=0,IF(D8<=0.000001,"PASS","FAIL"),IF(E8<=F8,"PASS","FAIL")) -> PASS | H8: DCF_MSFT!C31
A9: FCF Year 2 | B9: 1.4804868e+11 | C9: 1.4804868e+11 | D9: =ABS(B9-C9) -> 0 | E9: =IF(C9=0,"n/a (zero denom)",D9/ABS(C9)) -> 0 | F9: ='Tolerances'!$B$6 -> 0.001 | G9: =IF(C9=0,IF(D9<=0.000001,"PASS","FAIL"),IF(E9<=F9,"PASS","FAIL")) -> PASS | H9: DCF_MSFT!D31
A10: FCF Year 3 | B10: 1.6839226e+11 | C10: 1.6839226e+11 | D10: =ABS(B10-C10) -> 0 | E10: =IF(C10=0,"n/a (zero denom)",D10/ABS(C10)) -> 0 | F10: ='Tolerances'!$B$6 -> 0.001 | G10: =IF(C10=0,IF(D10<=0.000001,"PASS","FAIL"),IF(E10<=F10,"PASS","FAIL")) -> PASS | H10: DCF_MSFT!E31
A11: FCF Year 4 | B11: 1.9153129e+11 | C11: 1.9153129e+11 | D11: =ABS(B11-C11) -> 0 | E11: =IF(C11=0,"n/a (zero denom)",D11/ABS(C11)) -> 0 | F11: ='Tolerances'!$B$6 -> 0.001 | G11: =IF(C11=0,IF(D11<=0.000001,"PASS","FAIL"),IF(E11<=F11,"PASS","FAIL")) -> PASS | H11: DCF_MSFT!F31
A12: FCF Year 5 | B12: 2.1784989e+11 | C12: 2.1784989e+11 | D12: =ABS(B12-C12) -> 0 | E12: =IF(C12=0,"n/a (zero denom)",D12/ABS(C12)) -> 0 | F12: ='Tolerances'!$B$6 -> 0.001 | G12: =IF(C12=0,IF(D12<=0.000001,"PASS","FAIL"),IF(E12<=F12,"PASS","FAIL")) -> PASS | H12: DCF_MSFT!G31
A13: Terminal Value | B13: 2.9771145e+12 | C13: 2.9771145e+12 | D13: =ABS(B13-C13) -> 0 | E13: =IF(C13=0,"n/a (zero denom)",D13/ABS(C13)) -> 0 | F13: ='Tolerances'!$B$7 -> 0.002 | G13: =IF(C13=0,IF(D13<=0.000001,"PASS","FAIL"),IF(E13<=F13,"PASS","FAIL")) -> PASS | H13: DCF_MSFT!B34
A14: PV of Explicit FCF (sum of pv_fcf series) | B14: 6.3327836e+11 | C14: 6.3327836e+11 | D14: =ABS(B14-C14) -> 0 | E14: =IF(C14=0,"n/a (zero denom)",D14/ABS(C14)) -> 0 | F14: ='Tolerances'!$B$8 -> 0.002 | G14: =IF(C14=0,IF(D14<=0.000001,"PASS","FAIL"),IF(E14<=F14,"PASS","FAIL")) -> PASS | H14: DCF_MSFT!B39
A15: PV of Terminal Value | B15: 1.8485184e+12 | C15: 1.8485184e+12 | D15: =ABS(B15-C15) -> 0 | E15: =IF(C15=0,"n/a (zero denom)",D15/ABS(C15)) -> 0 | F15: ='Tolerances'!$B$9 -> 0.002 | G15: =IF(C15=0,IF(D15<=0.000001,"PASS","FAIL"),IF(E15<=F15,"PASS","FAIL")) -> PASS | H15: DCF_MSFT!B40
A16: Enterprise Value | B16: 2.4817968e+12 | C16: 2.4817968e+12 | D16: =ABS(B16-C16) -> 0 | E16: =IF(C16=0,"n/a (zero denom)",D16/ABS(C16)) -> 0 | F16: ='Tolerances'!$B$10 -> 0.002 | G16: =IF(C16=0,IF(D16<=0.000001,"PASS","FAIL"),IF(E16<=F16,"PASS","FAIL")) -> PASS | H16: DCF_MSFT!B41
A17: Equity Value | B17: 2.4624378e+12 | C17: 2.4624378e+12 | D17: =ABS(B17-C17) -> 0 | E17: =IF(C17=0,"n/a (zero denom)",D17/ABS(C17)) -> 0 | F17: ='Tolerances'!$B$11 -> 0.002 | G17: =IF(C17=0,IF(D17<=0.000001,"PASS","FAIL"),IF(E17<=F17,"PASS","FAIL")) -> PASS | H17: DCF_MSFT!B42
A18: Intrinsic Value per Share | B18: 331.61709 | C18: 331.61709 | D18: =ABS(B18-C18) -> 0 | E18: =IF(C18=0,"n/a (zero denom)",D18/ABS(C18)) -> 0 | F18: ='Tolerances'!$B$12 -> 0.005 | G18: =IF(C18=0,IF(D18<=0.000001,"PASS","FAIL"),IF(E18<=F18,"PASS","FAIL")) -> PASS | H18: DCF_MSFT!B43
A20: Sensitivity reconciliation coverage (full per-cell detail: 'All Sensitivity Comparisons' sheet)
A21: Table | B21: Scenario Rows | C21: Outputs / Row | D21: Scalar Comparisons | E21: All Pass
A22: Table 1 -- WACC | B22: 7 | C22: 4 | D22: =B22*C22 -> 28 | E22: PASS
A23: Table 2 -- Terminal growth | B23: 7 | C23: 4 | D23: =B23*C23 -> 28 | E23: PASS
A24: Table 3 -- Revenue growth | B24: 8 | C24: 9 | D24: =B24*C24 -> 72 | E24: PASS
A25: Table 4 -- Operating margin | B25: 7 | C25: 9 | D25: =B25*C25 -> 63 | E25: PASS
A26: Table 5 -- WACC x g two-way grid | B26: 36 | C26: 1 | D26: =B26*C26 -> 36 | E26: PASS
A27: TOTAL (this company) | D27: =SUM(D22:D26) -> 227

Sheet Detail_CAT
A1: Detailed base-case reconciliation -- CAT (Caterpillar Inc.)
A2: All metrics within tolerance.
A4: Metric | B4: Codebase Output | C4: Workbook Output | D4: Absolute Difference | E4: Relative/pp Difference | F4: Tolerance | G4: PASS/FAIL | H4: Workbook Cell
A5: Historical Revenue CAGR | B5: 0.073095112 | C5: 0.073095112 | D5: =ABS(B5-C5) -> 0 | E5: =D5 -> 0 | F5: ='Tolerances'!$B$3 -> 0.0001 | G5: =IF(D5<=F5,"PASS","FAIL") -> PASS | H5: DCF_CAT!B9
A6: Historical average Operating Margin | B6: 0.16559502 | C6: 0.16559502 | D6: =ABS(B6-C6) -> 0 | E6: =D6 -> 0 | F6: ='Tolerances'!$B$4 -> 0.0001 | G6: =IF(D6<=F6,"PASS","FAIL") -> PASS | H6: DCF_CAT!B10
A7: WACC (final, clamped [5%,20%]) | B7: 0.12095875 | C7: 0.12095875 | D7: =ABS(B7-C7) -> 0 | E7: =D7 -> 0 | F7: ='Tolerances'!$B$5 -> 0.0005 | G7: =IF(D7<=F7,"PASS","FAIL") -> PASS | H7: DCF_CAT!B21
A8: FCF Year 1 | B8: 8.355205e+09 | C8: 8.355205e+09 | D8: =ABS(B8-C8) -> 0 | E8: =IF(C8=0,"n/a (zero denom)",D8/ABS(C8)) -> 0 | F8: ='Tolerances'!$B$6 -> 0.001 | G8: =IF(C8=0,IF(D8<=0.000001,"PASS","FAIL"),IF(E8<=F8,"PASS","FAIL")) -> PASS | H8: DCF_CAT!C31
A9: FCF Year 2 | B9: 8.9659296e+09 | C9: 8.9659296e+09 | D9: =ABS(B9-C9) -> 0 | E9: =IF(C9=0,"n/a (zero denom)",D9/ABS(C9)) -> 0 | F9: ='Tolerances'!$B$6 -> 0.001 | G9: =IF(C9=0,IF(D9<=0.000001,"PASS","FAIL"),IF(E9<=F9,"PASS","FAIL")) -> PASS | H9: DCF_CAT!D31
A10: FCF Year 3 | B10: 9.6212953e+09 | C10: 9.6212953e+09 | D10: =ABS(B10-C10) -> 0 | E10: =IF(C10=0,"n/a (zero denom)",D10/ABS(C10)) -> 0 | F10: ='Tolerances'!$B$6 -> 0.001 | G10: =IF(C10=0,IF(D10<=0.000001,"PASS","FAIL"),IF(E10<=F10,"PASS","FAIL")) -> PASS | H10: DCF_CAT!E31
A11: FCF Year 4 | B11: 1.0324565e+10 | C11: 1.0324565e+10 | D11: =ABS(B11-C11) -> 0 | E11: =IF(C11=0,"n/a (zero denom)",D11/ABS(C11)) -> 0 | F11: ='Tolerances'!$B$6 -> 0.001 | G11: =IF(C11=0,IF(D11<=0.000001,"PASS","FAIL"),IF(E11<=F11,"PASS","FAIL")) -> PASS | H11: DCF_CAT!F31
A12: FCF Year 5 | B12: 1.107924e+10 | C12: 1.107924e+10 | D12: =ABS(B12-C12) -> 0 | E12: =IF(C12=0,"n/a (zero denom)",D12/ABS(C12)) -> 0 | F12: ='Tolerances'!$B$6 -> 0.001 | G12: =IF(C12=0,IF(D12<=0.000001,"PASS","FAIL"),IF(E12<=F12,"PASS","FAIL")) -> PASS | H12: DCF_CAT!G31
A13: Terminal Value | B13: 1.1834482e+11 | C13: 1.1834482e+11 | D13: =ABS(B13-C13) -> 0 | E13: =IF(C13=0,"n/a (zero denom)",D13/ABS(C13)) -> 0 | F13: ='Tolerances'!$B$7 -> 0.002 | G13: =IF(C13=0,IF(D13<=0.000001,"PASS","FAIL"),IF(E13<=F13,"PASS","FAIL")) -> PASS | H13: DCF_CAT!B34
A14: PV of Explicit FCF (sum of pv_fcf series) | B14: 3.4218526e+10 | C14: 3.4218526e+10 | D14: =ABS(B14-C14) -> 0 | E14: =IF(C14=0,"n/a (zero denom)",D14/ABS(C14)) -> 0 | F14: ='Tolerances'!$B$8 -> 0.002 | G14: =IF(C14=0,IF(D14<=0.000001,"PASS","FAIL"),IF(E14<=F14,"PASS","FAIL")) -> PASS | H14: DCF_CAT!B39
A15: PV of Terminal Value | B15: 6.6865345e+10 | C15: 6.6865345e+10 | D15: =ABS(B15-C15) -> 0 | E15: =IF(C15=0,"n/a (zero denom)",D15/ABS(C15)) -> 0 | F15: ='Tolerances'!$B$9 -> 0.002 | G15: =IF(C15=0,IF(D15<=0.000001,"PASS","FAIL"),IF(E15<=F15,"PASS","FAIL")) -> PASS | H15: DCF_CAT!B40
A16: Enterprise Value | B16: 1.0108387e+11 | C16: 1.0108387e+11 | D16: =ABS(B16-C16) -> 0 | E16: =IF(C16=0,"n/a (zero denom)",D16/ABS(C16)) -> 0 | F16: ='Tolerances'!$B$10 -> 0.002 | G16: =IF(C16=0,IF(D16<=0.000001,"PASS","FAIL"),IF(E16<=F16,"PASS","FAIL")) -> PASS | H16: DCF_CAT!B41
A17: Equity Value | B17: 7.4853871e+10 | C17: 7.4853871e+10 | D17: =ABS(B17-C17) -> 0 | E17: =IF(C17=0,"n/a (zero denom)",D17/ABS(C17)) -> 0 | F17: ='Tolerances'!$B$11 -> 0.002 | G17: =IF(C17=0,IF(D17<=0.000001,"PASS","FAIL"),IF(E17<=F17,"PASS","FAIL")) -> PASS | H17: DCF_CAT!B42
A18: Intrinsic Value per Share | B18: 162.8409 | C18: 162.8409 | D18: =ABS(B18-C18) -> 0 | E18: =IF(C18=0,"n/a (zero denom)",D18/ABS(C18)) -> 0 | F18: ='Tolerances'!$B$12 -> 0.005 | G18: =IF(C18=0,IF(D18<=0.000001,"PASS","FAIL"),IF(E18<=F18,"PASS","FAIL")) -> PASS | H18: DCF_CAT!B43
A20: Sensitivity reconciliation coverage (full per-cell detail: 'All Sensitivity Comparisons' sheet)
A21: Table | B21: Scenario Rows | C21: Outputs / Row | D21: Scalar Comparisons | E21: All Pass
A22: Table 1 -- WACC | B22: 7 | C22: 4 | D22: =B22*C22 -> 28 | E22: PASS
A23: Table 2 -- Terminal growth | B23: 7 | C23: 4 | D23: =B23*C23 -> 28 | E23: PASS
A24: Table 3 -- Revenue growth | B24: 8 | C24: 9 | D24: =B24*C24 -> 72 | E24: PASS
A25: Table 4 -- Operating margin | B25: 7 | C25: 9 | D25: =B25*C25 -> 63 | E25: PASS
A26: Table 5 -- WACC x g two-way grid | B26: 36 | C26: 1 | D26: =B26*C26 -> 36 | E26: PASS
A27: TOTAL (this company) | D27: =SUM(D22:D26) -> 227

Sheet Detail_INTC
A1: Detailed base-case reconciliation -- INTC (Intel Corporation)
A2: All metrics within tolerance.
A4: Metric | B4: Codebase Output | C4: Workbook Output | D4: Absolute Difference | E4: Relative/pp Difference | F4: Tolerance | G4: PASS/FAIL | H4: Workbook Cell
A5: Historical Revenue CAGR | B5: -0.095544173 | C5: -0.095544173 | D5: =ABS(B5-C5) -> 0 | E5: =D5 -> 0 | F5: ='Tolerances'!$B$3 -> 0.0001 | G5: =IF(D5<=F5,"PASS","FAIL") -> PASS | H5: DCF_INTC!B9
A6: Historical average Operating Margin | B6: 0.0046248517 | C6: 0.0046248517 | D6: =ABS(B6-C6) -> 0 | E6: =D6 -> 0 | F6: ='Tolerances'!$B$4 -> 0.0001 | G6: =IF(D6<=F6,"PASS","FAIL") -> PASS | H6: DCF_INTC!B10
A7: WACC (final, clamped [5%,20%]) | B7: 0.15054645 | C7: 0.15054645 | D7: =ABS(B7-C7) -> 0 | E7: =D7 -> 0 | F7: ='Tolerances'!$B$5 -> 0.0005 | G7: =IF(D7<=F7,"PASS","FAIL") -> PASS | H7: DCF_INTC!B21
A8: FCF Year 1 | B8: -4.2384226e+08 | C8: -4.2384226e+08 | D8: =ABS(B8-C8) -> 0 | E8: =IF(C8=0,"n/a (zero denom)",D8/ABS(C8)) -> 0 | F8: ='Tolerances'!$B$6 -> 0.001 | G8: =IF(C8=0,IF(D8<=0.000001,"PASS","FAIL"),IF(E8<=F8,"PASS","FAIL")) -> PASS | H8: DCF_INTC!C31
A9: FCF Year 2 | B9: -3.8334661e+08 | C9: -3.8334661e+08 | D9: =ABS(B9-C9) -> 0 | E9: =IF(C9=0,"n/a (zero denom)",D9/ABS(C9)) -> 0 | F9: ='Tolerances'!$B$6 -> 0.001 | G9: =IF(C9=0,IF(D9<=0.000001,"PASS","FAIL"),IF(E9<=F9,"PASS","FAIL")) -> PASS | H9: DCF_INTC!D31
A10: FCF Year 3 | B10: -3.4672007e+08 | C10: -3.4672007e+08 | D10: =ABS(B10-C10) -> 0 | E10: =IF(C10=0,"n/a (zero denom)",D10/ABS(C10)) -> 0 | F10: ='Tolerances'!$B$6 -> 0.001 | G10: =IF(C10=0,IF(D10<=0.000001,"PASS","FAIL"),IF(E10<=F10,"PASS","FAIL")) -> PASS | H10: DCF_INTC!E31
A11: FCF Year 4 | B11: -3.1359299e+08 | C11: -3.1359299e+08 | D11: =ABS(B11-C11) -> 0 | E11: =IF(C11=0,"n/a (zero denom)",D11/ABS(C11)) -> 0 | F11: ='Tolerances'!$B$6 -> 0.001 | G11: =IF(C11=0,IF(D11<=0.000001,"PASS","FAIL"),IF(E11<=F11,"PASS","FAIL")) -> PASS | H11: DCF_INTC!F31
A12: FCF Year 5 | B12: -2.8363101e+08 | C12: -2.8363101e+08 | D12: =ABS(B12-C12) -> 0 | E12: =IF(C12=0,"n/a (zero denom)",D12/ABS(C12)) -> 0 | F12: ='Tolerances'!$B$6 -> 0.001 | G12: =IF(C12=0,IF(D12<=0.000001,"PASS","FAIL"),IF(E12<=F12,"PASS","FAIL")) -> PASS | H12: DCF_INTC!G31
A13: Terminal Value | B13: -2.3156512e+09 | C13: -2.3156512e+09 | D13: =ABS(B13-C13) -> 0 | E13: =IF(C13=0,"n/a (zero denom)",D13/ABS(C13)) -> 0 | F13: ='Tolerances'!$B$7 -> 0.002 | G13: =IF(C13=0,IF(D13<=0.000001,"PASS","FAIL"),IF(E13<=F13,"PASS","FAIL")) -> PASS | H13: DCF_INTC!B34
A14: PV of Explicit FCF (sum of pv_fcf series) | B14: -1.2052603e+09 | C14: -1.2052603e+09 | D14: =ABS(B14-C14) -> 0 | E14: =IF(C14=0,"n/a (zero denom)",D14/ABS(C14)) -> 0 | F14: ='Tolerances'!$B$8 -> 0.002 | G14: =IF(C14=0,IF(D14<=0.000001,"PASS","FAIL"),IF(E14<=F14,"PASS","FAIL")) -> PASS | H14: DCF_INTC!B39
A15: PV of Terminal Value | B15: -1.1485565e+09 | C15: -1.1485565e+09 | D15: =ABS(B15-C15) -> 0 | E15: =IF(C15=0,"n/a (zero denom)",D15/ABS(C15)) -> 0 | F15: ='Tolerances'!$B$9 -> 0.002 | G15: =IF(C15=0,IF(D15<=0.000001,"PASS","FAIL"),IF(E15<=F15,"PASS","FAIL")) -> PASS | H15: DCF_INTC!B40
A16: Enterprise Value | B16: -2.3538168e+09 | C16: -2.3538168e+09 | D16: =ABS(B16-C16) -> 0 | E16: =IF(C16=0,"n/a (zero denom)",D16/ABS(C16)) -> 0 | F16: ='Tolerances'!$B$10 -> 0.002 | G16: =IF(C16=0,IF(D16<=0.000001,"PASS","FAIL"),IF(E16<=F16,"PASS","FAIL")) -> PASS | H16: DCF_INTC!B41
A17: Equity Value | B17: -3.4673817e+10 | C17: -3.4673817e+10 | D17: =ABS(B17-C17) -> 0 | E17: =IF(C17=0,"n/a (zero denom)",D17/ABS(C17)) -> 0 | F17: ='Tolerances'!$B$11 -> 0.002 | G17: =IF(C17=0,IF(D17<=0.000001,"PASS","FAIL"),IF(E17<=F17,"PASS","FAIL")) -> PASS | H17: DCF_INTC!B42
A18: Intrinsic Value per Share | B18: -6.5594261 | C18: -6.5594261 | D18: =ABS(B18-C18) -> 0 | E18: =IF(C18=0,"n/a (zero denom)",D18/ABS(C18)) -> 0 | F18: ='Tolerances'!$B$12 -> 0.005 | G18: =IF(C18=0,IF(D18<=0.000001,"PASS","FAIL"),IF(E18<=F18,"PASS","FAIL")) -> PASS | H18: DCF_INTC!B43
A20: Sensitivity reconciliation coverage (full per-cell detail: 'All Sensitivity Comparisons' sheet)
A21: Table | B21: Scenario Rows | C21: Outputs / Row | D21: Scalar Comparisons | E21: All Pass
A22: Table 1 -- WACC | B22: 7 | C22: 4 | D22: =B22*C22 -> 28 | E22: PASS
A23: Table 2 -- Terminal growth | B23: 7 | C23: 4 | D23: =B23*C23 -> 28 | E23: PASS
A24: Table 3 -- Revenue growth | B24: 8 | C24: 9 | D24: =B24*C24 -> 72 | E24: PASS
A25: Table 4 -- Operating margin | B25: 7 | C25: 9 | D25: =B25*C25 -> 63 | E25: PASS
A26: Table 5 -- WACC x g two-way grid | B26: 36 | C26: 1 | D26: =B26*C26 -> 36 | E26: PASS
A27: TOTAL (this company) | D27: =SUM(D22:D26) -> 227

Sheet Detail_VZ
A1: Detailed base-case reconciliation -- VZ (Verizon Communications Inc.)
A2: All metrics within tolerance.
A4: Metric | B4: Codebase Output | C4: Workbook Output | D4: Absolute Difference | E4: Relative/pp Difference | F4: Tolerance | G4: PASS/FAIL | H4: Workbook Cell
A5: Historical Revenue CAGR | B5: 0.0084578735 | C5: 0.0084578735 | D5: =ABS(B5-C5) -> 0 | E5: =D5 -> 0 | F5: ='Tolerances'!$B$3 -> 0.0001 | G5: =IF(D5<=F5,"PASS","FAIL") -> PASS | H5: DCF_VZ!B9
A6: Historical average Operating Margin | B6: 0.21216289 | C6: 0.21216289 | D6: =ABS(B6-C6) -> 0 | E6: =D6 -> 0 | F6: ='Tolerances'!$B$4 -> 0.0001 | G6: =IF(D6<=F6,"PASS","FAIL") -> PASS | H6: DCF_VZ!B10
A7: WACC (final, clamped [5%,20%]) | B7: 0.05 | C7: 0.05 | D7: =ABS(B7-C7) -> 0 | E7: =D7 -> 0 | F7: ='Tolerances'!$B$5 -> 0.0005 | G7: =IF(D7<=F7,"PASS","FAIL") -> PASS | H7: DCF_VZ!B21
A8: FCF Year 1 | B8: 2.1557635e+10 | C8: 2.1557635e+10 | D8: =ABS(B8-C8) -> 0 | E8: =IF(C8=0,"n/a (zero denom)",D8/ABS(C8)) -> 0 | F8: ='Tolerances'!$B$6 -> 0.001 | G8: =IF(C8=0,IF(D8<=0.000001,"PASS","FAIL"),IF(E8<=F8,"PASS","FAIL")) -> PASS | H8: DCF_VZ!C31
A9: FCF Year 2 | B9: 2.1739967e+10 | C9: 2.1739967e+10 | D9: =ABS(B9-C9) -> 0 | E9: =IF(C9=0,"n/a (zero denom)",D9/ABS(C9)) -> 0 | F9: ='Tolerances'!$B$6 -> 0.001 | G9: =IF(C9=0,IF(D9<=0.000001,"PASS","FAIL"),IF(E9<=F9,"PASS","FAIL")) -> PASS | H9: DCF_VZ!D31
A10: FCF Year 3 | B10: 2.1923841e+10 | C10: 2.1923841e+10 | D10: =ABS(B10-C10) -> 0 | E10: =IF(C10=0,"n/a (zero denom)",D10/ABS(C10)) -> 0 | F10: ='Tolerances'!$B$6 -> 0.001 | G10: =IF(C10=0,IF(D10<=0.000001,"PASS","FAIL"),IF(E10<=F10,"PASS","FAIL")) -> PASS | H10: DCF_VZ!E31
A11: FCF Year 4 | B11: 2.210927e+10 | C11: 2.210927e+10 | D11: =ABS(B11-C11) -> 0 | E11: =IF(C11=0,"n/a (zero denom)",D11/ABS(C11)) -> 0 | F11: ='Tolerances'!$B$6 -> 0.001 | G11: =IF(C11=0,IF(D11<=0.000001,"PASS","FAIL"),IF(E11<=F11,"PASS","FAIL")) -> PASS | H11: DCF_VZ!F31
A12: FCF Year 5 | B12: 2.2296268e+10 | C12: 2.2296268e+10 | D12: =ABS(B12-C12) -> 0 | E12: =IF(C12=0,"n/a (zero denom)",D12/ABS(C12)) -> 0 | F12: ='Tolerances'!$B$6 -> 0.001 | G12: =IF(C12=0,IF(D12<=0.000001,"PASS","FAIL"),IF(E12<=F12,"PASS","FAIL")) -> PASS | H12: DCF_VZ!G31
A13: Terminal Value | B13: 9.1414697e+11 | C13: 9.1414697e+11 | D13: =ABS(B13-C13) -> 0 | E13: =IF(C13=0,"n/a (zero denom)",D13/ABS(C13)) -> 0 | F13: ='Tolerances'!$B$7 -> 0.002 | G13: =IF(C13=0,IF(D13<=0.000001,"PASS","FAIL"),IF(E13<=F13,"PASS","FAIL")) -> PASS | H13: DCF_VZ!B34
A14: PV of Explicit FCF (sum of pv_fcf series) | B14: 9.4847571e+10 | C14: 9.4847571e+10 | D14: =ABS(B14-C14) -> 0 | E14: =IF(C14=0,"n/a (zero denom)",D14/ABS(C14)) -> 0 | F14: ='Tolerances'!$B$8 -> 0.002 | G14: =IF(C14=0,IF(D14<=0.000001,"PASS","FAIL"),IF(E14<=F14,"PASS","FAIL")) -> PASS | H14: DCF_VZ!B39
A15: PV of Terminal Value | B15: 7.1625807e+11 | C15: 7.1625807e+11 | D15: =ABS(B15-C15) -> 0 | E15: =IF(C15=0,"n/a (zero denom)",D15/ABS(C15)) -> 0 | F15: ='Tolerances'!$B$9 -> 0.002 | G15: =IF(C15=0,IF(D15<=0.000001,"PASS","FAIL"),IF(E15<=F15,"PASS","FAIL")) -> PASS | H15: DCF_VZ!B40
A16: Enterprise Value | B16: 8.1110564e+11 | C16: 8.1110564e+11 | D16: =ABS(B16-C16) -> 0 | E16: =IF(C16=0,"n/a (zero denom)",D16/ABS(C16)) -> 0 | F16: ='Tolerances'!$B$10 -> 0.002 | G16: =IF(C16=0,IF(D16<=0.000001,"PASS","FAIL"),IF(E16<=F16,"PASS","FAIL")) -> PASS | H16: DCF_VZ!B41
A17: Equity Value | B17: 6.7200364e+11 | C17: 6.7200364e+11 | D17: =ABS(B17-C17) -> 0 | E17: =IF(C17=0,"n/a (zero denom)",D17/ABS(C17)) -> 0 | F17: ='Tolerances'!$B$11 -> 0.002 | G17: =IF(C17=0,IF(D17<=0.000001,"PASS","FAIL"),IF(E17<=F17,"PASS","FAIL")) -> PASS | H17: DCF_VZ!B42
A18: Intrinsic Value per Share | B18: 161.74248 | C18: 161.74248 | D18: =ABS(B18-C18) -> 0 | E18: =IF(C18=0,"n/a (zero denom)",D18/ABS(C18)) -> 0 | F18: ='Tolerances'!$B$12 -> 0.005 | G18: =IF(C18=0,IF(D18<=0.000001,"PASS","FAIL"),IF(E18<=F18,"PASS","FAIL")) -> PASS | H18: DCF_VZ!B43
A20: Sensitivity reconciliation coverage (full per-cell detail: 'All Sensitivity Comparisons' sheet)
A21: Table | B21: Scenario Rows | C21: Outputs / Row | D21: Scalar Comparisons | E21: All Pass
A22: Table 1 -- WACC | B22: 7 | C22: 4 | D22: =B22*C22 -> 28 | E22: PASS
A23: Table 2 -- Terminal growth | B23: 7 | C23: 4 | D23: =B23*C23 -> 28 | E23: PASS
A24: Table 3 -- Revenue growth | B24: 8 | C24: 9 | D24: =B24*C24 -> 72 | E24: PASS
A25: Table 4 -- Operating margin | B25: 7 | C25: 9 | D25: =B25*C25 -> 63 | E25: PASS
A26: Table 5 -- WACC x g two-way grid | B26: 36 | C26: 1 | D26: =B26*C26 -> 36 | E26: PASS
A27: TOTAL (this company) | D27: =SUM(D22:D26) -> 227

Sheet Sensitivity Reconciliation
A1: Sensitivity reconciliation -- production recompute vs. workbook V2 cached grid, all four companies
A2: Table 1 (WACC) and Table 2 (terminal growth) IVPS rows shown here with full live-formula reconciliation for quick visual scanning. ALL FIVE tables' full per-scalar-comparison detail (908 rows total across four companies) is on the 'All Sensitivity Comparisons' sheet -- never summarized-out to JSON only.
A4: Coverage summary -- scenario rows vs. actual scalar comparisons (Finding 3 fix)
A5: Ticker | B5: Table | C5: Scenario Rows | D5: Outputs / Row | E5: Scalar Comparisons | F5: All Pass
A6: MSFT | B6: Table 1 -- WACC | C6: 7 | D6: 4 | E6: =C6*D6 -> 28 | F6: PASS
A7: MSFT | B7: Table 2 -- Terminal growth | C7: 7 | D7: 4 | E7: =C7*D7 -> 28 | F7: PASS
A8: MSFT | B8: Table 3 -- Revenue growth | C8: 8 | D8: 9 | E8: =C8*D8 -> 72 | F8: PASS
A9: MSFT | B9: Table 4 -- Operating margin | C9: 7 | D9: 9 | E9: =C9*D9 -> 63 | F9: PASS
A10: MSFT | B10: Table 5 -- WACC x g two-way grid | C10: 36 | D10: 1 | E10: =C10*D10 -> 36 | F10: PASS
A11: CAT | B11: Table 1 -- WACC | C11: 7 | D11: 4 | E11: =C11*D11 -> 28 | F11: PASS
A12: CAT | B12: Table 2 -- Terminal growth | C12: 7 | D12: 4 | E12: =C12*D12 -> 28 | F12: PASS
A13: CAT | B13: Table 3 -- Revenue growth | C13: 8 | D13: 9 | E13: =C13*D13 -> 72 | F13: PASS
A14: CAT | B14: Table 4 -- Operating margin | C14: 7 | D14: 9 | E14: =C14*D14 -> 63 | F14: PASS
A15: CAT | B15: Table 5 -- WACC x g two-way grid | C15: 36 | D15: 1 | E15: =C15*D15 -> 36 | F15: PASS
A16: INTC | B16: Table 1 -- WACC | C16: 7 | D16: 4 | E16: =C16*D16 -> 28 | F16: PASS
A17: INTC | B17: Table 2 -- Terminal growth | C17: 7 | D17: 4 | E17: =C17*D17 -> 28 | F17: PASS
... A25: VZ | B25: Table 5 -- WACC x g two-way grid | C25: 36 | D25: 1 | E25: =C25*D25 -> 36 | F25: PASS
A26: GRAND TOTAL (4 companies x 5 tables) | E26: =SUM(E5:E25) -> 908
A28: -- MSFT (Microsoft Corporation) --
A29: Table 1 -- WACC sensitivity (Intrinsic Value/Share)
A30: WACC | B30: Codebase IVPS | C30: Workbook IVPS | D30: Abs. Diff | E30: Rel. Diff | F30: Tolerance | G30: PASS/FAIL
A31: 0.05 | B31: 1038.4359 | C31: 1038.4359 | D31: =ABS(B31-C31) -> 0 | E31: =IF(C31=0,"n/a (zero denom)",D31/ABS(C31)) -> 0 | F31: ='Tolerances'!$B$13 -> 0.005 | G31: =IF(C31=0,IF(D31<=0.000001,"PASS","FAIL"),IF(E31<=F31,"PASS","FAIL")) -> PASS
A32: 0.075 | B32: 507.88514 | C32: 507.88514 | D32: =ABS(B32-C32) -> 0 | E32: =IF(C32=0,"n/a (zero denom)",D32/ABS(C32)) -> 0 | F32: ='Tolerances'!$B$13 -> 0.005 | G32: =IF(C32=0,IF(D32<=0.000001,"PASS","FAIL"),IF(E32<=F32,"PASS","FAIL")) -> PASS
A33: 0.1 | B33: 331.63686 | C33: 331.63686 | D33: =ABS(B33-C33) -> 5.6843419e-14 | E33: =IF(C33=0,"n/a (zero denom)",D33/ABS(C33)) -> 1.714026e-16 | F33: ='Tolerances'!$B$13 -> 0.005 | G33: =IF(C33=0,IF(D33<=0.000001,"PASS","FAIL"),IF(E33<=F33,"PASS","FAIL")) -> PASS
A34: 0.125 | B34: 243.91251 | C34: 243.91251 | D34: =ABS(B34-C34) -> 0 | E34: =IF(C34=0,"n/a (zero denom)",D34/ABS(C34)) -> 0 | F34: ='Tolerances'!$B$13 -> 0.005 | G34: =IF(C34=0,IF(D34<=0.000001,"PASS","FAIL"),IF(E34<=F34,"PASS","FAIL")) -> PASS
A35: 0.15 | B35: 191.56202 | C35: 191.56202 | D35: =ABS(B35-C35) -> 0 | E35: =IF(C35=0,"n/a (zero denom)",D35/ABS(C35)) -> 0 | F35: ='Tolerances'!$B$13 -> 0.005 | G35: =IF(C35=0,IF(D35<=0.000001,"PASS","FAIL"),IF(E35<=F35,"PASS","FAIL")) -> PASS
A36: 0.175 | B36: 156.87263 | C36: 156.87263 | D36: =ABS(B36-C36) -> 0 | E36: =IF(C36=0,"n/a (zero denom)",D36/ABS(C36)) -> 0 | F36: ='Tolerances'!$B$13 -> 0.005 | G36: =IF(C36=0,IF(D36<=0.000001,"PASS","FAIL"),IF(E36<=F36,"PASS","FAIL")) -> PASS
A37: 0.2 | B37: 132.25604 | C37: 132.25604 | D37: =ABS(B37-C37) -> 0 | E37: =IF(C37=0,"n/a (zero denom)",D37/ABS(C37)) -> 0 | F37: ='Tolerances'!$B$13 -> 0.005 | G37: =IF(C37=0,IF(D37<=0.000001,"PASS","FAIL"),IF(E37<=F37,"PASS","FAIL")) -> PASS
A38: Table 2 -- Terminal growth sensitivity (Intrinsic Value/Share)
A39: Terminal g | B39: Codebase IVPS | C39: Workbook IVPS | D39: Abs. Diff | E39: Rel. Diff | F39: Tolerance | G39: PASS/FAIL
A40: 0 | B40: 264.83076 | C40: 264.83076 | D40: =ABS(B40-C40) -> 0 | E40: =IF(C40=0,"n/a (zero denom)",D40/ABS(C40)) -> 0 | F40: ='Tolerances'!$B$13 -> 0.005 | G40: =IF(C40=0,IF(D40<=0.000001,"PASS","FAIL"),IF(E40<=F40,"PASS","FAIL")) -> PASS
A41: 0.01 | B41: 287.09308 | C41: 287.09308 | D41: =ABS(B41-C41) -> 0 | E41: =IF(C41=0,"n/a (zero denom)",D41/ABS(C41)) -> 0 | F41: ='Tolerances'!$B$13 -> 0.005 | G41: =IF(C41=0,IF(D41<=0.000001,"PASS","FAIL"),IF(E41<=F41,"PASS","FAIL")) -> PASS
A42: 0.02 | B42: 314.92068 | C42: 314.92068 | D42: =ABS(B42-C42) -> 0 | E42: =IF(C42=0,"n/a (zero denom)",D42/ABS(C42)) -> 0 | F42: ='Tolerances'!$B$13 -> 0.005 | G42: =IF(C42=0,IF(D42<=0.000001,"PASS","FAIL"),IF(E42<=F42,"PASS","FAIL")) -> PASS
A43: 0.025 | B43: 331.61709 | C43: 331.61709 | D43: =ABS(B43-C43) -> 0 | E43: =IF(C43=0,"n/a (zero denom)",D43/ABS(C43)) -> 0 | F43: ='Tolerances'!$B$13 -> 0.005 | G43: =IF(C43=0,IF(D43<=0.000001,"PASS","FAIL"),IF(E43<=F43,"PASS","FAIL")) -> PASS
A44: 0.03 | B44: 350.69856 | C44: 350.69856 | D44: =ABS(B44-C44) -> 0 | E44: =IF(C44=0,"n/a (zero denom)",D44/ABS(C44)) -> 0 | F44: ='Tolerances'!$B$13 -> 0.005 | G44: =IF(C44=0,IF(D44<=0.000001,"PASS","FAIL"),IF(E44<=F44,"PASS","FAIL")) -> PASS
A45: 0.04 | B45: 398.40155 | C45: 398.40155 | D45: =ABS(B45-C45) -> 0 | E45: =IF(C45=0,"n/a (zero denom)",D45/ABS(C45)) -> 0 | F45: ='Tolerances'!$B$13 -> 0.005 | G45: =IF(C45=0,IF(D45<=0.000001,"PASS","FAIL"),IF(E45<=F45,"PASS","FAIL")) -> PASS
A46: 0.05 | B46: 465.18413 | C46: 465.18413 | D46: =ABS(B46-C46) -> 0 | E46: =IF(C46=0,"n/a (zero denom)",D46/ABS(C46)) -> 0 | F46: ='Tolerances'!$B$13 -> 0.005 | G46: =IF(C46=0,IF(D46<=0.000001,"PASS","FAIL"),IF(E46<=F46,"PASS","FAIL")) -> PASS
A47: Tables 3/4/5 -- see 'All Sensitivity Comparisons' sheet for full detail. Summary: T3=PASS, T4=PASS, T5=PASS (36/36 cells).
A49: -- CAT (Caterpillar Inc.) --
A50: Table 1 -- WACC sensitivity (Intrinsic Value/Share)
...

Sheet All Sensitivity Comparisons
A1: All sensitivity scalar comparisons -- Tables 1-5, all four companies (908 rows)
A2: One row per individual scalar comparison (a single output metric within a single sensitivity scenario). Codebase/Workbook columns are hardcoded imports (yellow); Absolute Difference / Relative-or-pp Difference / PASS-FAIL are live formulas (white), with Tolerance a formula reference to the 'Tolerances' sheet's single source of truth.
A4: Ticker | B4: Table | C4: Scenario | D4: Output Metric | E4: Codebase Value | F4: Workbook Value | G4: Absolute Difference | H4: Relative/pp Difference | I4: Tolerance | J4: PASS/FAIL | K4: Notes
A5: MSFT | B5: Table 1 -- WACC | C5: WACC=5.0000% | D5: Terminal Value | E5: 8.9318455e+12 | F5: 8.9318455e+12 | G5: =ABS(E5-F5) -> 0 | H5: =IF(F5=0,"n/a (zero denom)",G5/ABS(F5)) -> 0 | I5: ='Tolerances'!$B$7 -> 0.002 | J5: =IF(F5=0,IF(G5<=0.000001,"PASS","FAIL"),IF(H5<=I5,"PASS","FAIL")) -> PASS
A6: MSFT | B6: Table 1 -- WACC | C6: WACC=5.0000% | D6: Enterprise Value | E6: 7.7303117e+12 | F6: 7.7303117e+12 | G6: =ABS(E6-F6) -> 0 | H6: =IF(F6=0,"n/a (zero denom)",G6/ABS(F6)) -> 0 | I6: ='Tolerances'!$B$10 -> 0.002 | J6: =IF(F6=0,IF(G6<=0.000001,"PASS","FAIL"),IF(H6<=I6,"PASS","FAIL")) -> PASS
A7: MSFT | B7: Table 1 -- WACC | C7: WACC=5.0000% | D7: Equity Value | E7: 7.7109527e+12 | F7: 7.7109527e+12 | G7: =ABS(E7-F7) -> 0 | H7: =IF(F7=0,"n/a (zero denom)",G7/ABS(F7)) -> 0 | I7: ='Tolerances'!$B$11 -> 0.002 | J7: =IF(F7=0,IF(G7<=0.000001,"PASS","FAIL"),IF(H7<=I7,"PASS","FAIL")) -> PASS
A8: MSFT | B8: Table 1 -- WACC | C8: WACC=5.0000% | D8: Intrinsic Value per Share | E8: 1038.4359 | F8: 1038.4359 | G8: =ABS(E8-F8) -> 0 | H8: =IF(F8=0,"n/a (zero denom)",G8/ABS(F8)) -> 0 | I8: ='Tolerances'!$B$13 -> 0.005 | J8: =IF(F8=0,IF(G8<=0.000001,"PASS","FAIL"),IF(H8<=I8,"PASS","FAIL")) -> PASS
A9: MSFT | B9: Table 1 -- WACC | C9: WACC=7.5000% | D9: Terminal Value | E9: 4.4659228e+12 | F9: 4.4659228e+12 | G9: =ABS(E9-F9) -> 0 | H9: =IF(F9=0,"n/a (zero denom)",G9/ABS(F9)) -> 0 | I9: ='Tolerances'!$B$7 -> 0.002 | J9: =IF(F9=0,IF(G9<=0.000001,"PASS","FAIL"),IF(H9<=I9,"PASS","FAIL")) -> PASS
A10: MSFT | B10: Table 1 -- WACC | C10: WACC=7.5000% | D10: Enterprise Value | E10: 3.7906832e+12 | F10: 3.7906832e+12 | G10: =ABS(E10-F10) -> 0 | H10: =IF(F10=0,"n/a (zero denom)",G10/ABS(F10)) -> 0 | I10: ='Tolerances'!$B$10 -> 0.002 | J10: =IF(F10=0,IF(G10<=0.000001,"PASS","FAIL"),IF(H10<=I10,"PASS","FAIL")) -> PASS
A11: MSFT | B11: Table 1 -- WACC | C11: WACC=7.5000% | D11: Equity Value | E11: 3.7713242e+12 | F11: 3.7713242e+12 | G11: =ABS(E11-F11) -> 0 | H11: =IF(F11=0,"n/a (zero denom)",G11/ABS(F11)) -> 0 | I11: ='Tolerances'!$B$11 -> 0.002 | J11: =IF(F11=0,IF(G11<=0.000001,"PASS","FAIL"),IF(H11<=I11,"PASS","FAIL")) -> PASS
A12: MSFT | B12: Table 1 -- WACC | C12: WACC=7.5000% | D12: Intrinsic Value per Share | E12: 507.88514 | F12: 507.88514 | G12: =ABS(E12-F12) -> 0 | H12: =IF(F12=0,"n/a (zero denom)",G12/ABS(F12)) -> 0 | I12: ='Tolerances'!$B$13 -> 0.005 | J12: =IF(F12=0,IF(G12<=0.000001,"PASS","FAIL"),IF(H12<=I12,"PASS","FAIL")) -> PASS
A13: MSFT | B13: Table 1 -- WACC | C13: WACC=10.0000% | D13: Terminal Value | E13: 2.9772818e+12 | F13: 2.9772818e+12 | G13: =ABS(E13-F13) -> 0 | H13: =IF(F13=0,"n/a (zero denom)",G13/ABS(F13)) -> 0 | I13: ='Tolerances'!$B$7 -> 0.002 | J13: =IF(F13=0,IF(G13<=0.000001,"PASS","FAIL"),IF(H13<=I13,"PASS","FAIL")) -> PASS
A14: MSFT | B14: Table 1 -- WACC | C14: WACC=10.0000% | D14: Enterprise Value | E14: 2.4819436e+12 | F14: 2.4819436e+12 | G14: =ABS(E14-F14) -> 0.00048828125 | H14: =IF(F14=0,"n/a (zero denom)",G14/ABS(F14)) -> 1.9673342e-16 | I14: ='Tolerances'!$B$10 -> 0.002 | J14: =IF(F14=0,IF(G14<=0.000001,"PASS","FAIL"),IF(H14<=I14,"PASS","FAIL")) -> PASS
A15: MSFT | B15: Table 1 -- WACC | C15: WACC=10.0000% | D15: Equity Value | E15: 2.4625846e+12 | F15: 2.4625846e+12 | G15: =ABS(E15-F15) -> 0.00048828125 | H15: =IF(F15=0,"n/a (zero denom)",G15/ABS(F15)) -> 1.9827999e-16 | I15: ='Tolerances'!$B$11 -> 0.002 | J15: =IF(F15=0,IF(G15<=0.000001,"PASS","FAIL"),IF(H15<=I15,"PASS","FAIL")) -> PASS
A16: MSFT | B16: Table 1 -- WACC | C16: WACC=10.0000% | D16: Intrinsic Value per Share | E16: 331.63686 | F16: 331.63686 | G16: =ABS(E16-F16) -> 5.6843419e-14 | H16: =IF(F16=0,"n/a (zero denom)",G16/ABS(F16)) -> 1.714026e-16 | I16: ='Tolerances'!$B$13 -> 0.005 | J16: =IF(F16=0,IF(G16<=0.000001,"PASS","FAIL"),IF(H16<=I16,"PASS","FAIL")) -> PASS
A17: MSFT | B17: Table 1 -- WACC | C17: WACC=12.5000% | D17: Terminal Value | E17: 2.2329614e+12 | F17: 2.2329614e+12 | G17: =ABS(E17-F17) -> 0 | H17: =IF(F17=0,"n/a (zero denom)",G17/ABS(F17)) -> 0 | I17: ='Tolerances'!$B$7 -> 0.002 | J17: =IF(F17=0,IF(G17<=0.000001,"PASS","FAIL"),IF(H17<=I17,"PASS","FAIL")) -> PASS
A18: MSFT | B18: Table 1 -- WACC | C18: WACC=12.5000% | D18: Enterprise Value | E18: 1.8305425e+12 | F18: 1.8305425e+12 | G18: =ABS(E18-F18) -> 0 | H18: =IF(F18=0,"n/a (zero denom)",G18/ABS(F18)) -> 0 | I18: ='Tolerances'!$B$10 -> 0.002 | J18: =IF(F18=0,IF(G18<=0.000001,"PASS","FAIL"),IF(H18<=I18,"PASS","FAIL")) -> PASS
A19: MSFT | B19: Table 1 -- WACC | C19: WACC=12.5000% | D19: Equity Value | E19: 1.8111835e+12 | F19: 1.8111835e+12 | G19: =ABS(E19-F19) -> 0 | H19: =IF(F19=0,"n/a (zero denom)",G19/ABS(F19)) -> 0 | I19: ='Tolerances'!$B$11 -> 0.002 | J19: =IF(F19=0,IF(G19<=0.000001,"PASS","FAIL"),IF(H19<=I19,"PASS","FAIL")) -> PASS
A20: MSFT | B20: Table 1 -- WACC | C20: WACC=12.5000% | D20: Intrinsic Value per Share | E20: 243.91251 | F20: 243.91251 | G20: =ABS(E20-F20) -> 0 | H20: =IF(F20=0,"n/a (zero denom)",G20/ABS(F20)) -> 0 | I20: ='Tolerances'!$B$13 -> 0.005 | J20: =IF(F20=0,IF(G20<=0.000001,"PASS","FAIL"),IF(H20<=I20,"PASS","FAIL")) -> PASS
A21: MSFT | B21: Table 1 -- WACC | C21: WACC=15.0000% | D21: Terminal Value | E21: 1.7863691e+12 | F21: 1.7863691e+12 | G21: =ABS(E21-F21) -> 0 | H21: =IF(F21=0,"n/a (zero denom)",G21/ABS(F21)) -> 0 | I21: ='Tolerances'!$B$7 -> 0.002 | J21: =IF(F21=0,IF(G21<=0.000001,"PASS","FAIL"),IF(H21<=I21,"PASS","FAIL")) -> PASS
A22: MSFT | B22: Table 1 -- WACC | C22: WACC=15.0000% | D22: Enterprise Value | E22: 1.4418115e+12 | F22: 1.4418115e+12 | G22: =ABS(E22-F22) -> 0 | H22: =IF(F22=0,"n/a (zero denom)",G22/ABS(F22)) -> 0 | I22: ='Tolerances'!$B$10 -> 0.002 | J22: =IF(F22=0,IF(G22<=0.000001,"PASS","FAIL"),IF(H22<=I22,"PASS","FAIL")) -> PASS
A23: MSFT | B23: Table 1 -- WACC | C23: WACC=15.0000% | D23: Equity Value | E23: 1.4224525e+12 | F23: 1.4224525e+12 | G23: =ABS(E23-F23) -> 0 | H23: =IF(F23=0,"n/a (zero denom)",G23/ABS(F23)) -> 0 | I23: ='Tolerances'!$B$11 -> 0.002 | J23: =IF(F23=0,IF(G23<=0.000001,"PASS","FAIL"),IF(H23<=I23,"PASS","FAIL")) -> PASS
A24: MSFT | B24: Table 1 -- WACC | C24: WACC=15.0000% | D24: Intrinsic Value per Share | E24: 191.56202 | F24: 191.56202 | G24: =ABS(E24-F24) -> 0 | H24: =IF(F24=0,"n/a (zero denom)",G24/ABS(F24)) -> 0 | I24: ='Tolerances'!$B$13 -> 0.005 | J24: =IF(F24=0,IF(G24<=0.000001,"PASS","FAIL"),IF(H24<=I24,"PASS","FAIL")) -> PASS
A25: MSFT | B25: Table 1 -- WACC | C25: WACC=17.5000% | D25: Terminal Value | E25: 1.4886409e+12 | F25: 1.4886409e+12 | G25: =ABS(E25-F25) -> 0 | H25: =IF(F25=0,"n/a (zero denom)",G25/ABS(F25)) -> 0 | I25: ='Tolerances'!$B$7 -> 0.002 | J25: =IF(F25=0,IF(G25<=0.000001,"PASS","FAIL"),IF(H25<=I25,"PASS","FAIL")) -> PASS
A26: MSFT | B26: Table 1 -- WACC | C26: WACC=17.5000% | D26: Enterprise Value | E26: 1.1842238e+12 | F26: 1.1842238e+12 | G26: =ABS(E26-F26) -> 0 | H26: =IF(F26=0,"n/a (zero denom)",G26/ABS(F26)) -> 0 | I26: ='Tolerances'!$B$10 -> 0.002 | J26: =IF(F26=0,IF(G26<=0.000001,"PASS","FAIL"),IF(H26<=I26,"PASS","FAIL")) -> PASS
A27: MSFT | B27: Table 1 -- WACC | C27: WACC=17.5000% | D27: Equity Value | E27: 1.1648648e+12 | F27: 1.1648648e+12 | G27: =ABS(E27-F27) -> 0 | H27: =IF(F27=0,"n/a (zero denom)",G27/ABS(F27)) -> 0 | I27: ='Tolerances'!$B$11 -> 0.002 | J27: =IF(F27=0,IF(G27<=0.000001,"PASS","FAIL"),IF(H27<=I27,"PASS","FAIL")) -> PASS
A28: MSFT | B28: Table 1 -- WACC | C28: WACC=17.5000% | D28: Intrinsic Value per Share | E28: 156.87263 | F28: 156.87263 | G28: =ABS(E28-F28) -> 0 | H28: =IF(F28=0,"n/a (zero denom)",G28/ABS(F28)) -> 0 | I28: ='Tolerances'!$B$13 -> 0.005 | J28: =IF(F28=0,IF(G28<=0.000001,"PASS","FAIL"),IF(H28<=I28,"PASS","FAIL")) -> PASS
A29: MSFT | B29: Table 1 -- WACC | C29: WACC=20.0000% | D29: Terminal Value | E29: 1.2759779e+12 | F29: 1.2759779e+12 | G29: =ABS(E29-F29) -> 0 | H29: =IF(F29=0,"n/a (zero denom)",G29/ABS(F29)) -> 0 | I29: ='Tolerances'!$B$7 -> 0.002 | J29: =IF(F29=0,IF(G29<=0.000001,"PASS","FAIL"),IF(H29<=I29,"PASS","FAIL")) -> PASS
A30: MSFT | B30: Table 1 -- WACC | C30: WACC=20.0000% | D30: Enterprise Value | E30: 1.0014323e+12 | F30: 1.0014323e+12 | G30: =ABS(E30-F30) -> 0.00012207031 | H30: =IF(F30=0,"n/a (zero denom)",G30/ABS(F30)) -> 1.2189572e-16 | I30: ='Tolerances'!$B$10 -> 0.002 | J30: =IF(F30=0,IF(G30<=0.000001,"PASS","FAIL"),IF(H30<=I30,"PASS","FAIL")) -> PASS
A31: MSFT | B31: Table 1 -- WACC | C31: WACC=20.0000% | D31: Equity Value | E31: 9.8207328e+11 | F31: 9.8207328e+11 | G31: =ABS(E31-F31) -> 0.00012207031 | H31: =IF(F31=0,"n/a (zero denom)",G31/ABS(F31)) -> 1.2429858e-16 | I31: ='Tolerances'!$B$11 -> 0.002 | J31: =IF(F31=0,IF(G31<=0.000001,"PASS","FAIL"),IF(H31<=I31,"PASS","FAIL")) -> PASS
A32: MSFT | B32: Table 1 -- WACC | C32: WACC=20.0000% | D32: Intrinsic Value per Share | E32: 132.25604 | F32: 132.25604 | G32: =ABS(E32-F32) -> 0 | H32: =IF(F32=0,"n/a (zero denom)",G32/ABS(F32)) -> 0 | I32: ='Tolerances'!$B$13 -> 0.005 | J32: =IF(F32=0,IF(G32<=0.000001,"PASS","FAIL"),IF(H32<=I32,"PASS","FAIL")) -> PASS
A33: MSFT | B33: Table 2 -- Terminal growth | C33: g=0.0000% | D33: Terminal Value | E33: 2.1784071e+12 | F33: 2.1784071e+12 | G33: =ABS(E33-F33) -> 0 | H33: =IF(F33=0,"n/a (zero denom)",G33/ABS(F33)) -> 0 | I33: ='Tolerances'!$B$7 -> 0.002 | J33: =IF(F33=0,IF(G33<=0.000001,"PASS","FAIL"),IF(H33<=I33,"PASS","FAIL")) -> PASS
A34: MSFT | B34: Table 2 -- Terminal growth | C34: g=0.0000% | D34: Enterprise Value | E34: 1.9858718e+12 | F34: 1.9858718e+12 | G34: =ABS(E34-F34) -> 0 | H34: =IF(F34=0,"n/a (zero denom)",G34/ABS(F34)) -> 0 | I34: ='Tolerances'!$B$10 -> 0.002 | J34: =IF(F34=0,IF(G34<=0.000001,"PASS","FAIL"),IF(H34<=I34,"PASS","FAIL")) -> PASS
A35: MSFT | B35: Table 2 -- Terminal growth | C35: g=0.0000% | D35: Equity Value | E35: 1.9665128e+12 | F35: 1.9665128e+12 | G35: =ABS(E35-F35) -> 0 | H35: =IF(F35=0,"n/a (zero denom)",G35/ABS(F35)) -> 0 | I35: ='Tolerances'!$B$11 -> 0.002 | J35: =IF(F35=0,IF(G35<=0.000001,"PASS","FAIL"),IF(H35<=I35,"PASS","FAIL")) -> PASS
A36: MSFT | B36: Table 2 -- Terminal growth | C36: g=0.0000% | D36: Intrinsic Value per Share | E36: 264.83076 | F36: 264.83076 | G36: =ABS(E36-F36) -> 0 | H36: =IF(F36=0,"n/a (zero denom)",G36/ABS(F36)) -> 0 | I36: ='Tolerances'!$B$13 -> 0.005 | J36: =IF(F36=0,IF(G36<=0.000001,"PASS","FAIL"),IF(H36<=I36,"PASS","FAIL")) -> PASS
A37: MSFT | B37: Table 2 -- Terminal growth | C37: g=1.0000% | D37: Terminal Value | E37: 2.4446454e+12 | F37: 2.4446454e+12 | G37: =ABS(E37-F37) -> 0 | H37: =IF(F37=0,"n/a (zero denom)",G37/ABS(F37)) -> 0 | I37: ='Tolerances'!$B$7 -> 0.002 | J37: =IF(F37=0,IF(G37<=0.000001,"PASS","FAIL"),IF(H37<=I37,"PASS","FAIL")) -> PASS
A38: MSFT | B38: Table 2 -- Terminal growth | C38: g=1.0000% | D38: Enterprise Value | E38: 2.1511817e+12 | F38: 2.1511817e+12 | G38: =ABS(E38-F38) -> 0 | H38: =IF(F38=0,"n/a (zero denom)",G38/ABS(F38)) -> 0 | I38: ='Tolerances'!$B$10 -> 0.002 | J38: =IF(F38=0,IF(G38<=0.000001,"PASS","FAIL"),IF(H38<=I38,"PASS","FAIL")) -> PASS
A39: MSFT | B39: Table 2 -- Terminal growth | C39: g=1.0000% | D39: Equity Value | E39: 2.1318227e+12 | F39: 2.1318227e+12 | G39: =ABS(E39-F39) -> 0 | H39: =IF(F39=0,"n/a (zero denom)",G39/ABS(F39)) -> 0 | I39: ='Tolerances'!$B$11 -> 0.002 | J39: =IF(F39=0,IF(G39<=0.000001,"PASS","FAIL"),IF(H39<=I39,"PASS","FAIL")) -> PASS
A40: MSFT | B40: Table 2 -- Terminal growth | C40: g=1.0000% | D40: Intrinsic Value per Share | E40: 287.09308 | F40: 287.09308 | G40: =ABS(E40-F40) -> 0 | H40: =IF(F40=0,"n/a (zero denom)",G40/ABS(F40)) -> 0 | I40: ='Tolerances'!$B$13 -> 0.005 | J40: =IF(F40=0,IF(G40<=0.000001,"PASS","FAIL"),IF(H40<=I40,"PASS","FAIL")) -> PASS
A41: MSFT | B41: Table 2 -- Terminal growth | C41: g=2.0000% | D41: Terminal Value | E41: 2.7774397e+12 | F41: 2.7774397e+12 | G41: =ABS(E41-F41) -> 0 | H41: =IF(F41=0,"n/a (zero denom)",G41/ABS(F41)) -> 0 | I41: ='Tolerances'!$B$7 -> 0.002 | J41: =IF(F41=0,IF(G41<=0.000001,"PASS","FAIL"),IF(H41<=I41,"PASS","FAIL")) -> PASS
...

Sheet Findings
A1: Findings
A3: Overall verdict: GO
A4: Reconciliation target: independent workbook V2 (independent_dcf_validation_v2.xlsx), built in Track A Phase 2C from the corrected years_elapsed specification (A-028/L-019). V1 (independent_dcf_validation.xlsx) is preserved unchanged; its original Phase 2B NO-GO evidence is archived at validation/dcf_reconciliation/history/phase2b_initial_no_go/ and was never edited.
A5: No base-case divergence found in any company against V2. Phase 2B's original NO-GO (against V1) was caused by V1's 'years_elapsed = COUNT(periods)-1' convention, which did NOT conform to the now-clarified specification (docs/model-specifications/dcf.md's years_elapsed = actual elapsed calendar days / 365.25) for a company on an irregular fiscal calendar (INTC). V1's convention is not described as having been correct under the clarified specification -- it was a reasonable resolution of a genuine ambiguity that the clarification has since closed. Production code (src/dcf_model/dcf.py) required NO change: its existing calculate_historical_revenue_cagr implementation already computed years_elapsed via actual elapsed calendar days, which is what the specification was clarified to require.
A6: Directional bias: MSFT, CAT, and VZ match V2 to full floating-point precision on every required metric (zero signed difference) -- no bias to investigate among them.
A7: INTC sensitivity tables show a documented, mathematically-correct inverted direction (IV rises with WACC, falls with terminal growth, falls with revenue growth) caused by negative base-case FCF -- both V2 and the production recompute agree on every inverted direction.
A8: Sensitivity coverage: 908 total scalar comparisons across four companies (227 per company: Table 1=28, Table 2=28, Table 3=72, Table 4=63, Table 5=36) -- every one appears as its own row on the 'All Sensitivity Comparisons' sheet, not only in reconciliation_results.json.

Sheet Sign-off
A1: Sign-off
A3: Source implementation commit | B3: 776e76f56e6210f1050caa74c60962ed89162496
A4: Branch | B4: remediation/valuation-engine-production-quality
A5: V1 independent workbook SHA-256 (preserved, historical) | B5: 942b5f096cf546d63487add31eb29b1b690f0819f923f01436093f9bbc75eba1
A6: V2 independent workbook SHA-256 (reconciliation target) | B6: cd2d225cfe0825ff56aa8f866c3b80b6bec5f87a8b02dc3f76724e4abdd27d6b
A7: Frozen snapshot SHA-256 (MSFT) | B7: 7c50a3e9fb2d27095a890ad8d11732d4ccc72ef9350998604adb3af7a3c845a8
A8: Frozen snapshot SHA-256 (CAT) | B8: 651d366c01415c2da33733058dabb9ac6e4f40cdf5b20e743c0b83ebc3a52c93
A9: Frozen snapshot SHA-256 (INTC) | B9: d73e4b40bce2442a75affde82aaa563ffdea9c68c7257e70cc325663cff24930
A10: Frozen snapshot SHA-256 (VZ) | B10: 77b8ea27b8decaff5fe3b4aad857c632a852445eda0b7f2342f594cd3c4b5f3d
A11: Overall reconciliation status | B11: GO
A12: Profitability established? | B12: NOT ESTABLISHED -- this reconciliation checks calculation agreement only
A13: Second-reviewer sign-off | B13: PENDING -- not performed in this session
