Workbook

Sheet Tolerances
A1: Tolerance constants -- single source of truth for every comparison table's Tolerance column
A2: Metric | B2: Tolerance | C2: Kind
A3: Revenue CAGR | B3: 0.0001 | C3: percentage points
A4: Operating Margin | B4: 0.0001 | C4: percentage points
A5: WACC | B5: 0.0005 | C5: percentage points
A6: Each FCF year | B6: 0.001 | C6: relative fraction
A7: Terminal Value | B7: 0.002 | C7: relative fraction
A8: PV of Explicit FCF | B8: 0.002 | C8: relative fraction
A9: PV of Terminal Value | B9: 0.002 | C9: relative fraction
A10: Enterprise Value | B10: 0.002 | C10: relative fraction
A11: Equity Value | B11: 0.002 | C11: relative fraction
A12: Intrinsic Value per Share | B12: 0.005 | C12: relative fraction
A13: Sensitivity IVPS (all tables) | B13: 0.005 | C13: relative fraction
A14: Zero-denominator floating-point carve-out (absolute $) | B14: 1e-06 | C14: absolute $

Sheet README
A1: DCF Codebase-to-Independent-Workbook Reconciliation
A2: Track A Phase 2B. This workbook reconciles src/dcf_model/dcf.py's production output against the ALREADY-FROZEN, already-committed independent workbook (validation/independent_dcf/independent_dcf_validation.xlsx), which is never modified by this workbook or by any script in validation/dcf_reconciliation/.
A4: Sheets:
A5: - Tolerances: the single source of truth for every tolerance constant used elsewhere.
A6: - Base Reconciliation: all 14 required metrics x 4 companies, live-formula comparison.
A7: - Detail_<TICKER>: per-company base reconciliation + sensitivity summary.
A8: - Sensitivity Reconciliation: Table 1/2 full live-formula detail; Table 3/4/5 summarized (full per-cell detail is in reconciliation_results.json).
A9: - Findings: narrative summary of what was (and wasn't) found.
A10: - Sign-off: commit/hash provenance and outstanding second-reviewer requirement.
A12: Source commit: 776e76f56e6210f1050caa74c60962ed89162496 (branch remediation/valuation-engine-production-quality)
A13: Original workbook SHA-256: 942b5f096cf546d63487add31eb29b1b690f0819f923f01436093f9bbc75eba1
A14: Overall status: NO-GO (pending separate second-reviewer sign-off)
A15: PROFITABILITY NOT ESTABLISHED -- this workbook verifies calculation agreement between two independent implementations. It is not investment advice and does not establish that any company is profitable to trade.

Sheet Base Reconciliation
A1: Base-case reconciliation -- all four companies, all 14 required metrics
A2: Codebase/Workbook columns are hardcoded values imported from codebase_outputs.json and the independent workbook's cached cells (yellow fill). Absolute Difference / Relative-or-pp Difference / Tolerance / PASS-FAIL are live formulas (white fill).
A4: Metric | B4: Codebase Output | C4: Workbook Output | D4: Absolute Difference | E4: Relative/pp Difference | F4: Tolerance | G4: PASS/FAIL | H4: Workbook Cell
A5: -- MSFT (Microsoft Corporation) --
A6: Historical Revenue CAGR | B6: 0.13741147 | C6: 0.13741147 | D6: =ABS(B6-C6) -> 0 | E6: =D6 -> 0 | F6: ='Tolerances'!$B$3 -> 0.0001 | G6: =IF(D6<=F6,"PASS","FAIL") | H6: DCF_MSFT!B7
A7: Historical average Operating Margin | B7: 0.44175047 | C7: 0.44175047 | D7: =ABS(B7-C7) -> 0 | E7: =D7 -> 0 | F7: ='Tolerances'!$B$4 -> 0.0001 | G7: =IF(D7<=F7,"PASS","FAIL") | H7: DCF_MSFT!B8
A8: WACC (final, clamped [5%,20%]) | B8: 0.10000422 | C8: 0.10000422 | D8: =ABS(B8-C8) -> 0 | E8: =D8 -> 0 | F8: ='Tolerances'!$B$5 -> 0.0005 | G8: =IF(D8<=F8,"PASS","FAIL") | H8: DCF_MSFT!B19
A9: FCF Year 1 | B9: 1.3016281e+11 | C9: 1.3016281e+11 | D9: =ABS(B9-C9) -> 0 | E9: =IF(C9=0,"n/a (zero denom)",D9/ABS(C9)) -> 0 | F9: ='Tolerances'!$B$6 -> 0.001 | G9: =IF(C9=0,IF(D9<=0.000001,"PASS","FAIL"),IF(E9<=F9,"PASS","FAIL")) | H9: DCF_MSFT!C29
A10: FCF Year 2 | B10: 1.4804868e+11 | C10: 1.4804868e+11 | D10: =ABS(B10-C10) -> 0 | E10: =IF(C10=0,"n/a (zero denom)",D10/ABS(C10)) -> 0 | F10: ='Tolerances'!$B$6 -> 0.001 | G10: =IF(C10=0,IF(D10<=0.000001,"PASS","FAIL"),IF(E10<=F10,"PASS","FAIL")) | H10: DCF_MSFT!D29
A11: FCF Year 3 | B11: 1.6839226e+11 | C11: 1.6839226e+11 | D11: =ABS(B11-C11) -> 0 | E11: =IF(C11=0,"n/a (zero denom)",D11/ABS(C11)) -> 0 | F11: ='Tolerances'!$B$6 -> 0.001 | G11: =IF(C11=0,IF(D11<=0.000001,"PASS","FAIL"),IF(E11<=F11,"PASS","FAIL")) | H11: DCF_MSFT!E29
A12: FCF Year 4 | B12: 1.9153129e+11 | C12: 1.9153129e+11 | D12: =ABS(B12-C12) -> 0 | E12: =IF(C12=0,"n/a (zero denom)",D12/ABS(C12)) -> 0 | F12: ='Tolerances'!$B$6 -> 0.001 | G12: =IF(C12=0,IF(D12<=0.000001,"PASS","FAIL"),IF(E12<=F12,"PASS","FAIL")) | H12: DCF_MSFT!F29
A13: FCF Year 5 | B13: 2.1784989e+11 | C13: 2.1784989e+11 | D13: =ABS(B13-C13) -> 0 | E13: =IF(C13=0,"n/a (zero denom)",D13/ABS(C13)) -> 0 | F13: ='Tolerances'!$B$6 -> 0.001 | G13: =IF(C13=0,IF(D13<=0.000001,"PASS","FAIL"),IF(E13<=F13,"PASS","FAIL")) | H13: DCF_MSFT!G29
A14: Terminal Value | B14: 2.9771145e+12 | C14: 2.9771145e+12 | D14: =ABS(B14-C14) -> 0 | E14: =IF(C14=0,"n/a (zero denom)",D14/ABS(C14)) -> 0 | F14: ='Tolerances'!$B$7 -> 0.002 | G14: =IF(C14=0,IF(D14<=0.000001,"PASS","FAIL"),IF(E14<=F14,"PASS","FAIL")) | H14: DCF_MSFT!B32
A15: PV of Explicit FCF (sum of pv_fcf series) | B15: 6.3327836e+11 | C15: 6.3327836e+11 | D15: =ABS(B15-C15) -> 0 | E15: =IF(C15=0,"n/a (zero denom)",D15/ABS(C15)) -> 0 | F15: ='Tolerances'!$B$8 -> 0.002 | G15: =IF(C15=0,IF(D15<=0.000001,"PASS","FAIL"),IF(E15<=F15,"PASS","FAIL")) | H15: DCF_MSFT!B37
A16: PV of Terminal Value | B16: 1.8485184e+12 | C16: 1.8485184e+12 | D16: =ABS(B16-C16) -> 0 | E16: =IF(C16=0,"n/a (zero denom)",D16/ABS(C16)) -> 0 | F16: ='Tolerances'!$B$9 -> 0.002 | G16: =IF(C16=0,IF(D16<=0.000001,"PASS","FAIL"),IF(E16<=F16,"PASS","FAIL")) | H16: DCF_MSFT!B38
A17: Enterprise Value | B17: 2.4817968e+12 | C17: 2.4817968e+12 | D17: =ABS(B17-C17) -> 0 | E17: =IF(C17=0,"n/a (zero denom)",D17/ABS(C17)) -> 0 | F17: ='Tolerances'!$B$10 -> 0.002 | G17: =IF(C17=0,IF(D17<=0.000001,"PASS","FAIL"),IF(E17<=F17,"PASS","FAIL")) | H17: DCF_MSFT!B39
A18: Equity Value | B18: 2.4624378e+12 | C18: 2.4624378e+12 | D18: =ABS(B18-C18) -> 0 | E18: =IF(C18=0,"n/a (zero denom)",D18/ABS(C18)) -> 0 | F18: ='Tolerances'!$B$11 -> 0.002 | G18: =IF(C18=0,IF(D18<=0.000001,"PASS","FAIL"),IF(E18<=F18,"PASS","FAIL")) | H18: DCF_MSFT!B40
A19: Intrinsic Value per Share | B19: 331.61709 | C19: 331.61709 | D19: =ABS(B19-C19) -> 0 | E19: =IF(C19=0,"n/a (zero denom)",D19/ABS(C19)) -> 0 | F19: ='Tolerances'!$B$12 -> 0.005 | G19: =IF(C19=0,IF(D19<=0.000001,"PASS","FAIL"),IF(E19<=F19,"PASS","FAIL")) | H19: DCF_MSFT!B41
A20: -- CAT (Caterpillar Inc.) --
A21: Historical Revenue CAGR | B21: 0.073095112 | C21: 0.073095112 | D21: =ABS(B21-C21) -> 0 | E21: =D21 -> 0 | F21: ='Tolerances'!$B$3 -> 0.0001 | G21: =IF(D21<=F21,"PASS","FAIL") | H21: DCF_CAT!B7
A22: Historical average Operating Margin | B22: 0.16559502 | C22: 0.16559502 | D22: =ABS(B22-C22) -> 0 | E22: =D22 -> 0 | F22: ='Tolerances'!$B$4 -> 0.0001 | G22: =IF(D22<=F22,"PASS","FAIL") | H22: DCF_CAT!B8
A23: WACC (final, clamped [5%,20%]) | B23: 0.12095875 | C23: 0.12095875 | D23: =ABS(B23-C23) -> 0 | E23: =D23 -> 0 | F23: ='Tolerances'!$B$5 -> 0.0005 | G23: =IF(D23<=F23,"PASS","FAIL") | H23: DCF_CAT!B19
A24: FCF Year 1 | B24: 8.355205e+09 | C24: 8.355205e+09 | D24: =ABS(B24-C24) -> 0 | E24: =IF(C24=0,"n/a (zero denom)",D24/ABS(C24)) -> 0 | F24: ='Tolerances'!$B$6 -> 0.001 | G24: =IF(C24=0,IF(D24<=0.000001,"PASS","FAIL"),IF(E24<=F24,"PASS","FAIL")) | H24: DCF_CAT!C29
A25: FCF Year 2 | B25: 8.9659296e+09 | C25: 8.9659296e+09 | D25: =ABS(B25-C25) -> 0 | E25: =IF(C25=0,"n/a (zero denom)",D25/ABS(C25)) -> 0 | F25: ='Tolerances'!$B$6 -> 0.001 | G25: =IF(C25=0,IF(D25<=0.000001,"PASS","FAIL"),IF(E25<=F25,"PASS","FAIL")) | H25: DCF_CAT!D29
A26: FCF Year 3 | B26: 9.6212953e+09 | C26: 9.6212953e+09 | D26: =ABS(B26-C26) -> 0 | E26: =IF(C26=0,"n/a (zero denom)",D26/ABS(C26)) -> 0 | F26: ='Tolerances'!$B$6 -> 0.001 | G26: =IF(C26=0,IF(D26<=0.000001,"PASS","FAIL"),IF(E26<=F26,"PASS","FAIL")) | H26: DCF_CAT!E29
A27: FCF Year 4 | B27: 1.0324565e+10 | C27: 1.0324565e+10 | D27: =ABS(B27-C27) -> 0 | E27: =IF(C27=0,"n/a (zero denom)",D27/ABS(C27)) -> 0 | F27: ='Tolerances'!$B$6 -> 0.001 | G27: =IF(C27=0,IF(D27<=0.000001,"PASS","FAIL"),IF(E27<=F27,"PASS","FAIL")) | H27: DCF_CAT!F29
A28: FCF Year 5 | B28: 1.107924e+10 | C28: 1.107924e+10 | D28: =ABS(B28-C28) -> 0 | E28: =IF(C28=0,"n/a (zero denom)",D28/ABS(C28)) -> 0 | F28: ='Tolerances'!$B$6 -> 0.001 | G28: =IF(C28=0,IF(D28<=0.000001,"PASS","FAIL"),IF(E28<=F28,"PASS","FAIL")) | H28: DCF_CAT!G29
A29: Terminal Value | B29: 1.1834482e+11 | C29: 1.1834482e+11 | D29: =ABS(B29-C29) -> 0 | E29: =IF(C29=0,"n/a (zero denom)",D29/ABS(C29)) -> 0 | F29: ='Tolerances'!$B$7 -> 0.002 | G29: =IF(C29=0,IF(D29<=0.000001,"PASS","FAIL"),IF(E29<=F29,"PASS","FAIL")) | H29: DCF_CAT!B32
A30: PV of Explicit FCF (sum of pv_fcf series) | B30: 3.4218526e+10 | C30: 3.4218526e+10 | D30: =ABS(B30-C30) -> 0 | E30: =IF(C30=0,"n/a (zero denom)",D30/ABS(C30)) -> 0 | F30: ='Tolerances'!$B$8 -> 0.002 | G30: =IF(C30=0,IF(D30<=0.000001,"PASS","FAIL"),IF(E30<=F30,"PASS","FAIL")) | H30: DCF_CAT!B37
A31: PV of Terminal Value | B31: 6.6865345e+10 | C31: 6.6865345e+10 | D31: =ABS(B31-C31) -> 0 | E31: =IF(C31=0,"n/a (zero denom)",D31/ABS(C31)) -> 0 | F31: ='Tolerances'!$B$9 -> 0.002 | G31: =IF(C31=0,IF(D31<=0.000001,"PASS","FAIL"),IF(E31<=F31,"PASS","FAIL")) | H31: DCF_CAT!B38
A32: Enterprise Value | B32: 1.0108387e+11 | C32: 1.0108387e+11 | D32: =ABS(B32-C32) -> 0 | E32: =IF(C32=0,"n/a (zero denom)",D32/ABS(C32)) -> 0 | F32: ='Tolerances'!$B$10 -> 0.002 | G32: =IF(C32=0,IF(D32<=0.000001,"PASS","FAIL"),IF(E32<=F32,"PASS","FAIL")) | H32: DCF_CAT!B39
A33: Equity Value | B33: 7.4853871e+10 | C33: 7.4853871e+10 | D33: =ABS(B33-C33) -> 0 | E33: =IF(C33=0,"n/a (zero denom)",D33/ABS(C33)) -> 0 | F33: ='Tolerances'!$B$11 -> 0.002 | G33: =IF(C33=0,IF(D33<=0.000001,"PASS","FAIL"),IF(E33<=F33,"PASS","FAIL")) | H33: DCF_CAT!B40
A34: Intrinsic Value per Share | B34: 162.8409 | C34: 162.8409 | D34: =ABS(B34-C34) -> 0 | E34: =IF(C34=0,"n/a (zero denom)",D34/ABS(C34)) -> 0 | F34: ='Tolerances'!$B$12 -> 0.005 | G34: =IF(C34=0,IF(D34<=0.000001,"PASS","FAIL"),IF(E34<=F34,"PASS","FAIL")) | H34: DCF_CAT!B41
A35: -- INTC (Intel Corporation) --
A36: Historical Revenue CAGR | B36: -0.095544173 | C36: -0.0956685 | D36: =ABS(B36-C36) -> 0.00012432697 | E36: =D36 -> 0.00012432697 | F36: ='Tolerances'!$B$3 -> 0.0001 | G36: =IF(D36<=F36,"PASS","FAIL") | H36: DCF_INTC!B7
A37: Historical average Operating Margin | B37: 0.0046248517 | C37: 0.0046248517 | D37: =ABS(B37-C37) -> 0 | E37: =D37 -> 0 | F37: ='Tolerances'!$B$4 -> 0.0001 | G37: =IF(D37<=F37,"PASS","FAIL") | H37: DCF_INTC!B8
A38: WACC (final, clamped [5%,20%]) | B38: 0.15054645 | C38: 0.15054645 | D38: =ABS(B38-C38) -> 0 | E38: =D38 -> 0 | F38: ='Tolerances'!$B$5 -> 0.0005 | G38: =IF(D38<=F38,"PASS","FAIL") | H38: DCF_INTC!B19
A39: FCF Year 1 | B39: -4.2384226e+08 | C39: -4.2371135e+08 | D39: =ABS(B39-C39) -> 130913.59 | E39: =IF(C39=0,"n/a (zero denom)",D39/ABS(C39)) -> 0.0003089688 | F39: ='Tolerances'!$B$6 -> 0.001 | G39: =IF(C39=0,IF(D39<=0.000001,"PASS","FAIL"),IF(E39<=F39,"PASS","FAIL")) | H39: DCF_INTC!C29
A40: FCF Year 2 | B40: -3.8334661e+08 | C40: -3.8317552e+08 | D40: =ABS(B40-C40) -> 171084.3 | E40: =IF(C40=0,"n/a (zero denom)",D40/ABS(C40)) -> 0.00044649069 | F40: ='Tolerances'!$B$6 -> 0.001 | G40: =IF(C40=0,IF(D40<=0.000001,"PASS","FAIL"),IF(E40<=F40,"PASS","FAIL")) | H40: DCF_INTC!D29
A41: FCF Year 3 | B41: -3.4672007e+08 | C41: -3.4651769e+08 | D41: =ABS(B41-C41) -> 202377.25 | E41: =IF(C41=0,"n/a (zero denom)",D41/ABS(C41)) -> 0.00058403149 | F41: ='Tolerances'!$B$6 -> 0.001 | G41: =IF(C41=0,IF(D41<=0.000001,"PASS","FAIL"),IF(E41<=F41,"PASS","FAIL")) | H41: DCF_INTC!E29
...

Sheet Detail_MSFT
A1: Detailed base-case reconciliation -- MSFT (Microsoft Corporation)
A2: All metrics within tolerance.
A4: Metric | B4: Codebase Output | C4: Workbook Output | D4: Absolute Difference | E4: Relative/pp Difference | F4: Tolerance | G4: PASS/FAIL | H4: Workbook Cell
A5: Historical Revenue CAGR | B5: 0.13741147 | C5: 0.13741147 | D5: =ABS(B5-C5) -> 0 | E5: =D5 -> 0 | F5: ='Tolerances'!$B$3 -> 0.0001 | G5: =IF(D5<=F5,"PASS","FAIL") | H5: DCF_MSFT!B7
A6: Historical average Operating Margin | B6: 0.44175047 | C6: 0.44175047 | D6: =ABS(B6-C6) -> 0 | E6: =D6 -> 0 | F6: ='Tolerances'!$B$4 -> 0.0001 | G6: =IF(D6<=F6,"PASS","FAIL") | H6: DCF_MSFT!B8
A7: WACC (final, clamped [5%,20%]) | B7: 0.10000422 | C7: 0.10000422 | D7: =ABS(B7-C7) -> 0 | E7: =D7 -> 0 | F7: ='Tolerances'!$B$5 -> 0.0005 | G7: =IF(D7<=F7,"PASS","FAIL") | H7: DCF_MSFT!B19
A8: FCF Year 1 | B8: 1.3016281e+11 | C8: 1.3016281e+11 | D8: =ABS(B8-C8) -> 0 | E8: =IF(C8=0,"n/a (zero denom)",D8/ABS(C8)) -> 0 | F8: ='Tolerances'!$B$6 -> 0.001 | G8: =IF(C8=0,IF(D8<=0.000001,"PASS","FAIL"),IF(E8<=F8,"PASS","FAIL")) | H8: DCF_MSFT!C29
A9: FCF Year 2 | B9: 1.4804868e+11 | C9: 1.4804868e+11 | D9: =ABS(B9-C9) -> 0 | E9: =IF(C9=0,"n/a (zero denom)",D9/ABS(C9)) -> 0 | F9: ='Tolerances'!$B$6 -> 0.001 | G9: =IF(C9=0,IF(D9<=0.000001,"PASS","FAIL"),IF(E9<=F9,"PASS","FAIL")) | H9: DCF_MSFT!D29
A10: FCF Year 3 | B10: 1.6839226e+11 | C10: 1.6839226e+11 | D10: =ABS(B10-C10) -> 0 | E10: =IF(C10=0,"n/a (zero denom)",D10/ABS(C10)) -> 0 | F10: ='Tolerances'!$B$6 -> 0.001 | G10: =IF(C10=0,IF(D10<=0.000001,"PASS","FAIL"),IF(E10<=F10,"PASS","FAIL")) | H10: DCF_MSFT!E29
A11: FCF Year 4 | B11: 1.9153129e+11 | C11: 1.9153129e+11 | D11: =ABS(B11-C11) -> 0 | E11: =IF(C11=0,"n/a (zero denom)",D11/ABS(C11)) -> 0 | F11: ='Tolerances'!$B$6 -> 0.001 | G11: =IF(C11=0,IF(D11<=0.000001,"PASS","FAIL"),IF(E11<=F11,"PASS","FAIL")) | H11: DCF_MSFT!F29
A12: FCF Year 5 | B12: 2.1784989e+11 | C12: 2.1784989e+11 | D12: =ABS(B12-C12) -> 0 | E12: =IF(C12=0,"n/a (zero denom)",D12/ABS(C12)) -> 0 | F12: ='Tolerances'!$B$6 -> 0.001 | G12: =IF(C12=0,IF(D12<=0.000001,"PASS","FAIL"),IF(E12<=F12,"PASS","FAIL")) | H12: DCF_MSFT!G29
A13: Terminal Value | B13: 2.9771145e+12 | C13: 2.9771145e+12 | D13: =ABS(B13-C13) -> 0 | E13: =IF(C13=0,"n/a (zero denom)",D13/ABS(C13)) -> 0 | F13: ='Tolerances'!$B$7 -> 0.002 | G13: =IF(C13=0,IF(D13<=0.000001,"PASS","FAIL"),IF(E13<=F13,"PASS","FAIL")) | H13: DCF_MSFT!B32
A14: PV of Explicit FCF (sum of pv_fcf series) | B14: 6.3327836e+11 | C14: 6.3327836e+11 | D14: =ABS(B14-C14) -> 0 | E14: =IF(C14=0,"n/a (zero denom)",D14/ABS(C14)) -> 0 | F14: ='Tolerances'!$B$8 -> 0.002 | G14: =IF(C14=0,IF(D14<=0.000001,"PASS","FAIL"),IF(E14<=F14,"PASS","FAIL")) | H14: DCF_MSFT!B37
A15: PV of Terminal Value | B15: 1.8485184e+12 | C15: 1.8485184e+12 | D15: =ABS(B15-C15) -> 0 | E15: =IF(C15=0,"n/a (zero denom)",D15/ABS(C15)) -> 0 | F15: ='Tolerances'!$B$9 -> 0.002 | G15: =IF(C15=0,IF(D15<=0.000001,"PASS","FAIL"),IF(E15<=F15,"PASS","FAIL")) | H15: DCF_MSFT!B38
A16: Enterprise Value | B16: 2.4817968e+12 | C16: 2.4817968e+12 | D16: =ABS(B16-C16) -> 0 | E16: =IF(C16=0,"n/a (zero denom)",D16/ABS(C16)) -> 0 | F16: ='Tolerances'!$B$10 -> 0.002 | G16: =IF(C16=0,IF(D16<=0.000001,"PASS","FAIL"),IF(E16<=F16,"PASS","FAIL")) | H16: DCF_MSFT!B39
A17: Equity Value | B17: 2.4624378e+12 | C17: 2.4624378e+12 | D17: =ABS(B17-C17) -> 0 | E17: =IF(C17=0,"n/a (zero denom)",D17/ABS(C17)) -> 0 | F17: ='Tolerances'!$B$11 -> 0.002 | G17: =IF(C17=0,IF(D17<=0.000001,"PASS","FAIL"),IF(E17<=F17,"PASS","FAIL")) | H17: DCF_MSFT!B40
A18: Intrinsic Value per Share | B18: 331.61709 | C18: 331.61709 | D18: =ABS(B18-C18) -> 0 | E18: =IF(C18=0,"n/a (zero denom)",D18/ABS(C18)) -> 0 | F18: ='Tolerances'!$B$12 -> 0.005 | G18: =IF(C18=0,IF(D18<=0.000001,"PASS","FAIL"),IF(E18<=F18,"PASS","FAIL")) | H18: DCF_MSFT!B41
A20: Sensitivity reconciliation summary (full grid in the Sensitivity Reconciliation sheet)
A21: Table | B21: Cells | C21: All Pass
A22: Table 1 -- WACC | B22: 7 | C22: PASS
A23: Table 2 -- Terminal growth | B23: 7 | C23: PASS
A24: Table 3 -- Revenue growth | B24: 8 | C24: PASS
A25: Table 4 -- Operating margin | B25: 7 | C25: PASS
A26: Table 5 -- WACC x g two-way grid | B26: 36 | C26: PASS

Sheet Detail_CAT
A1: Detailed base-case reconciliation -- CAT (Caterpillar Inc.)
A2: All metrics within tolerance.
A4: Metric | B4: Codebase Output | C4: Workbook Output | D4: Absolute Difference | E4: Relative/pp Difference | F4: Tolerance | G4: PASS/FAIL | H4: Workbook Cell
A5: Historical Revenue CAGR | B5: 0.073095112 | C5: 0.073095112 | D5: =ABS(B5-C5) -> 0 | E5: =D5 -> 0 | F5: ='Tolerances'!$B$3 -> 0.0001 | G5: =IF(D5<=F5,"PASS","FAIL") | H5: DCF_CAT!B7
A6: Historical average Operating Margin | B6: 0.16559502 | C6: 0.16559502 | D6: =ABS(B6-C6) -> 0 | E6: =D6 -> 0 | F6: ='Tolerances'!$B$4 -> 0.0001 | G6: =IF(D6<=F6,"PASS","FAIL") | H6: DCF_CAT!B8
A7: WACC (final, clamped [5%,20%]) | B7: 0.12095875 | C7: 0.12095875 | D7: =ABS(B7-C7) -> 0 | E7: =D7 -> 0 | F7: ='Tolerances'!$B$5 -> 0.0005 | G7: =IF(D7<=F7,"PASS","FAIL") | H7: DCF_CAT!B19
A8: FCF Year 1 | B8: 8.355205e+09 | C8: 8.355205e+09 | D8: =ABS(B8-C8) -> 0 | E8: =IF(C8=0,"n/a (zero denom)",D8/ABS(C8)) -> 0 | F8: ='Tolerances'!$B$6 -> 0.001 | G8: =IF(C8=0,IF(D8<=0.000001,"PASS","FAIL"),IF(E8<=F8,"PASS","FAIL")) | H8: DCF_CAT!C29
A9: FCF Year 2 | B9: 8.9659296e+09 | C9: 8.9659296e+09 | D9: =ABS(B9-C9) -> 0 | E9: =IF(C9=0,"n/a (zero denom)",D9/ABS(C9)) -> 0 | F9: ='Tolerances'!$B$6 -> 0.001 | G9: =IF(C9=0,IF(D9<=0.000001,"PASS","FAIL"),IF(E9<=F9,"PASS","FAIL")) | H9: DCF_CAT!D29
A10: FCF Year 3 | B10: 9.6212953e+09 | C10: 9.6212953e+09 | D10: =ABS(B10-C10) -> 0 | E10: =IF(C10=0,"n/a (zero denom)",D10/ABS(C10)) -> 0 | F10: ='Tolerances'!$B$6 -> 0.001 | G10: =IF(C10=0,IF(D10<=0.000001,"PASS","FAIL"),IF(E10<=F10,"PASS","FAIL")) | H10: DCF_CAT!E29
A11: FCF Year 4 | B11: 1.0324565e+10 | C11: 1.0324565e+10 | D11: =ABS(B11-C11) -> 0 | E11: =IF(C11=0,"n/a (zero denom)",D11/ABS(C11)) -> 0 | F11: ='Tolerances'!$B$6 -> 0.001 | G11: =IF(C11=0,IF(D11<=0.000001,"PASS","FAIL"),IF(E11<=F11,"PASS","FAIL")) | H11: DCF_CAT!F29
A12: FCF Year 5 | B12: 1.107924e+10 | C12: 1.107924e+10 | D12: =ABS(B12-C12) -> 0 | E12: =IF(C12=0,"n/a (zero denom)",D12/ABS(C12)) -> 0 | F12: ='Tolerances'!$B$6 -> 0.001 | G12: =IF(C12=0,IF(D12<=0.000001,"PASS","FAIL"),IF(E12<=F12,"PASS","FAIL")) | H12: DCF_CAT!G29
A13: Terminal Value | B13: 1.1834482e+11 | C13: 1.1834482e+11 | D13: =ABS(B13-C13) -> 0 | E13: =IF(C13=0,"n/a (zero denom)",D13/ABS(C13)) -> 0 | F13: ='Tolerances'!$B$7 -> 0.002 | G13: =IF(C13=0,IF(D13<=0.000001,"PASS","FAIL"),IF(E13<=F13,"PASS","FAIL")) | H13: DCF_CAT!B32
A14: PV of Explicit FCF (sum of pv_fcf series) | B14: 3.4218526e+10 | C14: 3.4218526e+10 | D14: =ABS(B14-C14) -> 0 | E14: =IF(C14=0,"n/a (zero denom)",D14/ABS(C14)) -> 0 | F14: ='Tolerances'!$B$8 -> 0.002 | G14: =IF(C14=0,IF(D14<=0.000001,"PASS","FAIL"),IF(E14<=F14,"PASS","FAIL")) | H14: DCF_CAT!B37
A15: PV of Terminal Value | B15: 6.6865345e+10 | C15: 6.6865345e+10 | D15: =ABS(B15-C15) -> 0 | E15: =IF(C15=0,"n/a (zero denom)",D15/ABS(C15)) -> 0 | F15: ='Tolerances'!$B$9 -> 0.002 | G15: =IF(C15=0,IF(D15<=0.000001,"PASS","FAIL"),IF(E15<=F15,"PASS","FAIL")) | H15: DCF_CAT!B38
A16: Enterprise Value | B16: 1.0108387e+11 | C16: 1.0108387e+11 | D16: =ABS(B16-C16) -> 0 | E16: =IF(C16=0,"n/a (zero denom)",D16/ABS(C16)) -> 0 | F16: ='Tolerances'!$B$10 -> 0.002 | G16: =IF(C16=0,IF(D16<=0.000001,"PASS","FAIL"),IF(E16<=F16,"PASS","FAIL")) | H16: DCF_CAT!B39
A17: Equity Value | B17: 7.4853871e+10 | C17: 7.4853871e+10 | D17: =ABS(B17-C17) -> 0 | E17: =IF(C17=0,"n/a (zero denom)",D17/ABS(C17)) -> 0 | F17: ='Tolerances'!$B$11 -> 0.002 | G17: =IF(C17=0,IF(D17<=0.000001,"PASS","FAIL"),IF(E17<=F17,"PASS","FAIL")) | H17: DCF_CAT!B40
A18: Intrinsic Value per Share | B18: 162.8409 | C18: 162.8409 | D18: =ABS(B18-C18) -> 0 | E18: =IF(C18=0,"n/a (zero denom)",D18/ABS(C18)) -> 0 | F18: ='Tolerances'!$B$12 -> 0.005 | G18: =IF(C18=0,IF(D18<=0.000001,"PASS","FAIL"),IF(E18<=F18,"PASS","FAIL")) | H18: DCF_CAT!B41
A20: Sensitivity reconciliation summary (full grid in the Sensitivity Reconciliation sheet)
A21: Table | B21: Cells | C21: All Pass
A22: Table 1 -- WACC | B22: 7 | C22: PASS
A23: Table 2 -- Terminal growth | B23: 7 | C23: PASS
A24: Table 3 -- Revenue growth | B24: 8 | C24: PASS
A25: Table 4 -- Operating margin | B25: 7 | C25: PASS
A26: Table 5 -- WACC x g two-way grid | B26: 36 | C26: PASS

Sheet Detail_INTC
A1: Detailed base-case reconciliation -- INTC (Intel Corporation)
A2: First divergence: Historical Revenue CAGR
A4: Metric | B4: Codebase Output | C4: Workbook Output | D4: Absolute Difference | E4: Relative/pp Difference | F4: Tolerance | G4: PASS/FAIL | H4: Workbook Cell
A5: Historical Revenue CAGR | B5: -0.095544173 | C5: -0.0956685 | D5: =ABS(B5-C5) -> 0.00012432697 | E5: =D5 -> 0.00012432697 | F5: ='Tolerances'!$B$3 -> 0.0001 | G5: =IF(D5<=F5,"PASS","FAIL") | H5: DCF_INTC!B7
A6: Historical average Operating Margin | B6: 0.0046248517 | C6: 0.0046248517 | D6: =ABS(B6-C6) -> 0 | E6: =D6 -> 0 | F6: ='Tolerances'!$B$4 -> 0.0001 | G6: =IF(D6<=F6,"PASS","FAIL") | H6: DCF_INTC!B8
A7: WACC (final, clamped [5%,20%]) | B7: 0.15054645 | C7: 0.15054645 | D7: =ABS(B7-C7) -> 0 | E7: =D7 -> 0 | F7: ='Tolerances'!$B$5 -> 0.0005 | G7: =IF(D7<=F7,"PASS","FAIL") | H7: DCF_INTC!B19
A8: FCF Year 1 | B8: -4.2384226e+08 | C8: -4.2371135e+08 | D8: =ABS(B8-C8) -> 130913.59 | E8: =IF(C8=0,"n/a (zero denom)",D8/ABS(C8)) -> 0.0003089688 | F8: ='Tolerances'!$B$6 -> 0.001 | G8: =IF(C8=0,IF(D8<=0.000001,"PASS","FAIL"),IF(E8<=F8,"PASS","FAIL")) | H8: DCF_INTC!C29
A9: FCF Year 2 | B9: -3.8334661e+08 | C9: -3.8317552e+08 | D9: =ABS(B9-C9) -> 171084.3 | E9: =IF(C9=0,"n/a (zero denom)",D9/ABS(C9)) -> 0.00044649069 | F9: ='Tolerances'!$B$6 -> 0.001 | G9: =IF(C9=0,IF(D9<=0.000001,"PASS","FAIL"),IF(E9<=F9,"PASS","FAIL")) | H9: DCF_INTC!D29
A10: FCF Year 3 | B10: -3.4672007e+08 | C10: -3.4651769e+08 | D10: =ABS(B10-C10) -> 202377.25 | E10: =IF(C10=0,"n/a (zero denom)",D10/ABS(C10)) -> 0.00058403149 | F10: ='Tolerances'!$B$6 -> 0.001 | G10: =IF(C10=0,IF(D10<=0.000001,"PASS","FAIL"),IF(E10<=F10,"PASS","FAIL")) | H10: DCF_INTC!E29
A11: FCF Year 4 | B11: -3.1359299e+08 | C11: -3.1336687e+08 | D11: =ABS(B11-C11) -> 226122.77 | E11: =IF(C11=0,"n/a (zero denom)",D11/ABS(C11)) -> 0.00072159121 | F11: ='Tolerances'!$B$6 -> 0.001 | G11: =IF(C11=0,IF(D11<=0.000001,"PASS","FAIL"),IF(E11<=F11,"PASS","FAIL")) | H11: DCF_INTC!F29
A12: FCF Year 5 | B12: -2.8363101e+08 | C12: -2.8338753e+08 | D12: =ABS(B12-C12) -> 243478.01 | E12: =IF(C12=0,"n/a (zero denom)",D12/ABS(C12)) -> 0.00085916983 | F12: ='Tolerances'!$B$6 -> 0.001 | G12: =IF(C12=0,IF(D12<=0.000001,"PASS","FAIL"),IF(E12<=F12,"PASS","FAIL")) | H12: DCF_INTC!G29
A13: Terminal Value | B13: -2.3156512e+09 | C13: -2.3136634e+09 | D13: =ABS(B13-C13) -> 1987829.8 | E13: =IF(C13=0,"n/a (zero denom)",D13/ABS(C13)) -> 0.00085916983 | F13: ='Tolerances'!$B$7 -> 0.002 | G13: =IF(C13=0,IF(D13<=0.000001,"PASS","FAIL"),IF(E13<=F13,"PASS","FAIL")) | H13: DCF_INTC!B32
A14: PV of Explicit FCF (sum of pv_fcf series) | B14: -1.2052603e+09 | C14: -1.2046346e+09 | D14: =ABS(B14-C14) -> 625707.52 | E14: =IF(C14=0,"n/a (zero denom)",D14/ABS(C14)) -> 0.00051941686 | F14: ='Tolerances'!$B$8 -> 0.002 | G14: =IF(C14=0,IF(D14<=0.000001,"PASS","FAIL"),IF(E14<=F14,"PASS","FAIL")) | H14: DCF_INTC!B37
A15: PV of Terminal Value | B15: -1.1485565e+09 | C15: -1.1475706e+09 | D15: =ABS(B15-C15) -> 985958 | E15: =IF(C15=0,"n/a (zero denom)",D15/ABS(C15)) -> 0.00085916983 | F15: ='Tolerances'!$B$9 -> 0.002 | G15: =IF(C15=0,IF(D15<=0.000001,"PASS","FAIL"),IF(E15<=F15,"PASS","FAIL")) | H15: DCF_INTC!B38
A16: Enterprise Value | B16: -2.3538168e+09 | C16: -2.3522052e+09 | D16: =ABS(B16-C16) -> 1611665.5 | E16: =IF(C16=0,"n/a (zero denom)",D16/ABS(C16)) -> 0.00068517217 | F16: ='Tolerances'!$B$10 -> 0.002 | G16: =IF(C16=0,IF(D16<=0.000001,"PASS","FAIL"),IF(E16<=F16,"PASS","FAIL")) | H16: DCF_INTC!B39
A17: Equity Value | B17: -3.4673817e+10 | C17: -3.4672205e+10 | D17: =ABS(B17-C17) -> 1611665.5 | E17: =IF(C17=0,"n/a (zero denom)",D17/ABS(C17)) -> 4.6482925e-05 | F17: ='Tolerances'!$B$11 -> 0.002 | G17: =IF(C17=0,IF(D17<=0.000001,"PASS","FAIL"),IF(E17<=F17,"PASS","FAIL")) | H17: DCF_INTC!B40
A18: Intrinsic Value per Share | B18: -6.5594261 | C18: -6.5591212 | D18: =ABS(B18-C18) -> 0.00030488714 | E18: =IF(C18=0,"n/a (zero denom)",D18/ABS(C18)) -> 4.6482925e-05 | F18: ='Tolerances'!$B$12 -> 0.005 | G18: =IF(C18=0,IF(D18<=0.000001,"PASS","FAIL"),IF(E18<=F18,"PASS","FAIL")) | H18: DCF_INTC!B41
A20: Sensitivity reconciliation summary (full grid in the Sensitivity Reconciliation sheet)
A21: Table | B21: Cells | C21: All Pass
A22: Table 1 -- WACC | B22: 7 | C22: PASS
A23: Table 2 -- Terminal growth | B23: 7 | C23: PASS
A24: Table 3 -- Revenue growth | B24: 8 | C24: PASS
A25: Table 4 -- Operating margin | B25: 7 | C25: FAIL
A26: Table 5 -- WACC x g two-way grid | B26: 36 | C26: PASS

Sheet Detail_VZ
A1: Detailed base-case reconciliation -- VZ (Verizon Communications Inc.)
A2: All metrics within tolerance.
A4: Metric | B4: Codebase Output | C4: Workbook Output | D4: Absolute Difference | E4: Relative/pp Difference | F4: Tolerance | G4: PASS/FAIL | H4: Workbook Cell
A5: Historical Revenue CAGR | B5: 0.0084578735 | C5: 0.0084578735 | D5: =ABS(B5-C5) -> 0 | E5: =D5 -> 0 | F5: ='Tolerances'!$B$3 -> 0.0001 | G5: =IF(D5<=F5,"PASS","FAIL") | H5: DCF_VZ!B7
A6: Historical average Operating Margin | B6: 0.21216289 | C6: 0.21216289 | D6: =ABS(B6-C6) -> 0 | E6: =D6 -> 0 | F6: ='Tolerances'!$B$4 -> 0.0001 | G6: =IF(D6<=F6,"PASS","FAIL") | H6: DCF_VZ!B8
A7: WACC (final, clamped [5%,20%]) | B7: 0.05 | C7: 0.05 | D7: =ABS(B7-C7) -> 0 | E7: =D7 -> 0 | F7: ='Tolerances'!$B$5 -> 0.0005 | G7: =IF(D7<=F7,"PASS","FAIL") | H7: DCF_VZ!B19
A8: FCF Year 1 | B8: 2.1557635e+10 | C8: 2.1557635e+10 | D8: =ABS(B8-C8) -> 0 | E8: =IF(C8=0,"n/a (zero denom)",D8/ABS(C8)) -> 0 | F8: ='Tolerances'!$B$6 -> 0.001 | G8: =IF(C8=0,IF(D8<=0.000001,"PASS","FAIL"),IF(E8<=F8,"PASS","FAIL")) | H8: DCF_VZ!C29
A9: FCF Year 2 | B9: 2.1739967e+10 | C9: 2.1739967e+10 | D9: =ABS(B9-C9) -> 0 | E9: =IF(C9=0,"n/a (zero denom)",D9/ABS(C9)) -> 0 | F9: ='Tolerances'!$B$6 -> 0.001 | G9: =IF(C9=0,IF(D9<=0.000001,"PASS","FAIL"),IF(E9<=F9,"PASS","FAIL")) | H9: DCF_VZ!D29
A10: FCF Year 3 | B10: 2.1923841e+10 | C10: 2.1923841e+10 | D10: =ABS(B10-C10) -> 0 | E10: =IF(C10=0,"n/a (zero denom)",D10/ABS(C10)) -> 0 | F10: ='Tolerances'!$B$6 -> 0.001 | G10: =IF(C10=0,IF(D10<=0.000001,"PASS","FAIL"),IF(E10<=F10,"PASS","FAIL")) | H10: DCF_VZ!E29
A11: FCF Year 4 | B11: 2.210927e+10 | C11: 2.210927e+10 | D11: =ABS(B11-C11) -> 0 | E11: =IF(C11=0,"n/a (zero denom)",D11/ABS(C11)) -> 0 | F11: ='Tolerances'!$B$6 -> 0.001 | G11: =IF(C11=0,IF(D11<=0.000001,"PASS","FAIL"),IF(E11<=F11,"PASS","FAIL")) | H11: DCF_VZ!F29
A12: FCF Year 5 | B12: 2.2296268e+10 | C12: 2.2296268e+10 | D12: =ABS(B12-C12) -> 0 | E12: =IF(C12=0,"n/a (zero denom)",D12/ABS(C12)) -> 0 | F12: ='Tolerances'!$B$6 -> 0.001 | G12: =IF(C12=0,IF(D12<=0.000001,"PASS","FAIL"),IF(E12<=F12,"PASS","FAIL")) | H12: DCF_VZ!G29
A13: Terminal Value | B13: 9.1414697e+11 | C13: 9.1414697e+11 | D13: =ABS(B13-C13) -> 0 | E13: =IF(C13=0,"n/a (zero denom)",D13/ABS(C13)) -> 0 | F13: ='Tolerances'!$B$7 -> 0.002 | G13: =IF(C13=0,IF(D13<=0.000001,"PASS","FAIL"),IF(E13<=F13,"PASS","FAIL")) | H13: DCF_VZ!B32
A14: PV of Explicit FCF (sum of pv_fcf series) | B14: 9.4847571e+10 | C14: 9.4847571e+10 | D14: =ABS(B14-C14) -> 0 | E14: =IF(C14=0,"n/a (zero denom)",D14/ABS(C14)) -> 0 | F14: ='Tolerances'!$B$8 -> 0.002 | G14: =IF(C14=0,IF(D14<=0.000001,"PASS","FAIL"),IF(E14<=F14,"PASS","FAIL")) | H14: DCF_VZ!B37
A15: PV of Terminal Value | B15: 7.1625807e+11 | C15: 7.1625807e+11 | D15: =ABS(B15-C15) -> 0 | E15: =IF(C15=0,"n/a (zero denom)",D15/ABS(C15)) -> 0 | F15: ='Tolerances'!$B$9 -> 0.002 | G15: =IF(C15=0,IF(D15<=0.000001,"PASS","FAIL"),IF(E15<=F15,"PASS","FAIL")) | H15: DCF_VZ!B38
A16: Enterprise Value | B16: 8.1110564e+11 | C16: 8.1110564e+11 | D16: =ABS(B16-C16) -> 0 | E16: =IF(C16=0,"n/a (zero denom)",D16/ABS(C16)) -> 0 | F16: ='Tolerances'!$B$10 -> 0.002 | G16: =IF(C16=0,IF(D16<=0.000001,"PASS","FAIL"),IF(E16<=F16,"PASS","FAIL")) | H16: DCF_VZ!B39
A17: Equity Value | B17: 6.7200364e+11 | C17: 6.7200364e+11 | D17: =ABS(B17-C17) -> 0 | E17: =IF(C17=0,"n/a (zero denom)",D17/ABS(C17)) -> 0 | F17: ='Tolerances'!$B$11 -> 0.002 | G17: =IF(C17=0,IF(D17<=0.000001,"PASS","FAIL"),IF(E17<=F17,"PASS","FAIL")) | H17: DCF_VZ!B40
A18: Intrinsic Value per Share | B18: 161.74248 | C18: 161.74248 | D18: =ABS(B18-C18) -> 0 | E18: =IF(C18=0,"n/a (zero denom)",D18/ABS(C18)) -> 0 | F18: ='Tolerances'!$B$12 -> 0.005 | G18: =IF(C18=0,IF(D18<=0.000001,"PASS","FAIL"),IF(E18<=F18,"PASS","FAIL")) | H18: DCF_VZ!B41
A20: Sensitivity reconciliation summary (full grid in the Sensitivity Reconciliation sheet)
A21: Table | B21: Cells | C21: All Pass
A22: Table 1 -- WACC | B22: 7 | C22: PASS
A23: Table 2 -- Terminal growth | B23: 7 | C23: PASS
A24: Table 3 -- Revenue growth | B24: 8 | C24: PASS
A25: Table 4 -- Operating margin | B25: 7 | C25: PASS
A26: Table 5 -- WACC x g two-way grid | B26: 36 | C26: PASS

Sheet Sensitivity Reconciliation
A1: Sensitivity reconciliation -- production recompute vs. workbook cached grid, all four companies
A2: Table 1 (WACC) and Table 2 (terminal growth) IVPS rows shown with full live-formula reconciliation. Tables 3/4/5 (revenue growth, operating margin, two-way grid) are large (8-36 rows each per company); their PASS/FAIL and cell counts are summarized per company on each Detail_<TICKER> sheet, with the full per-cell numeric detail in reconciliation_results.json.
A4: -- MSFT (Microsoft Corporation) --
A5: Table 1 -- WACC sensitivity (Intrinsic Value/Share)
A6: WACC | B6: Codebase IVPS | C6: Workbook IVPS | D6: Abs. Diff | E6: Rel. Diff | F6: Tolerance | G6: PASS/FAIL
A7: 0.05 | B7: 1038.4359 | C7: 1038.4359 | D7: =ABS(B7-C7) -> 0 | E7: =IF(C7=0,"n/a (zero denom)",D7/ABS(C7)) -> 0 | F7: ='Tolerances'!$B$13 -> 0.005 | G7: =IF(C7=0,IF(D7<=0.000001,"PASS","FAIL"),IF(E7<=F7,"PASS","FAIL"))
A8: 0.075 | B8: 507.88514 | C8: 507.88514 | D8: =ABS(B8-C8) -> 0 | E8: =IF(C8=0,"n/a (zero denom)",D8/ABS(C8)) -> 0 | F8: ='Tolerances'!$B$13 -> 0.005 | G8: =IF(C8=0,IF(D8<=0.000001,"PASS","FAIL"),IF(E8<=F8,"PASS","FAIL"))
A9: 0.1 | B9: 331.63686 | C9: 331.63686 | D9: =ABS(B9-C9) -> 5.6843419e-14 | E9: =IF(C9=0,"n/a (zero denom)",D9/ABS(C9)) -> 1.714026e-16 | F9: ='Tolerances'!$B$13 -> 0.005 | G9: =IF(C9=0,IF(D9<=0.000001,"PASS","FAIL"),IF(E9<=F9,"PASS","FAIL"))
A10: 0.125 | B10: 243.91251 | C10: 243.91251 | D10: =ABS(B10-C10) -> 0 | E10: =IF(C10=0,"n/a (zero denom)",D10/ABS(C10)) -> 0 | F10: ='Tolerances'!$B$13 -> 0.005 | G10: =IF(C10=0,IF(D10<=0.000001,"PASS","FAIL"),IF(E10<=F10,"PASS","FAIL"))
A11: 0.15 | B11: 191.56202 | C11: 191.56202 | D11: =ABS(B11-C11) -> 0 | E11: =IF(C11=0,"n/a (zero denom)",D11/ABS(C11)) -> 0 | F11: ='Tolerances'!$B$13 -> 0.005 | G11: =IF(C11=0,IF(D11<=0.000001,"PASS","FAIL"),IF(E11<=F11,"PASS","FAIL"))
A12: 0.175 | B12: 156.87263 | C12: 156.87263 | D12: =ABS(B12-C12) -> 0 | E12: =IF(C12=0,"n/a (zero denom)",D12/ABS(C12)) -> 0 | F12: ='Tolerances'!$B$13 -> 0.005 | G12: =IF(C12=0,IF(D12<=0.000001,"PASS","FAIL"),IF(E12<=F12,"PASS","FAIL"))
A13: 0.2 | B13: 132.25604 | C13: 132.25604 | D13: =ABS(B13-C13) -> 0 | E13: =IF(C13=0,"n/a (zero denom)",D13/ABS(C13)) -> 0 | F13: ='Tolerances'!$B$13 -> 0.005 | G13: =IF(C13=0,IF(D13<=0.000001,"PASS","FAIL"),IF(E13<=F13,"PASS","FAIL"))
A14: Table 2 -- Terminal growth sensitivity (Intrinsic Value/Share)
A15: Terminal g | B15: Codebase IVPS | C15: Workbook IVPS | D15: Abs. Diff | E15: Rel. Diff | F15: Tolerance | G15: PASS/FAIL
A16: 0 | B16: 264.83076 | C16: 264.83076 | D16: =ABS(B16-C16) -> 0 | E16: =IF(C16=0,"n/a (zero denom)",D16/ABS(C16)) -> 0 | F16: ='Tolerances'!$B$13 -> 0.005 | G16: =IF(C16=0,IF(D16<=0.000001,"PASS","FAIL"),IF(E16<=F16,"PASS","FAIL"))
A17: 0.01 | B17: 287.09308 | C17: 287.09308 | D17: =ABS(B17-C17) -> 0 | E17: =IF(C17=0,"n/a (zero denom)",D17/ABS(C17)) -> 0 | F17: ='Tolerances'!$B$13 -> 0.005 | G17: =IF(C17=0,IF(D17<=0.000001,"PASS","FAIL"),IF(E17<=F17,"PASS","FAIL"))
A18: 0.02 | B18: 314.92068 | C18: 314.92068 | D18: =ABS(B18-C18) -> 0 | E18: =IF(C18=0,"n/a (zero denom)",D18/ABS(C18)) -> 0 | F18: ='Tolerances'!$B$13 -> 0.005 | G18: =IF(C18=0,IF(D18<=0.000001,"PASS","FAIL"),IF(E18<=F18,"PASS","FAIL"))
A19: 0.025 | B19: 331.61709 | C19: 331.61709 | D19: =ABS(B19-C19) -> 0 | E19: =IF(C19=0,"n/a (zero denom)",D19/ABS(C19)) -> 0 | F19: ='Tolerances'!$B$13 -> 0.005 | G19: =IF(C19=0,IF(D19<=0.000001,"PASS","FAIL"),IF(E19<=F19,"PASS","FAIL"))
A20: 0.03 | B20: 350.69856 | C20: 350.69856 | D20: =ABS(B20-C20) -> 0 | E20: =IF(C20=0,"n/a (zero denom)",D20/ABS(C20)) -> 0 | F20: ='Tolerances'!$B$13 -> 0.005 | G20: =IF(C20=0,IF(D20<=0.000001,"PASS","FAIL"),IF(E20<=F20,"PASS","FAIL"))
A21: 0.04 | B21: 398.40155 | C21: 398.40155 | D21: =ABS(B21-C21) -> 0 | E21: =IF(C21=0,"n/a (zero denom)",D21/ABS(C21)) -> 0 | F21: ='Tolerances'!$B$13 -> 0.005 | G21: =IF(C21=0,IF(D21<=0.000001,"PASS","FAIL"),IF(E21<=F21,"PASS","FAIL"))
A22: 0.05 | B22: 465.18413 | C22: 465.18413 | D22: =ABS(B22-C22) -> 0 | E22: =IF(C22=0,"n/a (zero denom)",D22/ABS(C22)) -> 0 | F22: ='Tolerances'!$B$13 -> 0.005 | G22: =IF(C22=0,IF(D22<=0.000001,"PASS","FAIL"),IF(E22<=F22,"PASS","FAIL"))
A23: Tables 3/4/5 summary: T3=PASS, T4=PASS, T5=PASS (36/36 cells).
A25: -- CAT (Caterpillar Inc.) --
A26: Table 1 -- WACC sensitivity (Intrinsic Value/Share)
A27: WACC | B27: Codebase IVPS | C27: Workbook IVPS | D27: Abs. Diff | E27: Rel. Diff | F27: Tolerance | G27: PASS/FAIL
A28: 0.05 | B28: 807.66151 | C28: 807.66151 | D28: =ABS(B28-C28) -> 0 | E28: =IF(C28=0,"n/a (zero denom)",D28/ABS(C28)) -> 0 | F28: ='Tolerances'!$B$13 -> 0.005 | G28: =IF(C28=0,IF(D28<=0.000001,"PASS","FAIL"),IF(E28<=F28,"PASS","FAIL"))
A29: 0.075 | B29: 371.34814 | C29: 371.34814 | D29: =ABS(B29-C29) -> 0 | E29: =IF(C29=0,"n/a (zero denom)",D29/ABS(C29)) -> 0 | F29: ='Tolerances'!$B$13 -> 0.005 | G29: =IF(C29=0,IF(D29<=0.000001,"PASS","FAIL"),IF(E29<=F29,"PASS","FAIL"))
A30: 0.1 | B30: 226.14434 | C30: 226.14434 | D30: =ABS(B30-C30) -> 0 | E30: =IF(C30=0,"n/a (zero denom)",D30/ABS(C30)) -> 0 | F30: ='Tolerances'!$B$13 -> 0.005 | G30: =IF(C30=0,IF(D30<=0.000001,"PASS","FAIL"),IF(E30<=F30,"PASS","FAIL"))
A31: 0.125 | B31: 153.698 | C31: 153.698 | D31: =ABS(B31-C31) -> 0 | E31: =IF(C31=0,"n/a (zero denom)",D31/ABS(C31)) -> 0 | F31: ='Tolerances'!$B$13 -> 0.005 | G31: =IF(C31=0,IF(D31<=0.000001,"PASS","FAIL"),IF(E31<=F31,"PASS","FAIL"))
A32: 0.15 | B32: 110.34085 | C32: 110.34085 | D32: =ABS(B32-C32) -> 0 | E32: =IF(C32=0,"n/a (zero denom)",D32/ABS(C32)) -> 0 | F32: ='Tolerances'!$B$13 -> 0.005 | G32: =IF(C32=0,IF(D32<=0.000001,"PASS","FAIL"),IF(E32<=F32,"PASS","FAIL"))
A33: 0.175 | B33: 81.518342 | C33: 81.518342 | D33: =ABS(B33-C33) -> 0 | E33: =IF(C33=0,"n/a (zero denom)",D33/ABS(C33)) -> 0 | F33: ='Tolerances'!$B$13 -> 0.005 | G33: =IF(C33=0,IF(D33<=0.000001,"PASS","FAIL"),IF(E33<=F33,"PASS","FAIL"))
A34: 0.2 | B34: 60.993889 | C34: 60.993889 | D34: =ABS(B34-C34) -> 0 | E34: =IF(C34=0,"n/a (zero denom)",D34/ABS(C34)) -> 0 | F34: ='Tolerances'!$B$13 -> 0.005 | G34: =IF(C34=0,IF(D34<=0.000001,"PASS","FAIL"),IF(E34<=F34,"PASS","FAIL"))
A35: Table 2 -- Terminal growth sensitivity (Intrinsic Value/Share)
A36: Terminal g | B36: Codebase IVPS | C36: Workbook IVPS | D36: Abs. Diff | E36: Rel. Diff | F36: Tolerance | G36: PASS/FAIL
A37: 0 | B37: 129.96188 | C37: 129.96188 | D37: =ABS(B37-C37) -> 0 | E37: =IF(C37=0,"n/a (zero denom)",D37/ABS(C37)) -> 0 | F37: ='Tolerances'!$B$13 -> 0.005 | G37: =IF(C37=0,IF(D37<=0.000001,"PASS","FAIL"),IF(E37<=F37,"PASS","FAIL"))
A38: 0.01 | B38: 141.33558 | C38: 141.33558 | D38: =ABS(B38-C38) -> 0 | E38: =IF(C38=0,"n/a (zero denom)",D38/ABS(C38)) -> 0 | F38: ='Tolerances'!$B$13 -> 0.005 | G38: =IF(C38=0,IF(D38<=0.000001,"PASS","FAIL"),IF(E38<=F38,"PASS","FAIL"))
A39: 0.02 | B39: 154.96242 | C39: 154.96242 | D39: =ABS(B39-C39) -> 0 | E39: =IF(C39=0,"n/a (zero denom)",D39/ABS(C39)) -> 0 | F39: ='Tolerances'!$B$13 -> 0.005 | G39: =IF(C39=0,IF(D39<=0.000001,"PASS","FAIL"),IF(E39<=F39,"PASS","FAIL"))
A40: 0.025 | B40: 162.8409 | C40: 162.8409 | D40: =ABS(B40-C40) -> 0 | E40: =IF(C40=0,"n/a (zero denom)",D40/ABS(C40)) -> 0 | F40: ='Tolerances'!$B$13 -> 0.005 | G40: =IF(C40=0,IF(D40<=0.000001,"PASS","FAIL"),IF(E40<=F40,"PASS","FAIL"))
A41: 0.03 | B41: 171.58553 | C41: 171.58553 | D41: =ABS(B41-C41) -> 0 | E41: =IF(C41=0,"n/a (zero denom)",D41/ABS(C41)) -> 0 | F41: ='Tolerances'!$B$13 -> 0.005 | G41: =IF(C41=0,IF(D41<=0.000001,"PASS","FAIL"),IF(E41<=F41,"PASS","FAIL"))
A42: 0.04 | B42: 192.3152 | C42: 192.3152 | D42: =ABS(B42-C42) -> 0 | E42: =IF(C42=0,"n/a (zero denom)",D42/ABS(C42)) -> 0 | F42: ='Tolerances'!$B$13 -> 0.005 | G42: =IF(C42=0,IF(D42<=0.000001,"PASS","FAIL"),IF(E42<=F42,"PASS","FAIL"))
...

Sheet Findings
A1: Findings
A3: Overall verdict: NO-GO
A4: Base-case divergence found for: INTC
A5: - INTC: first divergence at metric 'Historical Revenue CAGR'.
A6: Root cause (INTC Revenue CAGR): the independent workbook's 'Years elapsed' formula (DCF_INTC!B5) computes COUNT(periods)-1 (a plain period count = 4), while docs/model-specifications/dcf.md's formula and src/dcf_model/dcf.py's calculate_historical_revenue_cagr compute the ACTUAL elapsed calendar days between the earliest and latest frozen fiscal-period-end dates, divided by 365.25 (= 4.005476 for INTC, whose fiscal year-end dates are not evenly spaced). MSFT/CAT/VZ's period-end dates recur on the same calendar day every year, so both methods coincidentally produce exactly 4.0 for them -- only INTC's irregular fiscal calendar exposes the difference. This is a specification-precision gap (the written spec names 'years_elapsed' without spelling out the day-count method in prose), not a numerical bug in either calculation path; neither path was modified in this session.
A7: Directional bias: MSFT, CAT, and VZ match the workbook to full floating-point precision on every required metric (zero signed difference) -- no bias to investigate among them. INTC's nonzero differences are fully attributable to the single root cause above.
A8: INTC sensitivity tables show a documented, mathematically-correct inverted direction (IV rises with WACC, falls with terminal growth, falls with revenue growth) caused by negative base-case FCF -- both the workbook and the production recompute agree on every inverted direction.

Sheet Sign-off
A1: Sign-off
A3: Source implementation commit | B3: 776e76f56e6210f1050caa74c60962ed89162496
A4: Branch | B4: remediation/valuation-engine-production-quality
A5: Original independent workbook SHA-256 | B5: 942b5f096cf546d63487add31eb29b1b690f0819f923f01436093f9bbc75eba1
A6: Frozen snapshot SHA-256 (MSFT) | B6: 7c50a3e9fb2d27095a890ad8d11732d4ccc72ef9350998604adb3af7a3c845a8
A7: Frozen snapshot SHA-256 (CAT) | B7: 651d366c01415c2da33733058dabb9ac6e4f40cdf5b20e743c0b83ebc3a52c93
A8: Frozen snapshot SHA-256 (INTC) | B8: d73e4b40bce2442a75affde82aaa563ffdea9c68c7257e70cc325663cff24930
A9: Frozen snapshot SHA-256 (VZ) | B9: 77b8ea27b8decaff5fe3b4aad857c632a852445eda0b7f2342f594cd3c4b5f3d
A10: Overall reconciliation status | B10: NO-GO
A11: Profitability established? | B11: NOT ESTABLISHED -- this reconciliation checks calculation agreement only
A12: Second-reviewer sign-off | B12: PENDING -- not performed in this session
